Workbook

Sheet Sheet2
K2: 22 or 23 matches | P2: Matches | Q2: Games | S2: Week 1 | T2: WCS Final
K3: 44 or 46 games | O3: Opening Round | P3: 4 | Q3: =P3*2 -> 8 | S3: Week 1 | T3: F - Su
O4: Losers Round 1 | P4: 2 | Q4: =P4*2 -> 4 | S4: Week 2 | T4: F - Su
B5: 12 | D5: 5 | F5: 1 | O5: Winners Quarterfinal | P5: 4 | Q5: =P5*2 -> 8 | S5: Week 2 | T5: F - Su
B6: 13 | D6: 12 | F6: 8 | O6: Losers Round 2 | P6: 2 | Q6: =P6*2 -> 4 | S6: Week 3 | T6: T - R
O7: Losers Round 3 | P7: 2 | Q7: =P7*2 -> 4 | S7: Week 3 | T7: F - Su
O8: Winners Semifinal | P8: 2 | Q8: =P8*2 -> 4 | S8: Week 3 | T8: F - Su
B9: 9 | D9: 8 | F9: 4 | H9: 1 | O9: Losers Quarterfinal | P9: 2 | Q9: =P9*2 -> 4 | S9: Week 4 | T9: T - R
B10: 16 | D10: 9 | F10: 5 | H10: 4 | O10: Losers Semifinal | P10: 1 | Q10: =P10*2 -> 2 | S10: Week 4 | T10: F - Su
J11: 1 | O11: Winners Final | P11: 1 | Q11: =P11*2 -> 2 | S11: Week 4 | T11: F - Su
J12: 2 | O12: Losers Final | P12: 1 | Q12: =P12*2 -> 2 | S12: Week 5 | T12: T - R
B13: 10 | D13: 7 | F13: 3 | H13: 2 | O13: Grand Final | P13: 1 | Q13: =P13*2 -> 2 | S13: Week 5 | T13: F - Su
B14: 15 | D14: 10 | F14: 6 | H14: 3 | O14: Grand Final - Reset | P14: 1 | Q14: =P14*2 -> 2 | S14: Week 6 | T14: T - R
L16: 1 | M16: 1 | P16: =SUM(P3:P14) -> 23 | Q16: =SUM(Q3:Q14) -> 46
B17: 11 | D17: 6 | F17: 2 | L17: 2 | M17: 2
B18: 14 | D18: 11 | F18: 7
D20: Opening | F20: WQF | H20: WSF | J20: WF | L20: GF | M20: R
F22: LR1 | G22: LR2 | H22: LR3 | I22: LQF | J22: LSF | K22: LF
D23: 13 | E23: 11 | F23: 9 | G23: 7 | H23: 5 | I23: 3 | J23: 3 | K23: 2
D24: 16 | E24: 13 | F24: 11 | G24: 9 | H24: 7 | I24: 5 | J24: 4 | K24: 3
D26: 14 | E26: 12 | F26: 10 | G26: 8 | H26: 6 | I26: 4
D27: 15 | E27: 14 | F27: 12 | G27: 10 | H27: 8 | I27: 6
F29: 11th/12th | G29: 9th/10th | H29: 7th/8th | I29: 5th/6th | J29: Fourth | K29: Third | L29: Champion
K33: 30 to 31 matches | P33: Matches | Q33: Games
K34: 58 to 64 games | O34: Opening Round | P34: 4 | Q34: =P34*2 -> 8 | S34: Week 1 | T34: F - Su
O35: Losers Round 1 | P35: 2 | Q35: =P35*2 -> 4 | S35: Week 2 | T35: F - Su
B36: 12 | D36: 5 | F36: 1 | O36: Winners Round 2 | P36: 4 | Q36: =P36*2 -> 8 | S36: Week 2 | T36: F - Su
B37: 13 | D37: 12 | F37: 8 | O37: Losers Round 2 | P37: 2 | Q37: =P37*2 -> 4 | S37: Week 3 | T37: T - R
O38: Losers Round 3 | P38: 2 | Q38: =P38*2 -> 4 | S38: Week 3 | T38: F - Su
O39: Winners Quarterfinal | P39: 4 | Q39: =P39*2 -> 8 | S39: Week 3 | T39: F - Su
B40: 9 | D40: 8 | F40: 4 | H40: 1 | O40: Losers Round 4 | P40: 2 | Q40: =P40*2 -> 4 | S40: Week 4 | T40: T - R
B41: 16 | D41: 9 | F41: 5 | H41: 4 | O41: Losers Round 5 | P41: 2 | Q41: =P41*2 -> 4 | S41: Week 4 | T41: F - Su
J42: 1 | O42: Winners Semifinal | P42: 2 | Q42: =P42*2 -> 4 | S42: Week 4 | T42: F - Su
J43: 2 | O43: Losers Quarterfinal | P43: 2 | Q43: =P43*2 -> 4 | S43: Week 5 | T43: T - R
B44: 10 | D44: 7 | F44: 3 | H44: 2 | O44: Losers Semifinal | P44: 1 | Q44: =P44*2 -> 2 | S44: Week 5 | T44: F - Su
B45: 15 | D45: 10 | F45: 6 | H45: 3 | O45: Winners Final | P45: 1 | Q45: =P45*2 -> 2 | S45: Week 5 | T45: F - Su
O46: Losers Final | P46: 1 | Q46: =P46*2 -> 2 | S46: Week 6 | T46: F - Su
L47: 1 | M47: 1 | O47: Grand Final | P47: 1 | Q47: 3 | S47: Week 7 | T47: T - R - Su
B48: 11 | D48: 6 | F48: 2 | L48: 2 | M48: 2 | O48: Grand Final - Reset | P48: 1 | Q48: 3 | S48: Week 8 | T48: T - R - Su
B49: 14 | D49: 11 | F49: 7
...

Sheet Bracket
D2: Lily Valley | E2: #1 | H2: Opening Round | I2: Match 1 | J2: #8 | M2: Play-in Round | N2: Match A | O2: #11
E3: #2 | J3: #9 | O3: #12
E4: #3 | I4: Match 2 | J4: #5 | N4: Match B | O4: #13
E5: #4 | J5: #12 | K5: Winner of Match C | O5: #14
E6: #5 | I6: Match 3 | J6: #6 | N6: Match C | P6: Loser of Match A
E7: #6 | J7: #11 | K7: Winner of Match A | P7: Winner of Match B
E8: #7 | I8: Match 4 | J8: #7
E9: #8 | J9: #10
E10: #9
E11: #10 | H11: Upper Bracket QF | I11: Match 5 | J11: #1
E12: #11 | K12: Winner of Match 1
E13: #12 | I13: Match 6 | J13: #4
E14: #13 | K14: Winner of Match 2
E15: #14 | I15: Match 7 | J15: #3
K16: Winner of Match 3
I17: Match 8 | J17: #2
K18: Winner of Match 4
C20: Lower Bracket R1 | D20: Match 9 | F20: Loser of Match 3
F21: Loser of Match 6
A22: 12 | D22: Match 10 | F22: Loser of Match 4
A23: 11 | F23: Loser of Match 5
A24: 10 | D24: Match 11 | F24: Loser of Match 1
A25: 9 | F25: Loser of Match 8
D26: Match 12 | F26: Loser of Match 2
F27: Loser of Match 7
C29: Lower Bracket R2 | D29: Match 13 | F29: Winner of Match 9 | H29: Upper Bracket SF | I29: Match 15 | K29: Winner of Match 5
A30: 8 | F30: Winner of Match 10 | K30: Winner of Match 6
A31: 7 | D31: Match 14 | F31: Winner of Match 11 | I31: Match 16 | K31: Winner of Match 7
F32: Winner of Match 12 | K32: Winner of Match 8
C34: Lower Bracket QF | D34: Match 17 | F34: Loser of Match 16
A35: 6 | F35: Winner of Match 13
A36: 5 | D36: Match 18 | F36: Loser of Match 15
F37: Winner of Match 14
A39: 4 | C39: Lower Bracket SF | D39: Match 19 | F39: Winner of Match 17 | H39: Upper Bracket Final | I39: Match 20 | K39: Winner of Match 15
F40: Winner of Match 18 | K40: Winner of Match 16
A42: 3 | C42: Lower Bracket Final | D42: Match 21 | F42: Loser of Match 20
F43: Winner of Match 19
H45: Grand Final | I45: Match 22 | K45: Winner of Match 20
K46: Winner of Match 21
A47: 2
...

Sheet Sheet5
L2: 0.99815419 | M2: 112 | O2: =L2*M2 -> 111.79327 | P2: =ROUNDDOWN(O2,0)+1 -> 112 | Q2: =ROUND(O2, 0) -> 112 | S2: 128 | T2: =L2*S2 -> 127.76374 | U2: =ROUND(T2, 0) -> 128 | V2: 121
D3: CONF | E3: CCC | F3: UTL | G3: MRL | H3: WCS | I3: PLAYOFFS | L3: 0.95589642 | M3: 111 | O3: =L3*M3 -> 106.1045 | P3: =ROUNDDOWN(O3,0)+1 -> 107 | Q3: =ROUND(O3, 0) -> 106 | S3: 127 | T3: =L3*S3 -> 121.39884 | U3: =ROUND(T3, 0) -> 121 | V3: 113
C4: 1 | D4: 24 | E4: 16 | F4: 24 | G4: 32 | H4: 48 | I4: 64 | L4: 0.94989296 | M4: 110 | O4: =L4*M4 -> 104.48823 | P4: =ROUNDDOWN(O4,0)+1 -> 105 | Q4: =ROUND(O4, 0) -> 104 | S4: 126 | T4: =L4*S4 -> 119.68651 | U4: =ROUND(T4, 0) -> 120 | V4: 105
C5: 2 | D5: 16 | E5: 8 | F5: 16 | G5: 24 | H5: 32 | I5: 48 | L5: 0.91303387 | M5: 109 | O5: =L5*M5 -> 99.520692 | P5: =ROUNDDOWN(O5,0)+1 -> 100 | Q5: =ROUND(O5, 0) -> 100 | S5: 125 | T5: =L5*S5 -> 114.12923 | U5: =ROUND(T5, 0) -> 114 | V5: 97
C6: 3 | E6: 4 | F6: 8 | G6: 16 | H6: 24 | I6: 40 | L6: 0.89541494 | M6: 108 | O6: =L6*M6 -> 96.704814 | P6: =ROUNDDOWN(O6,0)+1 -> 97 | Q6: =ROUND(O6, 0) -> 97 | S6: 124 | T6: =L6*S6 -> 111.03145 | U6: =ROUND(T6, 0) -> 111 | V6: 89
C7: 4 | I7: 32 | L7: 0.84842567 | M7: 107 | O7: =L7*M7 -> 90.781547 | P7: =ROUNDDOWN(O7,0)+1 -> 91 | Q7: =ROUND(O7, 0) -> 91 | S7: 123 | T7: =L7*S7 -> 104.35636 | U7: =ROUND(T7, 0) -> 104 | V7: 81
C8: 5-6 | E8: 2 | F8: 4 | G8: 8 | H8: 16 | I8: 28 | L8: 0.83368876 | M8: 106 | O8: =L8*M8 -> 88.371008 | P8: =ROUNDDOWN(O8,0)+1 -> 89 | Q8: =ROUND(O8, 0) -> 88 | S8: 122 | T8: =L8*S8 -> 101.71003 | U8: =ROUND(T8, 0) -> 102 | V8: 73
C9: 7-8 | I9: 24 | L9: 0.83294795 | M9: 105 | O9: =L9*M9 -> 87.459534 | P9: =ROUNDDOWN(O9,0)+1 -> 88 | Q9: =ROUND(O9, 0) -> 87 | S9: 120 | T9: =L9*S9 -> 99.953753 | U9: =ROUND(T9, 0) -> 100 | V9: 65
C10: 9-10 | E10: 1 | F10: 2 | G10: 4 | H10: 8 | I10: 20 | L10: 0.83142703 | M10: 104 | O10: =L10*M10 -> 86.468411 | P10: =ROUNDDOWN(O10,0)+1 -> 87 | Q10: =ROUND(O10, 0) -> 86 | S10: 119 | T10: =L10*S10 -> 98.939816 | U10: =ROUND(T10, 0) -> 99 | V10: 57
C11: 11-12 | I11: 16 | L11: 0.80994281 | M11: 103 | O11: =L11*M11 -> 83.42411 | P11: =ROUNDDOWN(O11,0)+1 -> 84 | Q11: =ROUND(O11, 0) -> 83 | S11: 118 | T11: =L11*S11 -> 95.573252 | U11: =ROUND(T11, 0) -> 96 | V11: 49
C12: 13-14 | E12: 0 | L12: 0.79043743 | M12: 102 | O12: =L12*M12 -> 80.624618 | P12: =ROUNDDOWN(O12,0)+1 -> 81 | Q12: =ROUND(O12, 0) -> 81 | S12: 117 | T12: =L12*S12 -> 92.48118 | U12: =ROUND(T12, 0) -> 92 | V12: 41
C13: 15-16 | L13: 0.78630396 | M13: 101 | O13: =L13*M13 -> 79.4167 | P13: =ROUNDDOWN(O13,0)+1 -> 80 | Q13: =ROUND(O13, 0) -> 79 | S13: 116 | T13: =L13*S13 -> 91.211259 | U13: =ROUND(T13, 0) -> 91 | V13: 33
C14: 17-20 | F14: 1 | L14: 0.76555796 | M14: 100 | O14: =L14*M14 -> 76.555796 | P14: =ROUNDDOWN(O14,0)+1 -> 77 | Q14: =ROUND(O14, 0) -> 77 | S14: 115 | T14: =L14*S14 -> 88.039165 | U14: =ROUND(T14, 0) -> 88 | V14: 25
L15: 0.76468114 | M15: 99 | O15: =L15*M15 -> 75.703433 | P15: =ROUNDDOWN(O15,0)+1 -> 76 | Q15: =ROUND(O15, 0) -> 76 | S15: 114 | T15: =L15*S15 -> 87.17365 | U15: =ROUND(T15, 0) -> 87 | V15: 17
L16: 0.73693288 | M16: 98 | O16: =L16*M16 -> 72.219422 | P16: =ROUNDDOWN(O16,0)+1 -> 73 | Q16: =ROUND(O16, 0) -> 72 | S16: 112 | T16: =L16*S16 -> 82.536482 | U16: =ROUND(T16, 0) -> 83 | V16: 9
L17: 0.73636681 | M17: 97 | O17: =L17*M17 -> 71.427581 | P17: =ROUNDDOWN(O17,0)+1 -> 72 | Q17: =ROUND(O17, 0) -> 71 | S17: 111 | T17: =L17*S17 -> 81.736716 | U17: =ROUND(T17, 0) -> 82 | V17: 1
B18: Season Three | D18: CONF | E18: CCC | F18: UTL* | G18: MRL* | H18: WCS | I18: PLAYOFFS | L18: 0.7311555 | M18: 96 | O18: =L18*M18 -> 70.190928 | P18: =ROUNDDOWN(O18,0)+1 -> 71 | Q18: =ROUND(O18, 0) -> 70 | S18: 110 | T18: =L18*S18 -> 80.427106 | U18: =ROUND(T18, 0) -> 80
C19: 1 | D19: 50 | E19: 30 | F19: 40 | G19: 50 | H19: 70 | I19: 100 | L19: 0.72898829 | M19: 95 | O19: =L19*M19 -> 69.253888 | P19: =ROUNDDOWN(O19,0)+1 -> 70 | Q19: =ROUND(O19, 0) -> 69 | S19: 109 | T19: =L19*S19 -> 79.459724 | U19: =ROUND(T19, 0) -> 79
C20: 2 | D20: 30 | E20: 24 | F20: 35 | G20: 44 | H20: 63 | I20: 92 | L20: 0.7203364 | M20: 94 | O20: =L20*M20 -> 67.711621 | P20: =ROUNDDOWN(O20,0)+1 -> 68 | Q20: =ROUND(O20, 0) -> 68 | S20: 108 | T20: =L20*S20 -> 77.796331 | U20: =ROUND(T20, 0) -> 78
C21: 3 | D21: 15^ | E21: 18 | F21: 30 | G21: 38 | H21: 56 | I21: 84 | L21: 0.71554019 | M21: 93 | O21: =L21*M21 -> 66.545237 | P21: =ROUNDDOWN(O21,0)+1 -> 67 | Q21: =ROUND(O21, 0) -> 67 | S21: 107 | T21: =L21*S21 -> 76.5628 | U21: =ROUND(T21, 0) -> 77
C22: 4 | D22: 10^* | I22: 76 | L22: 0.71016637 | M22: 92 | O22: =L22*M22 -> 65.335306 | P22: =ROUNDDOWN(O22,0)+1 -> 66 | Q22: =ROUND(O22, 0) -> 65 | S22: 106 | T22: =L22*S22 -> 75.277636 | U22: =ROUND(T22, 0) -> 75
C23: 5-6 | D23: 5^** | E23: 12 | F23: 25 | G23: 32 | H23: 49 | I23: 68 | L23: 0.70014331 | M23: 91 | O23: =L23*M23 -> 63.713041 | P23: =ROUNDDOWN(O23,0)+1 -> 64 | Q23: =ROUND(O23, 0) -> 64 | S23: 104 | T23: =L23*S23 -> 72.814904 | U23: =ROUND(T23, 0) -> 73
C24: 7-8 | I24: 60 | L24: 0.69749316 | M24: 90 | O24: =L24*M24 -> 62.774384 | P24: =ROUNDDOWN(O24,0)+1 -> 63 | Q24: =ROUND(O24, 0) -> 63 | S24: 103 | T24: =L24*S24 -> 71.841796 | U24: =ROUND(T24, 0) -> 72
C25: 9-10 | E25: 6 | F25: 20 | G25: 26 | H25: 42 | I25: 52* | L25: 0.69721774 | M25: 89 | O25: =L25*M25 -> 62.052379 | P25: =ROUNDDOWN(O25,0)+1 -> 63 | Q25: =ROUND(O25, 0) -> 62 | S25: 102 | T25: =L25*S25 -> 71.116209 | U25: =ROUND(T25, 0) -> 71
C26: 11-12 | I26: 48* | L26: 0.69601783 | M26: 88 | O26: =L26*M26 -> 61.249569 | P26: =ROUNDDOWN(O26,0)+1 -> 62 | Q26: =ROUND(O26, 0) -> 61 | S26: 101 | T26: =L26*S26 -> 70.297801 | U26: =ROUND(T26, 0) -> 70
C27: 13-14 | E27: 0 | I27: 44 | L27: 0.69497469 | M27: 87 | O27: =L27*M27 -> 60.462798 | P27: =ROUNDDOWN(O27,0)+1 -> 61 | Q27: =ROUND(O27, 0) -> 60 | S27: 100 | T27: =L27*S27 -> 69.497469 | U27: =ROUND(T27, 0) -> 69
C28: 15-16 | L28: 0.68575819 | M28: 86 | O28: =L28*M28 -> 58.975205 | P28: =ROUNDDOWN(O28,0)+1 -> 59 | Q28: =ROUND(O28, 0) -> 59 | S28: 99 | T28: =L28*S28 -> 67.890061 | U28: =ROUND(T28, 0) -> 68
C29: 17-20 | F29: et cetera | G29: et cetera | H29: et cetera | L29: 0.6777043 | M29: 85 | O29: =L29*M29 -> 57.604866 | P29: =ROUNDDOWN(O29,0)+1 -> 58 | Q29: =ROUND(O29, 0) -> 58 | S29: 98 | T29: =L29*S29 -> 66.415022 | U29: =ROUND(T29, 0) -> 66
D30: ^teams tied with second | G30: *varies by record | I30: OR 48, QF 52 | L30: 0.67631751 | M30: 84 | O30: =L30*M30 -> 56.810671 | P30: =ROUNDDOWN(O30,0)+1 -> 57 | Q30: =ROUND(O30, 0) -> 57 | S30: 96 | T30: =L30*S30 -> 64.926481 | U30: =ROUND(T30, 0) -> 65
D31: ^*positive/^**negative record | L31: 0.67139385 | M31: 83 | O31: =L31*M31 -> 55.72569 | P31: =ROUNDDOWN(O31,0)+1 -> 56 | Q31: =ROUND(O31, 0) -> 56 | S31: 95 | T31: =L31*S31 -> 63.782416 | U31: =ROUND(T31, 0) -> 64
L32: 0.66225275 | M32: 82 | O32: =L32*M32 -> 54.304726 | P32: =ROUNDDOWN(O32,0)+1 -> 55 | Q32: =ROUND(O32, 0) -> 54 | S32: 94 | T32: =L32*S32 -> 62.251759 | U32: =ROUND(T32, 0) -> 62
B33: Season Four | D33: CONF | E33: CCC | F33: UTL* | G33: MRL* | H33: WCS | I33: PLAYOFFS | L33: 0.65894759 | M33: 81 | O33: =L33*M33 -> 53.374754 | P33: =ROUNDDOWN(O33,0)+1 -> 54 | Q33: =ROUND(O33, 0) -> 53 | S33: 93 | T33: =L33*S33 -> 61.282125 | U33: =ROUND(T33, 0) -> 61
C34: 1 | D34: 50 | E34: 30 | F34: 40 | G34: 50 | H34: 70 | I34: 100 | L34: 0.64953149 | M34: 80 | O34: =L34*M34 -> 51.962519 | P34: =ROUNDDOWN(O34,0)+1 -> 52 | Q34: =ROUND(O34, 0) -> 52 | S34: 92 | T34: =L34*S34 -> 59.756897 | U34: =ROUND(T34, 0) -> 60
C35: 2 | D35: 30 | E35: 24 | F35: 35 | G35: 44 | H35: 60 | I35: 92 | L35: 0.64907982 | M35: 79 | O35: =L35*M35 -> 51.277305 | P35: =ROUNDDOWN(O35,0)+1 -> 52 | Q35: =ROUND(O35, 0) -> 51 | S35: 91 | T35: =L35*S35 -> 59.066263 | U35: =ROUND(T35, 0) -> 59
C36: 3 | D36: 15^ | E36: 18 | F36: 30 | G36: 38 | H36: 50 | I36: 84 | L36: 0.64627656 | M36: 78 | O36: =L36*M36 -> 50.409572 | P36: =ROUNDDOWN(O36,0)+1 -> 51 | Q36: =ROUND(O36, 0) -> 50 | S36: 90 | T36: =L36*S36 -> 58.16489 | U36: =ROUND(T36, 0) -> 58
C37: 4 | D37: 10^* | I37: 76 | L37: 0.64327405 | M37: 77 | O37: =L37*M37 -> 49.532102 | P37: =ROUNDDOWN(O37,0)+1 -> 50 | Q37: =ROUND(O37, 0) -> 50 | S37: 88 | T37: =L37*S37 -> 56.608117 | U37: =ROUND(T37, 0) -> 57
C38: 5-6 | D38: 5^** | E38: 12 | F38: 25 | G38: 32 | H38: 40 | I38: 68 | L38: 0.61836803 | M38: 76 | O38: =L38*M38 -> 46.99597 | P38: =ROUNDDOWN(O38,0)+1 -> 47 | Q38: =ROUND(O38, 0) -> 47 | S38: 87 | T38: =L38*S38 -> 53.798019 | U38: =ROUND(T38, 0) -> 54
C39: 7-8 | I39: 60 | L39: 0.60348558 | M39: 75 | O39: =L39*M39 -> 45.261418 | P39: =ROUNDDOWN(O39,0)+1 -> 46 | Q39: =ROUND(O39, 0) -> 45 | S39: 86 | T39: =L39*S39 -> 51.89976 | U39: =ROUND(T39, 0) -> 52
C40: 9-10 | E40: 6 | F40: 20 | G40: 26 | H40: 30 | I40: 52 | L40: 0.59716969 | M40: 74 | O40: =L40*M40 -> 44.190557 | P40: =ROUNDDOWN(O40,0)+1 -> 45 | Q40: =ROUND(O40, 0) -> 44 | S40: 85 | T40: =L40*S40 -> 50.759424 | U40: =ROUND(T40, 0) -> 51
C41: 11-12 | I41: 44 | L41: 0.59543018 | M41: 73 | O41: =L41*M41 -> 43.466403 | P41: =ROUNDDOWN(O41,0)+1 -> 44 | Q41: =ROUND(O41, 0) -> 43 | S41: 84 | T41: =L41*S41 -> 50.016135 | U41: =ROUND(T41, 0) -> 50
...

Sheet Phoenix Expansion Pass
P1: 120 | Q1: 110 | R1: 126 | S1: 158 | T1: 776 | U1: 56 | V1: 1346 | AB1: Rankings
B2: Phoenix Conference | G2: SS/AC/DG 1 | I2: CCC | J2: UTL | K2: MRL | L2: WCS | M2: Season | P2: CCC | Q2: UTL | R2: MRL | S2: WCS | T2: Season | U2: Total | V2: 776/48/522 | X2: Tuesday | Y2: Thursday | Z2: Weekend | AB2: Thursday | AC2: Weekend
B3: Orre Pod | D3: Almia Pod | G3: SS/AC/DG 1 | I3: 32 | J3: 12 | K3: 16 | L3: 32 | M3: 64 | O3: Week 1 | T3: 64 | U3: =SUM(P3:T3) -> 64 | Z3: SS/AC/DG/IP 1 | AB3: No | AC3: Yes | AD3: 1
B4: Phenac City | D4: Pueltown | G4: SS/AC/DG 1 | I4: 32 | J4: 12 | K4: 16 | L4: 32 | M4: 64 | O4: Week 2 | T4: 64 | U4: =SUM(P4:T4) -> 64 | Z4: SS/AC/DG/IP 1 | AB4: No | AC4: Yes | AD4: 2
B5: Pyrite Town | D5: Vientown | G5: SS/AC/DG 2 | I5: 32 | J5: 12 | K5: 16 | L5: 32 | M5: 64 | O5: Week 3 | T5: 64 | U5: =SUM(P5:T5) -> 64 | Z5: SS/AC/DG/IP 1 | AB5: No | AC5: Yes | AD5: 3
B6: Agate Village | D6: Haruba Village | G6: SS/AC/DG 2 | I6: 16 | J6: 12 | K6: 16 | L6: 32 | M6: 48 | O6: Week 4 | Q6: 12 | R6: 16 | T6: 48 | U6: =SUM(P6:T6) -> 76 | X6: MU R1 | Y6: WCS R0* | Z6: Interconference 1 | AB6: Yes | AC6: Yes | AD6: 5
B7: Gateon Port | D7: Boyleland | G7: SS/AC/DG 2 | I7: 8 | J7: 12 | K7: 16 | L7: 16 | M7: 64 | O7: Week 5 | P7: 32 | Q7: 12 | R7: 16 | S7: 16 | U7: =SUM(P7:T7) -> 76 | X7: MU R2 | Y7: WCS R1A | Z7: CCC R1 | AB7: Yes | AC7: Yes | AD7: 7
G8: Intrapod 1 | J8: 12 | K8: 16 | L8: 8 | M8: 48 | O8: Week 6 | Q8: 12 | R8: 16 | S8: 16 | T8: 64 | U8: =SUM(P8:T8) -> 108 | X8: MU R3 | Y8: WCS R1B | Z8: SS/AC/DG/IP 1 | AB8: Yes | AC8: Yes | AD8: 9
B9: Fiore Pod | D9: Oblivia Pod | G9: Intrapod 2 | J9: 8 | L9: 4 | M9: 64 | O9: Week 7 | P9: 32 | Q9: 12 | R9: 16 | T9: 48 | U9: =SUM(P9:T9) -> 108 | X9: MU R4 | Y9: CCC R2 | Z9: Interconference 2 | AB9: Yes | AC9: Yes | AD9: 11
B10: Fall City | D10: Dolce Island | G10: Intrapod 3 | J10: 16 | K10: 16 | L10: 2 | M10: 64 | O10: Week 8 | Q10: 12 | R10: 16 | S10: 16 | T10: 64 | U10: =SUM(P10:T10) -> 108 | X10: MU R5 | Y10: WCS R2A | Z10: SS/AC/DG/IP 2 | AB10: Yes | AC10: Yes | AD10: 13
B11: Ringtown | D11: Cocona Village | G11: Interconference 1 | J11: 8 | K11: 8 | M11: 48 | O11: Week 9 | P11: 32 | Q11: 12 | R11: 16 | S11: 16 | U11: =SUM(P11:T11) -> 76 | X11: MU R6 | Y11: WCS R2B | Z11: CCC QF | AB11: Yes | AC11: Yes | AD11: 15
B12: Summerland | D12: Tilt Village | G12: Interconference 2 | J12: 4 | K12: 4 | M12: 64 | O12: Week 10 | Q12: 8 | S12: 16 | T12: 64 | U12: =SUM(P12:T12) -> 88 | X12: UTL R20* | Y12: WCS R3A | Z12: SS/AC/DG/IP 2 | AB12: No | AC12: Yes | AD12: 16
B13: Wintown | D13: Aqua Resort | G13: Interconference 3 | J13: 2 | K13: 2 | M13: 48 | O13: Week 11 | P13: 16 | S13: 16 | T13: 48 | U13: =SUM(P13:T13) -> 80 | X13: CCC SF | Y13: WCS R3B* | Z13: Interconference 3 | AB13: Yes | AC13: Yes | AD13: 18
M14: 64 | O14: Week 12 | Q14: 8 | R14: 8 | S14: 16 | T14: 64 | U14: =SUM(P14:T14) -> 96 | X14: MU R16 | Y14: WCS R32 | Z14: SS/AC/DG/IP 2 | AB14: Yes | AC14: Yes | AD14: 20
B15: Preseason - Four games each (IP/SS/AC/DG) | I15: 1 | J15: 2 | M15: 64 | O15: Week 13 | P15: 8 | Q15: 8 | R15: 8 | S15: 16 | U15: =SUM(P15:T15) -> 40 | X15: MU R16 | Y15: WCS R32 | Z15: CCC Final | AB15: Yes | AC15: Yes | AD15: 22
I16: 4 | J16: 3 | O16: Week 14 | Q16: 4 | R16: 4 | S16: 8 | T16: 48 | U16: =SUM(P16:T16) -> 64 | X16: MU QF | Y16: WCS R16 | Z16: Interconference 4 | AB16: Yes | AC16: Yes | AD16: 24
I17: 5 | J17: 6 | O17: Week 15 | Q17: 4 | R17: 4 | S17: 8 | T17: 64 | U17: =SUM(P17:T17) -> 80 | X17: MU QF | Y17: WCS R16 | Z17: SS/AC/DG/IP 2 | AB17: Yes | AC17: Yes | AD17: 26
I18: 8 | J18: 7 | M18: 1340/1344 | O18: Week 16 | Q18: 2 | R18: 2 | S18: 4 | T18: 64 | U18: =SUM(P18:T18) -> 72 | X18: MU SF | Y18: WCS QF | Z18: Intrapod 3 | AB18: Yes | AC18: Yes | AD18: 28
C19: 48 | D19: 48 | E19: 48 | F19: 48 | M19: =64*12+8 -> 776 | N19: Season | O19: Week 17 | Q19: 2 | R19: 2 | S19: 4 | T19: 8 | U19: =SUM(P19:T19) -> 16 | X19: MU SF | Y19: WCS QF | Z19: Conf Champ | AB19: Yes | AC19: Yes | AD19: 30
B20: 1 | C20: BYE | D20: A | E20: B | F20: C | H20: 1 | I20: 2 | J20: 3 | K20: 4 | M20: =32+32+32+16+8 -> 120 | N20: CCC | O20: Week 18 | Q20: 1 | R20: 1 | S20: 4 | U20: =SUM(P20:T20) -> 6 | X20: WCS SF | Y20: WCS SF | Z20: MU Final | AB20: Yes | AC20: No | AD20: 31
B21: 8 | C21: BYE | D21: A | E21: B | F21: C | H21: 5 | I21: 6 | J21: 7 | K21: 8 | M21: 236 | N21: MRL/UTL | O21: Week 19 | Q21: 1 | R21: 1 | S21: 2 | U21: =SUM(P21:T21) -> 4 | X21: MU Final | Y21: WCS Final | Z21: WCS Final | AB21: Tuesday | AC21: Yes | AD21: 33
B22: 4 | C22: A | D22: BYE | E22: B | F22: C | H22: 12 | I22: 11 | J22: 10 | K22: 9 | M22: 158 | N22: WCS | X22: Tuesday | Y22: Thursday | Z22: Friday | AA22: Sunday
B23: 5 | C23: A | D23: BYE | E23: B | F23: C | H23: 16 | I23: 15 | J23: 14 | K23: 13 | M23: 50/54 | N23: Playoffs | O23: Week 20 | T23: 6 | U23: =SUM(P23:T23) -> 6 | X23: Play-in R1 | Y23: Play-in R1 | Z23: Play-in R2 | AA23: Play-in R2 | AB23: No | AC23: Yes | AD23: 34
B24: 2 | C24: A | D24: B | E24: BYE | F24: C | O24: Week 21 | T24: 16 | U24: =SUM(P24:T24) -> 16 | X24: OR | Y24: OR | Z24: WQF | AA24: WQF | AB24: Yes | AC24: Yes | AD24: 36
B25: 3 | C25: A | D25: B | E25: BYE | F25: C | H25: A | I25: 1 at 5 | J25: 12 at 16 | O25: Week 22 | T25: 16 | U25: =SUM(P25:T25) -> 16 | X25: LR1 | Y25: LR1 | Z25: LR2/WSF | AA25: LR2/WSF | AB25: Yes | AC25: Yes | AD25: 38
B26: 6 | C26: A | D26: B | E26: C | F26: BYE | H26: B | I26: 16 at 1 | J26: 5 at 12 | O26: Week 23 | T26: 8 | U26: =SUM(P26:T26) -> 8 | X26: LQF | Y26: LQF | Z26: LSF/WF | AA26: LSF/WF | AB26: Yes | AC26: Yes | AD26: 40
B27: 7 | C27: A | D27: B | E27: C | F27: BYE | H27: C | I27: 12 at 1 | J27: 16 at 5 | O27: Week 24 | T27: 2 | U27: =SUM(P27:T27) -> 2 | Z27: LF | AA27: LF | AC27: Yes | AD27: 41
O28: Week 25 | T28: 3 | U28: =SUM(P28:T28) -> 3 | X28: GF | Y28: GF | AA28: GF | AB28: Yes | AC28: If nec. | AD28: 42 or 43
O29: Week 26 | T29: 3 | U29: =SUM(P29:T29) -> 3 | X29: GF Reset | Y29: GF Reset | AA29: GF Reset | AB29: If nec. | AC29: If nec. | AD29: 43-44-45
M32: Playoffs | R32: 1 | S32: Conference Champion 1 | W32: Weeks 10 and 11
M33: Nos. 1-4 | N33: Top 4 Conference Champions | R33: 2 | S33: Conference Champion 2 | W33: WCS R3 - Only one week required
C34: MRL | G34: UTL | M34: Nos. 5-8 | N34: Next 4 highest teams | R34: 3 | S34: Conference Champion 3 | W34: So, anyone playing UTL R20 could play in WCS R3B
C35: Pos. 1-3 from each conference | G35: Pos. 4-6 from each conference | M35: Nos. 9-12 | N35: Remaining Conference Champions | R35: 4 | S35: Conference Champion 4
C36: World Finalists | G36: CCC Winners | N36: then next highest teams | R36: 5 | S36: Next highest ranked team 1
C37: WCS Finalists | G37: WCS Semifinalists | M37: Nos. 13-14 | N37: Next 2 highest teams | R37: 6 | S37: Next highest ranked team 2
C38: MRL Champion | G38: MRL Runner-up | N38: or next highest team and WCS Champion | R38: 7 | S38: Next highest ranked team 3
C39: UTL Champion | G39: UTL Runner-up | N39: or next highest team and MRL Champion | R39: 8 | S39: Next highest ranked team 4 | Z39: That NBA thing, reimagined
C40: Next highest overall teams until full^ | G40: Next highest overall teams until full^ | N40: or WCS Champion and MRL Champion | R40: 9 | S40: Conference Champion (5/6/7/8) or next highest team
C41: *No more than 5 per conference | G41: *No more than 5 per conference | R41: 10 | S41: Conference Champion (6/7/8) or next highest team | Z41: #11/#12 | AA41: Winner claims #11 seed | AD41: at #11
E42: **No more than 8 total per conference | N42: =12/112 -> 0.10714286 | O42: =14/112 -> 0.125 | R42: 11 | S42: Conference Champion (7/8) or next highest team | Z42: #13/#14 | AA42: Loser is eliminated | AD42: at #13
...

Sheet Season Four
B2: Conference Standings | K2: Master League | P2: Ultra League
B4: Indigo | C4: Delta | D4: Lily Valley | E4: Vertress | F4: Kalosite | G4: Lanakila | H4: Dynamax | K4: Pot A | M4: Pot C | P4: Pot A | R4: Pot C
B5: Crystal | C5: Emerald | D5: Platinum | E5: Gray | F5: Prism | G5: Kahuna | H5: Gigantamax | K5: 1 | L5: Cinnabar Island | M5: 1 | N5: Violet City | P5: 1 | Q5: Fuchsia City | R5: 1 | S5: Azalea Town
A6: 1 | B6: Cinnabar | C6: Ever Grande | D6: Resort Area | E6: Castelia | F6: Lumiose | G6: Kala'e Bay | H6: South Lakes | K6: 2 | L6: Ever Grande City | M6: 2 | N6: Slateport City | P6: 2 | Q6: Fortree City | R6: 2 | S6: Littleroot Town
A7: 2 | B7: Olivine | C7: Fallarbor | D7: Veilstone | E7: Virbank | F7: Vanivlle | G7: Ultra Mega | H7: Hulbury | K7: 3 | L7: Resort Area | M7: 3 | N7: Celestic Town | P7: 3 | Q7: Floaroma City | R7: 3 | S7: Eterna City
A8: 3 | B8: Violet | C8: Slateport | D8: Celestic | E8: Anville | F8: Laverre | G8: Malie | H8: Wyndon N | K8: 4 | L8: Castelia City | M8: 4 | N8: Anville Town | P8: 4 | Q8: Floccesy Town | R8: 4 | S8: Striaton City
A9: 4 | B9: Fuchsia | C9: Fortree | D9: Floaroma | E9: Floccesy | F9: Geosenge | G9: Iki | H9: Hammerlocke | K9: 5 | L9: Lumiose City | M9: 5 | N9: Laverre City | P9: 5 | Q9: Geosenge Town | R9: 5 | S9: Snowbelle City
A10: 5 | B10: Cianwood | C10: Dewford | D10: Snowpoint | E10: Humilau | F10: Anistar | G10: Poni | H10: Wyndon S | K10: 6 | L10: Kala'e Bay | M10: 6 | N10: Malie City | P10: 6 | Q10: Iki Town | R10: 6 | S10: Paniola Town
A11: 6 | B11: Vermilion | C11: Mauville | D11: Solaceon | E11: Mistralton | F11: Snowbelle | G11: Paniola | H11: Wedgehurst | K11: 7 | L11: South Lakes | M11: 7 | N11: Wyndon North | P11: 7 | Q11: Hammerlocke | R11: 7 | S11: Wedgehurst
A12: 7 | B12: Goldenrod | C12: Littleroot | D12: Eterna | E12: Striaton | F12: Cyllage | G12: Tapu | H12: Postwick | K12: 8 | L12: Fall City | M12: 8 | N12: Pyrite Town | P12: 8 | Q12: Aqua Resort | R12: 8 | S12: Haruba Village
A13: 8 | B13: Azalea | C13: Rustboro | D13: Twinleaf | E13: Nacrene | F13: Aquacorde | G13: Heahea | H13: Circhester Bay
A14: 9 | B14: Blackthorn | C14: Oldale | D14: Sandgem | E14: Icirrus | F14: Coumarine | G14: Hokulani | H14: Spikemuth | K14: Pot B | M14: Pot D | P14: Pot B | R14: Pot D
A15: 10 | B15: Mahogany | C15: Sootopolis | D15: Oreburgh | E15: Accumula | F15: Ambrette | G15: Aether | H15: Turffield | K15: 1 | L15: Olivine City | M15: 13 | N15: Dewford Town (Delta) | P15: 1 | Q15: Goldenrod City | R15: 25 | S15: Rustboro City (Delta)
A16: 11 | B16: Cerulean | C16: Lilycove | D16: Jubilife | E16: Undella | F16: Couriway | G16: Seafolk | H16: Ballonlea | K16: 2 | L16: Fallarbor Town | M16: 14 | N16: Cianwood City (Indigo) | P16: 2 | Q16: Mauville City | R16: 42 | S16: Cyllage City (Kalosite)
A17: 12 | B17: Saffron | C17: Pacifidlog | D17: Sunyshore | E17: Nimbasa | F17: Camphrier | G17: Exeggutor | H17: Crown Tundra | K17: 3 | L17: Veilstone City | M17: 16 | N17: Vermilion City (Indigo) | P17: 3 | Q17: Solaceon Town | R17: 44 | S17: Twinleaf Town (Lily Valley)
A18: 13 | B18: Celadon | C18: Petalburg | D18: Fight Area | E18: Driftveil | F18: Shalour | G18: Vast Poni | H18: City of Circhester | K18: 4 | L18: Virbank City | M18: 17 | N18: Humilau City (Vertress) | P18: 4 | Q18: Mistralton City | R18: 47 | S18: Coumarine Town (Kalosite)
A19: 14 | B19: Pewter | C19: Mossdeep | D19: Pastoria | E19: Lacunosa | F19: Kiloude | G19: Hau'oli | H19: Stow-on-Side | K19: 5 | L19: Vaniville Town | M19: 19 | N19: Postwick (Dynamax) | P19: 5 | Q19: Anistar City | R19: 50 | S19: Undella Town (Vertress)
A20: 15 | B20: Ecruteak | C20: Lavaridge | D20: Hearthome | E20: Opulecid | F20: Dendemille | G20: Po | H20: Isle of Armor | K20: 6 | L20: Ultra Megalopolis | M20: 22 | N20: Snowpoint City (Lily Valley) | P20: 6 | Q20: Poni Meadow | R20: 55 | S20: Heahea City (Lanakila)
A21: 16 | B21: Viridian | C21: Verdanturf | D21: Canalave | E21: Aspertia | F21: Santalune | G21: Konikoni | H21: Motostoke | K21: 7 | L21: Hulbury | P21: 7 | Q21: Wyndon South
K22: 8 | L22: Boyleland | P22: 8 | Q22: Gateon Port
O23: Finish season | S23: Skipped
O24: Sort out conference standings | R24: 49 | S24: Lilycove
O25: Complete MRL/UTL Rosters | R25: 51 | S25: Blackthorn
O26: Complete CCC Rosters | R26: 52 | S26: Nacrene
O27: Sort out WCS Roster | R27: 53 | S27: Accumula
M29: 38 | N29: Anville Town (lowest in MRL) | P29: 82 | Q29: Azalea Town (lowest in UTL)
K33: -3
K34: -2
F35: 25 | K35: -1
F36: 42 | J36: 1 | K36: 1
F37: 44 | J37: 2 | K37: 2
F38: 47 | J38: 3 | K38: 3
F39: 49 | J39: 4 | K39: 4
F40: 50 | J40: 5 | K40: 5
F41: 51 | J41: 6 | K41: 6
F42: 52 | J42: 7 | K42: 7
F43: 53 | J43: 8 | K43: 8
F44: 55 | J44: 9 | K44: 9
F45: 56 | J45: 10 | K45: 10
F46: 57 | J46: 11 | K46: 11
...

Sheet Sheet4
B1: 120 | C1: 110 | D1: 126 | E1: 158 | F1: 776 | G1: 56 | N1: 120 | O1: 110 | P1: 126 | Q1: 158 | R1: 776 | S1: 56
B2: CCC | C2: UTL | D2: MRL | E2: WCS | F2: Season | G2: Total | I2: Tuesday | J2: Thursday | K2: Weekend | N2: CCC | O2: UTL | P2: MRL | Q2: WCS | R2: Season | S2: Total | U2: Tuesday | V2: Thursday | W2: Weekend
A3: Week 1 | F3: 64 | G3: =SUM(B3:F3) -> 64 | K3: SS/AC/DG/IP 1 | M3: Week 1 | S3: =SUM(N3:R3) -> 0 | W3: SS/AC/DG/IP 1
A4: Week 2 | F4: 64 | G4: =SUM(B4:F4) -> 64 | K4: SS/AC/DG/IP 1 | M4: Week 2 | S4: =SUM(N4:R4) -> 0 | W4: SS/AC/DG/IP 1
A5: Week 3 | F5: 64 | G5: =SUM(B5:F5) -> 64 | K5: SS/AC/DG/IP 1 | M5: Week 3 | N5: 8 | O5: 12 | P5: 18 | R5: 64 | S5: =SUM(N5:R5) -> 102 | U5: MU R1 | V5: WCS R0* | W5: SS/AC/DG/IP 1
A6: Week 4 | C6: 20 | D6: 16 | F6: 64 | G6: =SUM(B6:F6) -> 100 | I6: MU R1 | J6: WCS R0* | K6: Interconference 1 | M6: Week 4 | N6: 8 | O6: 12 | P6: 18 | R6: 64 | S6: =SUM(N6:R6) -> 102 | U6: MU R2 | V6: WCS R1A | W6: Interconference 1
A7: Week 5 | B7: 32 | C7: 20 | D7: 16 | E7: 16 | G7: =SUM(B7:F7) -> 84 | I7: MU R2 | J7: WCS R1A | K7: CCC R1 | M7: Week 5 | N7: 8 | O7: 12 | P7: 18 | Q7: 16 | R7: 64 | S7: =SUM(N7:R7) -> 118 | U7: MU R3 | V7: WCS R1B
A8: Week 6 | C8: 20 | D8: 16 | E8: 16 | F8: 48 | G8: =SUM(B8:F8) -> 100 | I8: MU R3 | J8: WCS R1B | K8: SS/AC/DG/IP 1 | M8: Week 6 | N8: 8 | O8: 12 | P8: 18 | Q8: 16 | R8: 64 | S8: =SUM(N8:R8) -> 118 | U8: MU R4 | V8: WCS R2A | W8: SS/AC/DG/IP 1
A9: Week 7 | B9: 32 | C9: 20 | D9: 16 | F9: 48 | G9: =SUM(B9:F9) -> 116 | I9: MU R4 | J9: CCC R2 | K9: Interconference 2 | M9: Week 7 | N9: 8 | O9: 12 | P9: 18 | Q9: 16 | R9: 64 | S9: =SUM(N9:R9) -> 118 | U9: MU R5 | V9: WCS R2B | W9: Interconference 2
A10: Week 8 | C10: 20 | D10: 16 | E10: 16 | F10: 48 | G10: =SUM(B10:F10) -> 100 | I10: MU R5 | J10: WCS R2A | K10: SS/AC/DG/IP 2 | M10: Week 8 | N10: 8 | O10: 12 | P10: 18 | Q10: 16 | R10: 64 | S10: =SUM(N10:R10) -> 118 | U10: MU R6 | V10: WCS R3A | W10: SS/AC/DG/IP 2
A11: Week 9 | B11: 32 | C11: 20 | D11: 16 | E11: 16 | G11: =SUM(B11:F11) -> 84 | I11: MU R6 | J11: WCS R2B | K11: CCC QF | M11: Week 9 | N11: 8 | O11: 12 | P11: 18 | Q11: 16 | R11: 64 | S11: =SUM(N11:R11) -> 118 | U11: MU R7 | V11: WCS R3B
A12: Week 10 | E12: 16 | F12: 64 | G12: =SUM(B12:F12) -> 80 | I12: UTL R20* | J12: WCS R3A | K12: SS/AC/DG/IP 2 | M12: Week 10 | N12: 8 | O12: 12 | P12: 18 | Q12: 16 | R12: 64 | S12: =SUM(N12:R12) -> 118 | U12: MU R8 | V12: WCS R32 | W12: SS/AC/DG/IP 2
A13: Week 11 | B13: 16 | E13: 16 | F13: 64 | G13: =SUM(B13:F13) -> 96 | I13: CCC SF | J13: WCS R3B* | K13: Interconference 3 | M13: Week 11 | N13: 8 | O13: 12 | P13: 18 | Q13: 16 | R13: 64 | S13: =SUM(N13:R13) -> 118 | U13: MU R9 | V13: WCS R32 | W13: Interconference 3
A14: Week 12 | C14: 8 | D14: 8 | E14: 16 | F14: 64 | G14: =SUM(B14:F14) -> 96 | I14: MU R16 | J14: WCS R32 | K14: SS/AC/DG/IP 2 | M14: Week 12 | N14: 8 | O14: 12 | P14: 18 | Q14: 16 | R14: 48 | S14: =SUM(N14:R14) -> 102 | U14: MU R10 | V14: WCS R16 | W14: SS/AC/DG/IP 2
A15: Week 13 | B15: 8 | C15: 8 | D15: 8 | E15: 16 | G15: =SUM(B15:F15) -> 40 | I15: MU R16 | J15: WCS R32 | K15: CCC Final | M15: Week 13 | N15: 8 | O15: 8 | P15: 8 | Q15: 16 | R15: 48 | S15: =SUM(N15:R15) -> 88 | U15: MU R16 | V15: WCS R16
A16: Week 14 | C16: 4 | D16: 4 | E16: 8 | F16: 48 | G16: =SUM(B16:F16) -> 64 | I16: MU QF | J16: WCS R16 | K16: Interconference 4 | M16: Week 14 | N16: 8 | O16: 8 | P16: 8 | Q16: 8 | R16: 48 | S16: =SUM(N16:R16) -> 80 | U16: MU R16 | V16: WCS QF | W16: Interconference 4
A17: Week 15 | C17: 4 | D17: 4 | E17: 8 | F17: 64 | G17: =SUM(B17:F17) -> 80 | I17: MU QF | J17: WCS R16 | K17: SS/AC/DG/IP 2 | M17: Week 15 | N17: 4 | O17: 4 | P17: 4 | Q17: 8 | R17: 48 | S17: =SUM(N17:R17) -> 68 | U17: MU QF | V17: WCS QF | W17: SS/AC/DG/IP 2
A18: Week 16 | C18: 2 | D18: 2 | E18: 4 | F18: 64 | G18: =SUM(B18:F18) -> 72 | I18: MU SF | J18: WCS QF | K18: Intrapod 3 | M18: Week 16 | N18: 4 | O18: 4 | P18: 4 | Q18: 4 | S18: =SUM(N18:R18) -> 16 | U18: MU QF | V18: WCS SF | W18: Intrapod 3
A19: Week 17 | C19: 2 | D19: 2 | E19: 4 | F19: 8 | G19: =SUM(B19:F19) -> 16 | I19: MU SF | J19: WCS QF | K19: Conf Champ | M19: Week 17 | N19: 2 | O19: 2 | P19: 2 | Q19: 4 | S19: =SUM(N19:R19) -> 10 | U19: MU SF | V19: WCS SF | W19: Conf Champ
A20: Week 18 | C20: 1 | D20: 1 | E20: 4 | G20: =SUM(B20:F20) -> 6 | I20: WCS SF | J20: WCS SF | K20: MU Final | M20: Week 18 | N20: 2 | O20: 2 | P20: 2 | Q20: 4 | S20: =SUM(N20:R20) -> 10 | U20: MU SF | V20: WCS Final
A21: Week 19 | C21: 1 | D21: 1 | E21: 2 | G21: =SUM(B21:F21) -> 4 | I21: MU Final | J21: WCS Final | K21: WCS Final | M21: Week 19 | N21: 1 | O21: 1 | P21: 1 | Q21: 2 | S21: =SUM(N21:R21) -> 5 | U21: MU Final | V21: WCS Final
M22: Week 20 | N22: 1 | O22: 1 | P22: 1 | S22: =SUM(N22:R22) -> 3 | U22: MU Final | W22: CCC R1
A23: Week 20 | F23: 6 | G23: =SUM(B23:F23) -> 6 | S23: =SUM(N23:R23) -> 0 | V23: CCC R2 | W23: CCC QF
A24: Week 21 | F24: 16 | G24: =SUM(B24:F24) -> 16 | M24: Week 21 | S24: =SUM(N24:R24) -> 0 | V24: CCC SF | W24: CCC Final
A25: Week 22 | F25: 16 | G25: =SUM(B25:F25) -> 16 | M25: Week 22 | S25: =SUM(N25:R25) -> 0
A26: Week 23 | F26: 8 | G26: =SUM(B26:F26) -> 8 | M26: Week 23 | S26: =SUM(N26:R26) -> 0
A27: Week 24 | F27: 2 | G27: =SUM(B27:F27) -> 2 | M27: Week 24 | S27: =SUM(N27:R27) -> 0
A28: Week 25 | F28: 3 | G28: =SUM(B28:F28) -> 3 | M28: Week 25 | S28: =SUM(N28:R28) -> 0
A29: Week 26 | F29: 3 | G29: =SUM(B29:F29) -> 3 | M29: Week 26 | S29: =SUM(N29:R29) -> 0
B31: =SUM(B33:B52) -> 0 | C31: =SUM(C33:C52) -> 190 | D31: =SUM(D33:D52) -> 190 | E31: =SUM(E33:E52) -> 142 | F31: 768+120 | G31: 64 | I31: =482+768+120+60 -> 1430 | K31: UTL R20*
B32: GRL | C32: UTL | D32: MRL | E32: WCS | F32: Season | G32: Total | I32: 1412
A33: 1 | F33: 64 | G33: =SUM(B33:F33) -> 64 | I33: 1274+60 | K33: SS/AC/DG/IP 1
A34: 2 | F34: 64 | G34: =SUM(B34:F34) -> 64 | I34: =1274 -> 1274 | K34: SS/AC/DG/IP 1 | U34: 4 winners
A35: 3 | F35: 64 | G35: =SUM(B35:F35) -> 64 | K35: SS/AC/DG/IP 1 | M35: =150+190+142+768+120+60 -> 1430 | N35: 8x4/6x4 | U35: next 4
A36: 4 | C36: 16 | D36: 16 | E36: 16 | F36: 48 | G36: =SUM(B36:F36) -> 96 | I36: MU R1 | J36: WCS R1A | K36: Interconference 1 | M36: 1550 | N36: 6x6/4x6 | P36: 6 first | U36: X winners
A37: 5 | C37: 16 | D37: 16 | E37: 16 | F37: 48 | G37: =SUM(B37:F37) -> 96 | I37: MU R2 | J37: WCS R1B | K37: Interconference 2 | P37: 6 second | U37: next X
A38: 6 | C38: 16 | D38: 16 | E38: 16 | F38: 64 | G38: =SUM(B38:F38) -> 112 | I38: MU R3 | J38: WCS R2A | K38: SS/AC/DG/IP 1 | M38: =190+190+142+768+120+64 -> 1474 | P38: 4/6 third | Q38: 2/6 third
A39: 7 | C39: 16 | D39: 16 | E39: 16 | F39: 64 | G39: =SUM(B39:F39) -> 112 | I39: MU R4 | J39: WCS R2B | K39: SS/AC/DG/IP 2 | M39: 1474 or 1490 (WCS R4) | Q39: 6 fourth
A40: 8 | C40: 32 | D40: 32 | G40: =SUM(B40:F40) -> 64 | I40: MU R5 | J40: MU R6 | M40: 1470-1474 or 1486-1490 | Q40: 4 first
A41: 9 | C41: 16 | D41: 16 | E41: 16 | F41: 48 | G41: =SUM(B41:F41) -> 96 | I41: MU R7 | J41: WCS R3A | K41: Interconference 3 | Q41: 4 second
...

Sheet Sheet1
C2: Lumiose City | D2: 13 | E2: 9 | F2: =D2-E2 -> 4
C3: Resort Area | D3: 12 | E3: 8 | F3: =D3-E3 -> 4
C4: Ever Grande City | D4: 11 | E4: 7 | F4: =D4-E4 -> 4
C5: Kala'e Bay | D5: 11 | E5: 7 | F5: =D5-E5 -> 4
C6: Malie City | D6: 11 | E6: 7 | F6: =D6-E6 -> 4
C7: Cianwood City | D7: 10 | E7: 6 | F7: =D7-E7 -> 4
C8: Vermilion City | D8: 10 | E8: 6 | F8: =D8-E8 -> 4
C9: Postwick | D9: 10 | E9: 6 | F9: =D9-E9 -> 4
C10: Littleroot Town | D10: 9 | E10: 5 | F10: =D10-E10 -> 4
C11: Saffron City | D11: 6 | E11: 2 | F11: =D11-E11 -> 4
C12: Cinnabar Island | D12: 12 | E12: 9 | F12: =D12-E12 -> 3
C13: South Lakes | D13: 12 | E13: 9 | F13: =D13-E13 -> 3
... C113: Motostoke | D113: 1 | E113: 1 | F113: =D113-E113 -> 0

Sheet Season 3
A1: VLOOKUP(A2, Sheet7!$C$62:$F$173, 4, FALSE) | B1: START | C1: W1 | D1: W2 | E1: W3 | F1: W4 | G1: W5 | H1: W6 | I1: W7 | J1: W8 | K1: W9 | L1: W10 | M1: W11 | N1: W12 | O1: W13 | P1: W14 | Q1: W15 | R1: W16 | S1: W17 | T1: W18 | U1: W19 | V1: W20 | W1: W21 | X1: W22 | Y1: W23 | Z1: W24 | AA1: W25 | AB1: W26 | AC1: W27 | AD1: W28 | AE1: W29 | AF1: W30 | AG1: W31 | AH1: W32 | AI1: W33 | AJ1: W34 | AK1: W35 | AL1: W36 | AM1: W37 | AN1: W38 | AO1: W39 | AP1: W40 | AQ1: W41 | AR1: W42 | AS1: W43 | AT1: W44 | AU1: W45 | AV1: W46 | AW1: W47 | AX1: W48 | AY1: W49 | AZ1: W50 | BA1: W51 | BB1: W52 | BC1: W53 | BD1: W54 | BE1: W55 | BF1: W56 | BG1: W57 | BH1: W58 | BI1: W59 | BJ1: W60 | BK1: W61 | BL1: W62 | BM1: W63 | BN1: W64 | BO1: W65 | BP1: W66 | BQ1: W67 | BR1: W68 | BS1: W69 | BT1: W70 | BU1: W71 | BV1: W72 | BW1: W73 | BX1: W74 | BY1: W75 | BZ1: W76 | CA1: W77 | CB1: W78
A2: Resort Area | B2: 1782 | C2: 1796 | D2: 1814 | E2: 1834 | F2: 1846 | G2: 1846 | H2: 1846 | I2: 1855 | J2: 1855 | K2: 1870 | L2: 1889 | M2: 1907 | N2: 1920 | O2: 1901 | P2: 1915 | Q2: 1934 | R2: 1934 | S2: 1934 | T2: 1952 | U2: 1938 | V2: 1949 | W2: 1925 | X2: 1940 | Y2: 1956 | Z2: 1961 | AA2: 1961 | AB2: 1961 | AC2: 1982 | AD2: 1961 | AE2: 1972 | AF2: 1972 | AG2: 1972 | AH2: 1984 | AI2: 1959 | AJ2: 1972 | AK2: 1972 | AL2: 1972 | AM2: 1972 | AN2: 1972 | AO2: 1979 | AP2: 1979 | AQ2: 1979 | AR2: 1999 | AS2: 2013 | AT2: 2016 | AU2: 2034 | AV2: 2048 | AW2: 2048 | AX2: 2048 | AY2: 2061 | AZ2: 2075 | BA2: 2075 | BB2: 2075 | BC2: 2096 | BD2: 2114 | BE2: 2126 | BF2: 2126 | BG2: 2126 | BH2: 2126 | BI2: 2126 | BJ2: 2126 | BK2: 2126 | BL2: 2143 | BM2: 2107 | BN2: 2107 | BO2: 2107 | BP2: 2085 | BQ2: 2123 | BR2: 2123 | BS2: 2123 | BT2: 2101 | BU2: 2083 | BV2: 2065 | BW2: 2095 | BX2: 2127 | BY2: 2154 | BZ2: 2125 | CA2: 2158 | CB2: 2180 | CC2: 42
A3: Lumiose City | B3: 1906 | C3: 1918 | D3: 1928 | E3: 1941 | F3: 1953 | G3: 1953 | H3: 1953 | I3: 1962 | J3: 1962 | K3: 1962 | L3: 1969 | M3: 1969 | N3: 1969 | O3: 1979 | P3: 1990 | Q3: 1996 | R3: 2008 | S3: 1986 | T3: 1996 | U3: 2002 | V3: 2002 | W3: 2002 | X3: 2002 | Y3: 2002 | Z3: 2014 | AA3: 1993 | AB3: 2014 | AC3: 2029 | AD3: 2043 | AE3: 2052 | AF3: 2058 | AG3: 2064 | AH3: 2064 | AI3: 2064 | AJ3: 2070 | AK3: 2088 | AL3: 2106 | AM3: 2127 | AN3: 2105 | AO3: 2107 | AP3: 2119 | AQ3: 2088 | AR3: 2088 | AS3: 2088 | AT3: 2094 | AU3: 2117 | AV3: 2137 | AW3: 2109 | AX3: 2082 | AY3: 2056 | AZ3: 2075 | BA3: 2075 | BB3: 2075 | BC3: 2094 | BD3: 2094 | BE3: 2094 | BF3: 2094 | BG3: 2094 | BH3: 2094 | BI3: 2094 | BJ3: 2094 | BK3: 2094 | BL3: 2116 | BM3: 2139 | BN3: 2139 | BO3: 2139 | BP3: 2161 | BQ3: 2123 | BR3: 2143 | BS3: 2111 | BT3: 2141 | BU3: 2160 | BV3: 2178 | BW3: 2148 | BX3: 2148 | BY3: 2148 | BZ3: 2148 | CA3: 2148 | CB3: 2148 | CC3: 72
A4: Kala'e Bay | B4: 1849 | C4: 1833 | D4: 1852 | E4: 1871 | F4: 1881 | G4: 1881 | H4: 1881 | I4: 1893 | J4: 1893 | K4: 1893 | L4: 1906 | M4: 1906 | N4: 1906 | O4: 1919 | P4: 1894 | Q4: 1916 | R4: 1944 | S4: 1964 | T4: 1978 | U4: 1985 | V4: 1996 | W4: 2005 | X4: 2005 | Y4: 2005 | Z4: 2010 | AA4: 2021 | AB4: 2030 | AC4: 2043 | AD4: 2057 | AE4: 2063 | AF4: 2072 | AG4: 2082 | AH4: 2082 | AI4: 2082 | AJ4: 2086 | AK4: 2095 | AL4: 2107 | AM4: 2118 | AN4: 2131 | AO4: 2138 | AP4: 2142 | AQ4: 2146 | AR4: 2146 | AS4: 2146 | AT4: 2124 | AU4: 2101 | AV4: 2081 | AW4: 2100 | AX4: 2115 | AY4: 2115 | AZ4: 2115 | BA4: 2134 | BB4: 2108 | BC4: 2115 | BD4: 2095 | BE4: 2075 | BF4: 2075 | BG4: 2075 | BH4: 2075 | BI4: 2075 | BJ4: 2089 | BK4: 2104 | BL4: 2130 | BM4: 2102 | BN4: 2102 | BO4: 2102 | BP4: 2132 | BQ4: 2158 | BR4: 2158 | BS4: 2158 | BT4: 2180 | BU4: 2198 | BV4: 2198 | BW4: 2198 | BX4: 2166 | BY4: 2139 | BZ4: 2168 | CA4: 2135 | CB4: 2113 | CC4: 87
A5: South Lakes | B5: 1796 | C5: 1809 | D5: 1824 | E5: 1834 | F5: 1852 | G5: 1852 | H5: 1870 | I5: 1880 | J5: 1891 | K5: 1867 | L5: 1877 | M5: 1892 | N5: 1908 | O5: 1908 | P5: 1908 | Q5: 1890 | R5: 1890 | S5: 1890 | T5: 1890 | U5: 1902 | V5: 1924 | W5: 1904 | X5: 1904 | Y5: 1904 | Z5: 1913 | AA5: 1913 | AB5: 1913 | AC5: 1913 | AD5: 1913 | AE5: 1919 | AF5: 1941 | AG5: 1955 | AH5: 1955 | AI5: 1955 | AJ5: 1968 | AK5: 1968 | AL5: 1968 | AM5: 1968 | AN5: 1968 | AO5: 1979 | AP5: 1995 | AQ5: 2012 | AR5: 2012 | AS5: 2012 | AT5: 2020 | AU5: 2020 | AV5: 2020 | AW5: 2048 | AX5: 2075 | AY5: 2075 | AZ5: 2075 | BA5: 2056 | BB5: 2082 | BC5: 2096 | BD5: 2096 | BE5: 2096 | BF5: 2096 | BG5: 2096 | BH5: 2096 | BI5: 2096 | BJ5: 2096 | BK5: 2096 | BL5: 2070 | BM5: 2098 | BN5: 2115 | BO5: 2128 | BP5: 2092 | BQ5: 2060 | BR5: 2060 | BS5: 2060 | BT5: 2060 | BU5: 2060 | BV5: 2060 | BW5: 2060 | BX5: 2060 | BY5: 2060 | BZ5: 2060 | CA5: 2060 | CB5: 2060 | CC5: 107
A6: Cinnabar Island | B6: 1888 | C6: 1904 | D6: 1920 | E6: 1934 | F6: 1940 | G6: 1940 | H6: 1940 | I6: 1949 | J6: 1949 | K6: 1949 | L6: 1955 | M6: 1955 | N6: 1955 | O6: 1971 | P6: 1986 | Q6: 1970 | R6: 1951 | S6: 1969 | T6: 1981 | U6: 1994 | V6: 1994 | W6: 1994 | X6: 1994 | Y6: 1994 | Z6: 2005 | AA6: 2013 | AB6: 2020 | AC6: 1991 | AD6: 2010 | AE6: 2017 | AF6: 2028 | AG6: 2035 | AH6: 2035 | AI6: 2035 | AJ6: 2044 | AK6: 2026 | AL6: 2008 | AM6: 2032 | AN6: 2005 | AO6: 2013 | AP6: 2038 | AQ6: 2053 | AR6: 2053 | AS6: 2053 | AT6: 2064 | AU6: 2064 | AV6: 2064 | AW6: 2091 | AX6: 2108 | AY6: 2108 | AZ6: 2108 | BA6: 2121 | BB6: 2090 | BC6: 2109 | BD6: 2129 | BE6: 2149 | BF6: 2149 | BG6: 2149 | BH6: 2149 | BI6: 2149 | BJ6: 2149 | BK6: 2149 | BL6: 2167 | BM6: 2188 | BN6: 2188 | BO6: 2188 | BP6: 2158 | BQ6: 2132 | BR6: 2144 | BS6: 2106 | BT6: 2076 | BU6: 2057 | BV6: 2057 | BW6: 2057 | BX6: 2057 | BY6: 2057 | BZ6: 2057 | CA6: 2057 | CB6: 2057 | CC6: 13
A7: Virbank City | B7: 1782 | C7: 1799 | D7: 1788 | E7: 1780 | F7: 1794 | G7: 1794 | H7: 1794 | I7: 1812 | J7: 1812 | K7: 1812 | L7: 1821 | M7: 1821 | N7: 1821 | O7: 1849 | P7: 1833 | Q7: 1848 | R7: 1864 | S7: 1875 | T7: 1898 | U7: 1906 | V7: 1906 | W7: 1906 | X7: 1906 | Y7: 1906 | Z7: 1915 | AA7: 1926 | AB7: 1937 | AC7: 1952 | AD7: 1923 | AE7: 1931 | AF7: 1945 | AG7: 1921 | AH7: 1921 | AI7: 1921 | AJ7: 1926 | AK7: 1941 | AL7: 1956 | AM7: 1986 | AN7: 2012 | AO7: 2024 | AP7: 2041 | AQ7: 2008 | AR7: 2008 | AS7: 2008 | AT7: 2013 | AU7: 1993 | AV7: 2020 | AW7: 2020 | AX7: 2020 | AY7: 2046 | AZ7: 2027 | BA7: 2027 | BB7: 2027 | BC7: 2006 | BD7: 1985 | BE7: 1970 | BF7: 1970 | BG7: 1970 | BH7: 1970 | BI7: 1970 | BJ7: 1989 | BK7: 2006 | BL7: 1988 | BM7: 1967 | BN7: 2003 | BO7: 1977 | BP7: 2013 | BQ7: 2045 | BR7: 2025 | BS7: 2057 | BT7: 2057 | BU7: 2057 | BV7: 2057 | BW7: 2057 | BX7: 2057 | BY7: 2057 | BZ7: 2057 | CA7: 2057 | CB7: 2057 | CC7: 56
A8: Veilstone City | B8: 1835 | C8: 1845 | D8: 1854 | E8: 1839 | F8: 1856 | G8: 1856 | H8: 1856 | I8: 1869 | J8: 1869 | K8: 1883 | L8: 1894 | M8: 1908 | N8: 1919 | O8: 1934 | P8: 1947 | Q8: 1928 | R8: 1928 | S8: 1928 | T8: 1940 | U8: 1945 | V8: 1955 | W8: 1962 | X8: 1972 | Y8: 1983 | Z8: 1994 | AA8: 1994 | AB8: 1994 | AC8: 1973 | AD8: 1994 | AE8: 1999 | AF8: 2016 | AG8: 2032 | AH8: 2042 | AI8: 2014 | AJ8: 2021 | AK8: 2021 | AL8: 2021 | AM8: 2044 | AN8: 2061 | AO8: 2067 | AP8: 2044 | AQ8: 2021 | AR8: 2029 | AS8: 2039 | AT8: 2044 | AU8: 2057 | AV8: 2071 | AW8: 2071 | AX8: 2071 | AY8: 2040 | AZ8: 2017 | BA8: 2017 | BB8: 2017 | BC8: 1996 | BD8: 1996 | BE8: 1996 | BF8: 1996 | BG8: 1996 | BH8: 1996 | BI8: 1996 | BJ8: 1974 | BK8: 2004 | BL8: 1987 | BM8: 2023 | BN8: 2036 | BO8: 2000 | BP8: 2000 | BQ8: 2000 | BR8: 2000 | BS8: 2000 | BT8: 2000 | BU8: 2000 | BV8: 2000 | BW8: 2000 | BX8: 2000 | BY8: 2000 | BZ8: 2000 | CA8: 2000 | CB8: 2000 | CC8: 44
A9: Vaniville Town | B9: 1977 | C9: 1989 | D9: 1998 | E9: 1979 | F9: 1987 | G9: 1987 | H9: 1987 | I9: 2002 | J9: 2002 | K9: 2002 | L9: 1983 | M9: 1983 | N9: 1983 | O9: 1992 | P9: 2001 | Q9: 2007 | R9: 2016 | S9: 2025 | T9: 2034 | U9: 2041 | V9: 2048 | W9: 2053 | X9: 2053 | Y9: 2053 | Z9: 2058 | AA9: 2067 | AB9: 2042 | AC9: 2048 | AD9: 2055 | AE9: 2061 | AF9: 2040 | AG9: 2059 | AH9: 2059 | AI9: 2059 | AJ9: 2065 | AK9: 2080 | AL9: 2096 | AM9: 2075 | AN9: 2097 | AO9: 2101 | AP9: 2109 | AQ9: 2119 | AR9: 2119 | AS9: 2119 | AT9: 2095 | AU9: 2065 | AV9: 2081 | AW9: 2054 | AX9: 2037 | AY9: 2013 | AZ9: 2037 | BA9: 2037 | BB9: 2037 | BC9: 2018 | BD9: 2018 | BE9: 2018 | BF9: 2018 | BG9: 2018 | BH9: 2018 | BI9: 2018 | BJ9: 2040 | BK9: 2010 | BL9: 2010 | BM9: 2010 | BN9: 1974 | BO9: 2000 | BP9: 2000 | BQ9: 2000 | BR9: 2000 | BS9: 2000 | BT9: 2000 | BU9: 2000 | BV9: 2000 | BW9: 2000 | BX9: 2000 | BY9: 2000 | BZ9: 2000 | CA9: 2000 | CB9: 2000 | CC9: 80
A10: Castelia City | B10: 1928 | C10: 1936 | D10: 1942 | E10: 1948 | F10: 1956 | G10: 1956 | H10: 1956 | I10: 1930 | J10: 1930 | K10: 1930 | L10: 1914 | M10: 1914 | N10: 1914 | O10: 1926 | P10: 1936 | Q10: 1943 | R10: 1925 | S10: 1939 | T10: 1958 | U10: 1965 | V10: 1965 | W10: 1965 | X10: 1965 | Y10: 1965 | Z10: 1976 | AA10: 1984 | AB10: 1994 | AC10: 1976 | AD10: 1955 | AE10: 1967 | AF10: 1978 | AG10: 1987 | AH10: 1987 | AI10: 1987 | AJ10: 1995 | AK10: 1973 | AL10: 2000 | AM10: 2000 | AN10: 2000 | AO10: 1988 | AP10: 1963 | AQ10: 1948 | AR10: 1948 | AS10: 1948 | AT10: 1956 | AU10: 1989 | AV10: 2014 | AW10: 2014 | AX10: 2014 | AY10: 2038 | AZ10: 2014 | BA10: 2014 | BB10: 2014 | BC10: 2035 | BD10: 2056 | BE10: 2071 | BF10: 2071 | BG10: 2071 | BH10: 2071 | BI10: 2071 | BJ10: 2039 | BK10: 2059 | BL10: 2037 | BM10: 2014 | BN10: 2028 | BO10: 1982 | BP10: 1982 | BQ10: 1982 | BR10: 1982 | BS10: 1982 | BT10: 1982 | BU10: 1982 | BV10: 1982 | BW10: 1982 | BX10: 1982 | BY10: 1982 | BZ10: 1982 | CA10: 1982 | CB10: 1982 | CC10: 58
A11: Cianwood City | B11: 1810 | C11: 1822 | D11: 1835 | E11: 1849 | F11: 1833 | G11: 1833 | H11: 1833 | I11: 1845 | J11: 1858 | K11: 1858 | L11: 1867 | M11: 1878 | N11: 1889 | O11: 1914 | P11: 1927 | Q11: 1934 | R11: 1943 | S11: 1951 | T11: 1968 | U11: 1945 | V11: 1957 | W11: 1930 | X11: 1930 | Y11: 1930 | Z11: 1943 | AA11: 1964 | AB11: 1943 | AC11: 1957 | AD11: 1971 | AE11: 1981 | AF11: 1981 | AG11: 1981 | AH11: 1981 | AI11: 1981 | AJ11: 1992 | AK11: 1971 | AL11: 1995 | AM11: 1971 | AN11: 1998 | AO11: 2008 | AP11: 2008 | AQ11: 2008 | AR11: 2008 | AS11: 2008 | AT11: 1993 | AU11: 1993 | AV11: 1993 | AW11: 1993 | AX11: 1993 | AY11: 1993 | AZ11: 1993 | BA11: 1993 | BB11: 1993 | BC11: 1993 | BD11: 1993 | BE11: 1993 | BF11: 2012 | BG11: 1982 | BH11: 1982 | BI11: 1982 | BJ11: 1982 | BK11: 1982 | BL11: 1982 | BM11: 1982 | BN11: 1982 | BO11: 1982 | BP11: 1982 | BQ11: 1982 | BR11: 1982 | BS11: 1982 | BT11: 1982 | BU11: 1982 | BV11: 1982 | BW11: 1982 | BX11: 1982 | BY11: 1982 | BZ11: 1982 | CA11: 1982 | CB11: 1982 | CC11: 1
A12: Humilau City | B12: 1908 | C12: 1889 | D12: 1898 | E12: 1909 | F12: 1920 | G12: 1920 | H12: 1920 | I12: 1928 | J12: 1928 | K12: 1938 | L12: 1945 | M12: 1945 | N12: 1945 | O12: 1957 | P12: 1968 | Q12: 1975 | R12: 1994 | S12: 1977 | T12: 1986 | U12: 1992 | V12: 2000 | W12: 2008 | X12: 2008 | Y12: 2008 | Z12: 1991 | AA12: 1999 | AB12: 2006 | AC12: 2024 | AD12: 2045 | AE12: 2026 | AF12: 2033 | AG12: 2040 | AH12: 2040 | AI12: 2040 | AJ12: 2045 | AK12: 2055 | AL12: 2064 | AM12: 2034 | AN12: 2008 | AO12: 1988 | AP12: 2011 | AQ12: 2034 | AR12: 2034 | AS12: 2034 | AT12: 2012 | AU12: 2032 | AV12: 2005 | AW12: 1986 | AX12: 1971 | AY12: 1971 | AZ12: 1971 | BA12: 1971 | BB12: 1971 | BC12: 1971 | BD12: 1971 | BE12: 1971 | BF12: 1971 | BG12: 1971 | BH12: 1971 | BI12: 1971 | BJ12: 1971 | BK12: 1971 | BL12: 1971 | BM12: 1971 | BN12: 1971 | BO12: 1971 | BP12: 1971 | BQ12: 1971 | BR12: 1971 | BS12: 1971 | BT12: 1971 | BU12: 1971 | BV12: 1971 | BW12: 1971 | BX12: 1971 | BY12: 1971 | BZ12: 1971 | CA12: 1971 | CB12: 1971 | CC12: 61
A13: Rustboro City | B13: 1940 | C13: 1949 | D13: 1931 | E13: 1913 | F13: 1895 | G13: 1895 | H13: 1895 | I13: 1907 | J13: 1907 | K13: 1907 | L13: 1917 | M13: 1917 | N13: 1917 | O13: 1926 | P13: 1936 | Q13: 1914 | R13: 1933 | S13: 1915 | T13: 1930 | U13: 1942 | V13: 1942 | W13: 1942 | X13: 1942 | Y13: 1942 | Z13: 1930 | AA13: 1945 | AB13: 1957 | AC13: 1975 | AD13: 1987 | AE13: 1999 | AF13: 2020 | AG13: 2001 | AH13: 2001 | AI13: 2001 | AJ13: 2007 | AK13: 2028 | AL13: 2004 | AM13: 2024 | AN13: 2041 | AO13: 2018 | AP13: 2018 | AQ13: 2018 | AR13: 2018 | AS13: 2018 | AT13: 2022 | AU13: 1989 | AV13: 1964 | AW13: 1964 | AX13: 1964 | AY13: 1964 | AZ13: 1964 | BA13: 1964 | BB13: 1964 | BC13: 1964 | BD13: 1964 | BE13: 1964 | BF13: 1964 | BG13: 1964 | BH13: 1964 | BI13: 1964 | BJ13: 1964 | BK13: 1964 | BL13: 1964 | BM13: 1964 | BN13: 1964 | BO13: 1964 | BP13: 1964 | BQ13: 1964 | BR13: 1964 | BS13: 1964 | BT13: 1964 | BU13: 1964 | BV13: 1964 | BW13: 1964 | BX13: 1964 | BY13: 1964 | BZ13: 1964 | CA13: 1964 | CB13: 1964 | CC13: 23
... A113: Isle of Armor | B113: 1807 | C113: 1791 | D113: 1779 | E113: 1760 | F113: 1771 | G113: 1771 | H113: 1771 | I113: 1757 | J113: 1757 | K113: 1757 | L113: 1741 | M113: 1741 | N113: 1741 | O113: 1724 | P113: 1749 | Q113: 1734 | R113: 1717 | S113: 1705 | T113: 1688 | U113: 1679 | V113: 1661 | W113: 1650 | X113: 1650 | Y113: 1650 | Z113: 1641 | AA113: 1631 | AB113: 1619 | AC113: 1619 | AD113: 1619 | AE113: 1607 | AF113: 1607 | AG113: 1607 | AH113: 1607 | AI113: 1607 | AJ113: 1602 | AK113: 1602 | AL113: 1602 | AM113: 1602 | AN113: 1602 | AO113: 1595 | AP113: 1595 | AQ113: 1595 | AR113: 1595 | AS113: 1595 | AT113: 1608 | AU113: 1608 | AV113: 1608 | AW113: 1608 | AX113: 1608 | AY113: 1608 | AZ113: 1608 | BA113: 1608 | BB113: 1608 | BC113: 1608 | BD113: 1608 | BE113: 1608 | BF113: 1608 | BG113: 1608 | BH113: 1608 | BI113: 1608 | BJ113: 1608 | BK113: 1608 | BL113: 1608 | BM113: 1608 | BN113: 1608 | BO113: 1608 | BP113: 1608 | BQ113: 1608 | BR113: 1608 | BS113: 1608 | BT113: 1608 | BU113: 1608 | BV113: 1608 | BW113: 1608 | BX113: 1608 | BY113: 1608 | BZ113: 1608 | CA113: 1608 | CB113: 1608 | CC113: 110

Sheet Sheet7
I1: 48 | J1: 78 | K1: OLD ELO | L1: OLD ELO | N1: 24=Regular // 32=WCS Rounds 1-5, MRL/UTL Group, CCC R1+R2 // 40=WCS/MRL/UTL Last 16, CCC Last 8 // 48=Playoffs
C2: Resort Area | D2: 17 | E2: 15 | F2: Kala'e Bay | H2: =D2-E2 -> 2 | I2: =$I$1+H2-4 -> 46 | K2: =VLOOKUP(C2, 'Season 3'!$A$2:$CH$113, $J$1+1, FALSE) -> 2158 | L2: =VLOOKUP(F2, 'Season 3'!$A$2:$CH$113, $J$1+1, FALSE) -> 2135 | N2: =1/(10^(-(K2-L2)/400)+1) -> 0.53305139 | O2: =1-N2 -> 0.46694861 | Q2: =ROUNDUP(I2*(1-N2),0) -> 22 | S2: =K2+Q2 -> 2180 | T2: =L2-Q2 -> 2113
H3: =D3-E3 -> 0 | I3: =$I$1+H3-4 -> 44 | K3: =VLOOKUP(C3, 'Season 3'!$A$2:$CH$113, $J$1+1, FALSE) -> #N/A | L3: =VLOOKUP(F3, 'Season 3'!$A$2:$CH$113, $J$1+1, FALSE) -> #N/A | N3: =1/(10^(-(K3-L3)/400)+1) -> #N/A | O3: =1-N3 -> #N/A | Q3: =ROUNDUP(I3*(1-N3),0) -> #N/A | S3: =K3+Q3 -> #N/A | T3: =L3-Q3 -> #N/A
H4: =D4-E4 -> 0 | I4: =$I$1+H4-4 -> 44 | K4: =VLOOKUP(C4, 'Season 3'!$A$2:$CH$113, $J$1+1, FALSE) -> #N/A | L4: =VLOOKUP(F4, 'Season 3'!$A$2:$CH$113, $J$1+1, FALSE) -> #N/A | N4: =1/(10^(-(K4-L4)/400)+1) -> #N/A | O4: =1-N4 -> #N/A | Q4: =ROUNDUP(I4*(1-N4),0) -> #N/A | S4: =K4+Q4 -> #N/A | T4: =L4-Q4 -> #N/A
H5: =D5-E5 -> 0 | I5: =$I$1+H5-4 -> 44 | K5: =VLOOKUP(C5, 'Season 3'!$A$2:$CH$113, $J$1+1, FALSE) -> #N/A | L5: =VLOOKUP(F5, 'Season 3'!$A$2:$CH$113, $J$1+1, FALSE) -> #N/A | N5: =1/(10^(-(K5-L5)/400)+1) -> #N/A | O5: =1-N5 -> #N/A | Q5: =ROUNDUP(I5*(1-N5),0) -> #N/A | S5: =K5+Q5 -> #N/A | T5: =L5-Q5 -> #N/A
H6: =D6-E6 -> 0 | I6: =$I$1+H6-4 -> 44 | K6: =VLOOKUP(C6, 'Season 3'!$A$2:$CH$113, $J$1+1, FALSE) -> #N/A | L6: =VLOOKUP(F6, 'Season 3'!$A$2:$CH$113, $J$1+1, FALSE) -> #N/A | N6: =1/(10^(-(K6-L6)/400)+1) -> #N/A | O6: =1-N6 -> #N/A | Q6: =ROUNDUP(I6*(1-N6),0) -> #N/A | S6: =K6+Q6 -> #N/A | T6: =L6-Q6 -> #N/A
H7: =D7-E7 -> 0 | I7: =$I$1+H7-4 -> 44 | K7: =VLOOKUP(C7, 'Season 3'!$A$2:$CH$113, $J$1+1, FALSE) -> #N/A | L7: =VLOOKUP(F7, 'Season 3'!$A$2:$CH$113, $J$1+1, FALSE) -> #N/A | N7: =1/(10^(-(K7-L7)/400)+1) -> #N/A | O7: =1-N7 -> #N/A | Q7: =ROUNDUP(I7*(1-N7),0) -> #N/A | S7: =K7+Q7 -> #N/A | T7: =L7-Q7 -> #N/A
H8: =D8-E8 -> 0 | I8: =$I$1+H8-4 -> 44 | K8: =VLOOKUP(C8, 'Season 3'!$A$2:$CH$113, $J$1+1, FALSE) -> #N/A | L8: =VLOOKUP(F8, 'Season 3'!$A$2:$CH$113, $J$1+1, FALSE) -> #N/A | N8: =1/(10^(-(K8-L8)/400)+1) -> #N/A | O8: =1-N8 -> #N/A | Q8: =ROUNDUP(I8*(1-N8),0) -> #N/A | S8: =K8+Q8 -> #N/A | T8: =L8-Q8 -> #N/A
H9: =D9-E9 -> 0 | I9: =$I$1+H9-4 -> 44 | K9: =VLOOKUP(C9, 'Season 3'!$A$2:$CH$113, $J$1+1, FALSE) -> #N/A | L9: =VLOOKUP(F9, 'Season 3'!$A$2:$CH$113, $J$1+1, FALSE) -> #N/A | N9: =1/(10^(-(K9-L9)/400)+1) -> #N/A | O9: =1-N9 -> #N/A | Q9: =ROUNDUP(I9*(1-N9),0) -> #N/A | S9: =K9+Q9 -> #N/A | T9: =L9-Q9 -> #N/A
H10: =D10-E10 -> 0 | I10: =$I$1+H10-4 -> 44 | K10: =VLOOKUP(C10, 'Season 3'!$A$2:$CH$113, $J$1+1, FALSE) -> #N/A | L10: =VLOOKUP(F10, 'Season 3'!$A$2:$CH$113, $J$1+1, FALSE) -> #N/A | N10: =1/(10^(-(K10-L10)/400)+1) -> #N/A | O10: =1-N10 -> #N/A | Q10: =ROUNDUP(I10*(1-N10),0) -> #N/A | S10: =K10+Q10 -> #N/A | T10: =L10-Q10 -> #N/A
H11: =D11-E11 -> 0 | I11: =$I$1+H11-4 -> 44 | K11: =VLOOKUP(C11, 'Season 3'!$A$2:$CH$113, $J$1+1, FALSE) -> #N/A | L11: =VLOOKUP(F11, 'Season 3'!$A$2:$CH$113, $J$1+1, FALSE) -> #N/A | N11: =1/(10^(-(K11-L11)/400)+1) -> #N/A | O11: =1-N11 -> #N/A | Q11: =ROUNDUP(I11*(1-N11),0) -> #N/A | S11: =K11+Q11 -> #N/A | T11: =L11-Q11 -> #N/A
H12: =D12-E12 -> 0 | I12: =$I$1+H12-4 -> 44 | K12: =VLOOKUP(C12, 'Season 3'!$A$2:$CH$113, $J$1+1, FALSE) -> #N/A | L12: =VLOOKUP(F12, 'Season 3'!$A$2:$CH$113, $J$1+1, FALSE) -> #N/A | N12: =1/(10^(-(K12-L12)/400)+1) -> #N/A | O12: =1-N12 -> #N/A | Q12: =ROUNDUP(I12*(1-N12),0) -> #N/A | S12: =K12+Q12 -> #N/A | T12: =L12-Q12 -> #N/A
H13: =D13-E13 -> 0 | I13: =$I$1+H13-4 -> 44 | K13: =VLOOKUP(C13, 'Season 3'!$A$2:$CH$113, $J$1+1, FALSE) -> #N/A | L13: =VLOOKUP(F13, 'Season 3'!$A$2:$CH$113, $J$1+1, FALSE) -> #N/A | N13: =1/(10^(-(K13-L13)/400)+1) -> #N/A | O13: =1-N13 -> #N/A | Q13: =ROUNDUP(I13*(1-N13),0) -> #N/A | S13: =K13+Q13 -> #N/A | T13: =L13-Q13 -> #N/A
H14: =D14-E14 -> 0 | I14: =$I$1+H14-4 -> 44 | K14: =VLOOKUP(C14, 'Season 3'!$A$2:$CH$113, $J$1+1, FALSE) -> #N/A | L14: =VLOOKUP(F14, 'Season 3'!$A$2:$CH$113, $J$1+1, FALSE) -> #N/A | N14: =1/(10^(-(K14-L14)/400)+1) -> #N/A | O14: =1-N14 -> #N/A | Q14: =ROUNDUP(I14*(1-N14),0) -> #N/A | S14: =K14+Q14 -> #N/A | T14: =L14-Q14 -> #N/A
... H57: =D57-E57 -> 0 | I57: =$I$1+H57-4 -> 44 | K57: =VLOOKUP(C57, 'Season 3'!$A$2:$CH$113, $J$1+1, FALSE) -> #N/A | L57: =VLOOKUP(F57, 'Season 3'!$A$2:$CH$113, $J$1+1, FALSE) -> #N/A | N57: =1/(10^(-(K57-L57)/400)+1) -> #N/A | O57: =1-N57 -> #N/A | Q57: =ROUNDUP(I57*(1-N57),0) -> #N/A | S57: =K57+Q57 -> #N/A | T57: =L57-Q57 -> #N/A
C62: =C2 -> Resort Area | F62: =S2 -> 2180
C63: =C3 -> 0 | F63: =S3 -> #N/A
C64: =C4 -> 0 | F64: =S4 -> #N/A
C65: =C5 -> 0 | F65: =S5 -> #N/A
C66: =C6 -> 0 | F66: =S6 -> #N/A
C67: =C7 -> 0 | F67: =S7 -> #N/A
C68: =C8 -> 0 | F68: =S8 -> #N/A
C69: =C9 -> 0 | F69: =S9 -> #N/A
C70: =C10 -> 0 | F70: =S10 -> #N/A
C71: =C11 -> 0 | F71: =S11 -> #N/A
C72: =C12 -> 0 | F72: =S12 -> #N/A
C73: =C13 -> 0 | F73: =S13 -> #N/A
... C117: =C57 -> 0 | F117: =S57 -> #N/A
C118: =F2 -> Kala'e Bay | F118: =T2 -> 2113
C119: =F3 -> 0 | F119: =T3 -> #N/A
C120: =F4 -> 0 | F120: =T4 -> #N/A
C121: =F5 -> 0 | F121: =T5 -> #N/A
C122: =F6 -> 0 | F122: =T6 -> #N/A
C123: =F7 -> 0 | F123: =T7 -> #N/A
C124: =F8 -> 0 | F124: =T8 -> #N/A
C125: =F9 -> 0 | F125: =T9 -> #N/A
C126: =F10 -> 0 | F126: =T10 -> #N/A
C127: =F11 -> 0 | F127: =T11 -> #N/A
C128: =F12 -> 0 | F128: =T12 -> #N/A
C129: =F13 -> 0 | F129: =T13 -> #N/A
...

Sheet Archive
D1: =IF([1]ScoreboardNCAA!J18>=0, [1]ScoreboardNCAA!J17, [1]ScoreboardNCAA!L17) -> -1934.2704 | E1: =[1]ScoreboardNCAA!J1 -> 1314.7271 | F1: =IF(H1=[1]ScoreboardNCAA!B2, "A", "H") -> H | G1: =IF([1]ScoreboardNCAA!J18>=0, [1]ScoreboardNCAA!I4, [1]ScoreboardNCAA!M4) -> 1 | H1: =IF([1]ScoreboardNCAA!J18>=0, [1]ScoreboardNCAA!B2,[1]ScoreboardNCAA!N2) -> Cinnabar Island | I1: =MAX([1]ScoreboardNCAA!F6, [1]ScoreboardNCAA!N6) -> 4 | J1: =MIN([1]ScoreboardNCAA!F6, [1]ScoreboardNCAA!N6) -> 0 | K1: =IF([1]ScoreboardNCAA!J18<0, [1]ScoreboardNCAA!B2,[1]ScoreboardNCAA!N2) -> Resort Area | L1: =IF([1]ScoreboardNCAA!J18<0, [1]ScoreboardNCAA!I4, [1]ScoreboardNCAA!M4) -> 3 | M1: =IF([1]ScoreboardNCAA!J18>=0,CONCATENATE("[",COUNTA([1]ScoreboardNCAA!B6:E11),"-",COUNTA([1]ScoreboardNCAA!Q6:T11),"]"),CONCATENATE("[",COUNTA([1]ScoreboardNCAA!Q6:T11),"-",COUNTA([1]ScoreboardNCAA!B6:E11),"]")) -> [2-0] | N1: =IF([1]ScoreboardNCAA!J18>=0,CONCATENATE("{", ROUND([1]ScoreboardNCAA!J4, 3), "-", ROUND([1]ScoreboardNCAA!L4, 3), "}"),CONCATENATE("{", ROUND([1]ScoreboardNCAA!L4, 3), "-", ROUND([1]ScoreboardNCAA!J4, 3), "}")) -> {110.656-0} | O1: =IF(OR(MID(N1, 5, 1)=".", MID(N1, 6, 1)="."), "MAX", "") -> MAX | P1: CONCATENATE(G, " leads ", H, "-", I)
A2: D1 5/8 | B2: W1 | C2: Matchday One | D2: 3.487 | E2: 12.241429 | G2: 79 | H2: Couriway Town | I2: 11 | J2: 9 | K2: Dendemille Town | L2: 112 | M2: [6-9] | N2: {13.2-9.2} | P2: Season Start - 5/8/2020 | Q2: =ABS(D2) -> 3.487
D3: 1.077 | E3: 8.6057143 | G3: 93 | H3: Petalburg City | I3: 14 | J3: 11 | K3: Littleroot Town | L3: 110 | M3: [8-6] | N3: {18.3-12.8} | Q3: =ABS(D3) -> 1.077
D4: -2.006 | E4: 13.04 | G4: 109 | H4: Sootopolis City | I4: 15 | J4: 11 | K4: Pacifidlog Town | L4: 89 | M4: [10-7] | N4: {26.7-3.3} | Q4: =ABS(D4) -> 2.006
D5: 4.059 | E5: 36.431071 | G5: 43 | H5: Floaroma City | I5: 20 | J5: 15 | K5: Snowpoint City | L5: 108 | M5: [10-7] | N5: {41.9-14.2} | Q5: =ABS(D5) -> 4.059
D6: 2.158 | E6: 34.369286 | G6: 55 | H6: Nacrene City | I6: 22 | J6: 16 | K6: Accumula Town | L6: 107 | M6: [11-8] | N6: {22.5-19.5} | P6: OT - 16[8-8] | Q6: =ABS(D6) -> 2.158
D7: -0.16 | E7: 6.8107143 | G7: 103 | H7: Ever Grande City | I7: 16 | J7: 15 | K7: Mossdeep City | L7: 106 | M7: [9-7] | N7: {23.8-11.2} | Q7: =ABS(D7) -> 0.16
D8: 3.919 | E8: 40.147143 | G8: 37 | H8: Olivine City | I8: 19 | J8: 18 | K8: Ecruteak City | L8: 105 | M8: [7-9] | N8: {18.7-17.4} | Q8: =ABS(D8) -> 3.919
D9: -2.918 | E9: 37.798571 | G9: 104 | H9: Ultra Megalopolis | I9: 15 | J9: 13 | K9: Hau'oli City | L9: 56 | M9: [8-7] | N9: {37.4-7.7} | Q9: =ABS(D9) -> 2.918
D10: 4.825 | E10: 55.839286 | G10: 12 | H10: Seafolk Village | I10: 19 | J10: 14 | K10: Vast Poni Canyon | L10: 102 | M10: [5-9] | N10: {29.9-25.5} | Q10: =ABS(D10) -> 4.825
D11: -2.123 | E11: 29.195 | G11: 99 | H11: Hammerlocke | I11: 16 | J11: 10 | K11: Circhester Bay | L11: 63 | M11: [9-4] | N11: {39.5-4.6} | P11: Dynamax Conference debut | Q11: =ABS(D11) -> 2.123
D12: 4.53 | E12: 55.335714 | G12: 18 | H12: Postwick | I12: 12 | J12: 10 | K12: Crown Tundra | L12: 98 | M12: [6-5] | N12: {12.9-12.2} | Q12: =ABS(D12) -> 4.53
A13: D2 5/9 | D13: -0.499 | E13: 23.124286 | G13: 97 | H13: Ambrette Town | I13: 16 | J13: 14 | K13: Shalour City | L13: 76 | M13: [9-10] | N13: {51.3-1.6} | P13: Ambrette: 3pt# @ 60:20 | Q13: =ABS(D13) -> 0.499
D14: 1.834 | E14: 41.636429 | G14: 46 | H14: Resort Area | I14: 24 | J14: 12 | K14: Sunyshore City | L14: 96 | M14: [9-8] | N14: {80.3-4.9} | P14: Resort: 22(20) pts In 1st | Q14: =ABS(D14) -> 1.834
D15: 3.077 | E15: 42.7575 | G15: 42 | H15: Veilstone City | I15: 14 | J15: 10 | K15: Fight Area | L15: 95 | M15: [7-6] | N15: {15.5-12.7} | Q15: =ABS(D15) -> 3.077
D16: 4.556 | E16: 58.531429 | G16: 15 | H16: Twinleaf Town | I16: 21 | J16: 15 | K16: Canalave City | L16: 92 | M16: [7-10] | N16: {41.8-17.0} | Q16: =ABS(D16) -> 4.556
D17: 2.452 | E17: 50.436071 | G17: 28 | H17: Hulbury | I17: 20 | J17: 11 | K17: Motostoke | L17: 91 | M17: [11-5] | N17: {52.9-15.7} | Q17: =ABS(D17) -> 2.452
D18: -4.019 | E18: 63.942143 | G18: 90 | H18: Opelucid City | I18: 16 | J18: 12 | K18: Humilau City | L18: 19 | M18: [11-6] | N18: {38.1-3.1} | Q18: =ABS(D18) -> 4.019
D19: -1.281 | E19: 29.932857 | G19: 87 | H19: Fuchsia City | I19: 18 | J19: 16 | K19: Pewter City | L19: 72 | M19: [11-8] | N19: {36.0-17.1} | Q19: =ABS(D19) -> 1.281
D20: -1.288 | E20: 47.080714 | G20: 86 | H20: Tapu Village | I20: 18 | J20: 15 | K20: Mount Hokulani | L20: 48 | M20: [10-9] | N20: {43.3-9.9} | P20: Tapu: 4pt @ 59:30 | Q20: =ABS(D20) -> 1.288
D21: -2.337 | E21: 49.838929 | G21: 85 | H21: Aquacorde Town | I21: 20 | J21: 12 | K21: Kiloude City | L21: 44 | M21: [12-5] | N21: {79.3-3.7} | Q21: =ABS(D21) -> 2.337
D22: 3.323 | E22: 59.055 | G22: 24 | H22: Wyndon South | I22: 17 | J22: 14 | K22: Ballonlea | L22: 84 | M22: [8-8] | N22: {13.8-24.7} | O22: INVT | Q22: =ABS(D22) -> 3.323
D23: -1.658 | E23: 54.577143 | G23: 83 | H23: Icirrus City | I23: 13 | J23: 9 | K23: Nimbasa City | L23: 33 | M23: [7-5] | N23: {43.4-7.6} | Q23: =ABS(D23) -> 1.658
D24: 1.943 | E24: 46.781786 | G24: 47 | H24: Laverre City | I24: 16 | J24: 0 | K24: Camphrier Town | L24: 82 | M24: [11-0] | N24: {565.499-0} | O24: MAX | P24: FIRST EVER SHUTOUT, D-Score Record | Q24: =ABS(D24) -> 1.943
D25: 1.39 | E25: 51.998214 | G25: 36 | H25: Anville Town | I25: 15 | J25: 13 | K25: Floccesy Town | L25: 81 | M25: [9-7] | N25: {26.2-15.8} | Q25: =ABS(D25) -> 1.39
A26: D3 5/10 | D26: -1.551 | E26: 55.304286 | G26: 80 | H26: Mauville City | I26: 21 | J26: 15 | K26: Lilycove City | L26: 34 | M26: [12-8] | N26: {62.3-8.9} | Q26: =ABS(D26) -> 1.551
D27: -0.059 | E27: 34.863571 | G27: 68 | H27: Anistar City | I27: 14 | J27: 13 | K27: Snowbelle City | L27: 78 | M27: [9-8] | N27: {24.0-11.5} | Q27: =ABS(D27) -> 0.059
