Workbook

Sheet ScoreboardNCAA
B1: =(INDEX(Rankings!BS2:BS113,I4,1)) -> 0.57191123 | C1: =(INDEX(Rankings!BU2:BU113,I4,1)) -> 5.8880185 | D1: =INDEX(Rankings!BV2:BV113,I4,1)-INDEX(Rankings!BW2:BW113,M4,1) -> -0.4809036 | H1: =CONCATENATE(INDEX(Rankings!B2:'Rankings'!G113, (I4), 1)," Conference - ",INDEX(Rankings!B2:'Rankings'!G113, (I4), 2)," Pod") -> Indigo Conference - West Johto Pod | I1: =CONCATENATE("Conf ", INDEX(Rankings!D2:'Rankings'!J113, (I4), 6),"-",INDEX(Rankings!D2:'Rankings'!J113, (I4), 7)) -> Conf 5-4 | J1: =((1-(((AVERAGE(I4,M4)*(IF(AND(I4<26, M4<26), 0.875, IF(OR(I4<26, M4<26), 1, IF(AND(I4>56, M4>56), 1.25, 1.125)))))+(IF(J18>0, J17, L17)))*(1-IF(A2="AGG", 0.04, 0)-IF(OR(A3="CCC", A3="UTL"), 0.04, 0)-IF(OR(A3="MRL", A3="WCS"), 0.06, 0)-IF(A3="CHMP", 0.08, 0))/140))*100)+(IF(K8>2, K8-2, 0)) -> 647.04355 | K1: =((((T1-B1)/0.15)*3)+((IF(A3="CCC", 1, IF(A3="", 0.5, 0.75))))+((0.125*L1*ABS(C5-S5))+0.5)+((S1-C1)/2)+(IF(A3="WCS", (1/2)*(T5-B5), 0))) -> 5.9169688 | L1: =IF(HLOOKUP(INDEX(Rankings!B2:'Rankings'!B113,(M4),1),B25:H26,2,FALSE)="Perfect",2,IF(HLOOKUP(INDEX(Rankings!B2:'Rankings'!B113,(M4),1),B25:H26,2,FALSE)="Beautiful",(5/3),IF(HLOOKUP(INDEX(Rankings!B2:'Rankings'!B113,(M4),1),B25:H26,2,FALSE)="Good",(4/3),IF(HLOOKUP(INDEX(Rankings!B2:'Rankings'!B113,(M4),1),B25:H26,2,FALSE)="Normal",1,IF(HLOOKUP(INDEX(Rankings!B2:'Rankings'!B113,(M4),1),B25:H26,2,FALSE)="Subpar",(2/3), IF(HLOOKUP(INDEX(Rankings!B2:'Rankings'!B113,(M4),1),B25:H26,2,FALSE)="Stormy",(1/3), 0)))))) -> 1 | M1: =CONCATENATE("Conf ", INDEX(Rankings!D2:'Rankings'!J113, (M4), 6),"-",INDEX(Rankings!D2:'Rankings'!J113, (M4), 7)) -> Conf 6-3 | N1: =CONCATENATE(INDEX(Rankings!B2:'Rankings'!G113, (M4), 1)," Conference - ",INDEX(Rankings!B2:'Rankings'!G113, (M4), 2)," Pod") -> Indigo Conference - West Johto Pod | R1: =INDEX(Rankings!BV2:BV113,M4,1)-INDEX(Rankings!BW2:BW113,I4,1) -> -0.1511182 | S1: =(INDEX(Rankings!BU2:BU113,M4,1)) -> 7.1778261 | T1: =(INDEX(Rankings!BS2:BS113,M4,1)) -> 0.76468114
A2: AGG | B2: =INDEX(Rankings!D2:'Rankings'!D113, (I4), 1) -> Goldenrod City | I2: =CONCATENATE("Seas ", INDEX(Rankings!D2:'Rankings'!G113, (I4), 3),"-",INDEX(Rankings!D2:'Rankings'!G113, (I4), 4)) -> Seas 7-6 | J2: RESORT AREA | M2: =CONCATENATE("Seas ", INDEX(Rankings!D2:'Rankings'!G113, (M4), 3),"-",INDEX(Rankings!D2:'Rankings'!G113, (M4), 4)) -> Seas 10-3 | N2: =INDEX(Rankings!D2:'Rankings'!D113, (M4), 1) -> Cianwood City
A3: CHMP | I3: =CONCATENATE("Ovr ", (INDEX(Rankings!D2:'Rankings'!N113,(I4),3)+INDEX(Rankings!D2:'Rankings'!N113,(I4),9)), "-", (INDEX(Rankings!D2:'Rankings'!N113,(I4),4)+INDEX(Rankings!D2:'Rankings'!N113,(I4),10))) -> Ovr 11-13 | J3: SEASON THREE CHAMPIONS | M3: =CONCATENATE("Ovr ", (INDEX(Rankings!D2:'Rankings'!N113,(M4),3)+INDEX(Rankings!D2:'Rankings'!N113,(M4),9)), "-", (INDEX(Rankings!D2:'Rankings'!N113,(M4),4)+INDEX(Rankings!D2:'Rankings'!N113,(M4),10))) -> Ovr 25-8
A4: 2.25 | I4: 3 | J4: =IF(((SUM(J19:J26)-IF(J20>F6,J20-F6,0)+IF(J20<-N6,-N6-J20, 0))*J27)<0, 0, ((SUM(J19:J26)-IF(J20>F6,J20-F6,0)+IF(J20<-N6,-N6-J20, 0))*J27)) -> 0 | K4: D-SCORE | L4: =IF(((SUM(L19:L26)-IF(L20>N6,L20-N6,0)+IF(L20<-F6,-F6-L20, 0))*L27)<0, 0, ((SUM(L19:L26)-IF(L20>N6,L20-N6,0)+IF(L20<-F6,-F6-L20, 0))*L27)) -> 89.205962 | M4: 1
B5: =(INDEX(Rankings!BT2:BT113,I4,1)) -> 4 | C5: =INDEX(Rankings!BR2:BR113,I4,1) -> 0.33333333 | D5: =INDEX(Rankings!BO2:BO113,I4,1)+INDEX(Rankings!BP2:BP113,I4,1) -> 115 | E5: =IF(ROUND(F5,0)=0, "[---]", CONCATENATE("[+", ROUND(F5,0), "]")) -> [---] | F5: =IF(K1>=0, 0, -K1*(((1+(0.05*(R5-2))))*((1-(0.05*(D5-2)))))*IF(T27="-", 1, T27)) -> 0 | P5: =IF(K1<=0, 0, K1*(((1-(0.05*(R5-2))))*((1+(0.05*(D5-2)))))*IF(T27="-", 1, T27)) -> -872.04656 | Q5: =IF(ROUND(P5,0)=0, "[---]", CONCATENATE("[+", ROUND(P5,0), "]")) -> [+-872] | R5: =INDEX(Rankings!BO2:BO113,M4,1)+INDEX(Rankings!BP2:BP113,M4,1) -> 219 | S5: =INDEX(Rankings!BR2:BR113,M4,1) -> 1.6666667 | T5: =(INDEX(Rankings!BT2:BT113,M4,1)) -> 2
F6: =SUM(L45:O50) -> 0 | I6: =IF(AND(A2="AGG", H5<>""), F6+H5, "") | J6: =IF(K8 = 1, "1st",IF(K8 = 2, "2nd",IF(K8 = 3, "1st", IF(K8 = 4, "2nd", IF(K8 = 5, "3rd", IF(K8>5, CONCATENATE(K8-2,"th"))))))) -> 1st | K6: =IF(K8<3, "HALF", "Overtime") -> HALF | M6: =IF(AND(A2="AGG", N5<>""), N5+N6, "") | N6: =SUM(Q45:T50) -> 4 | Q6: 2*2
Q7: 2*4
J8: =IF(M101="DUPLIC.", "DUPLIC.", IF(AND(K8=1, J9=0), "<<<<", IF(AND(K8=2, J9=250), ">>>>", IF(AND(ISODD(K8), (J9/100)=K8+2, J9>300), "<<<<", IF(AND(ISEVEN(K8), (J9/100)=K8+2, J9>400), ">>>>", "-"))))) -> <<<< | K8: 1 | L8: =CONCATENATE(IF(K8=1,IF(J9<251,ROUNDUP(J9/10,0),CONCATENATE("25+",ROUNDUP((J9-250)/10,0))),IF(K8=2,IF(J9<501,ROUNDUP(J9/10,0),CONCATENATE("50+",ROUNDUP((J9-500)/10,0))),IF(K8>2,IF(J9<(301+(100*K8)),ROUNDUP(J9/10,0),CONCATENATE((K8+3),"0+",ROUNDUP((J9-(300+(K8*100)))/10, 0)))))), "'") -> 0'
J9: 0 | L9: 0 | M9: =IF(K8=1, P66, IF(K8=2, P73, IF(K8>2, P80, 0))) -> 2
M10: =IF(K8 = 1, M9+25, IF(K8 = 2, M9+50, IF(K8>2, ((K8-2)*10+50)+M9))) -> 27
B13: GOAL | C13: X | D13: X | E13: 4 | F13: 3 | G13: 2 | H13: 2 | I13: 1 | J13: 1 | K13: 1 | L13: 1 | M13: 1 | N13: 2 | O13: 2 | P13: 3 | Q13: 4 | R13: X | S13: X | T13: GOAL
B14: =IF(I5="#1", "Indigo Conference Champion", IF(I5="#2", "Lily Valley Conference Champion",IF(I5="#3", "Kalosite Conference Champion",IF(I5="#4", "Dynamax Conference Champion",IF(I5="#5", "Lanakila Conference Champion",IF(I5="#6", "Vertress Conference Champion",IF(I5="#9", "Delta Conference Champion", ""))))))) | F14: * | G14: K | H14: Q | I14: J | K14: 9*9 | M14: J | N14: Q | O14: K | P14: * | T14: =IF(M5="#1", "Indigo Conference Champion", IF(M5="#2", "Lily Valley Conference Champion",IF(M5="#3", "Kalosite Conference Champion",IF(M5="#4", "Dynamax Conference Champion",IF(M5="#5", "Lanakila Conference Champion",IF(M5="#6", "Vertress Conference Champion",IF(M5="#9", "Delta Conference Champion", "")))))))
J15: =IF(COUNTIF(Q104:Q152, ">1.5")=0, "", INDEX(N104:N152, COUNTIF(Q104:Q152, "<2"))) | K15: HALFTIME SCORE | L15: =IF(COUNTIF(Q104:Q152, ">1.5")=0, "", INDEX(T104:T152, COUNTIF(Q104:Q152, "<2")))
F16: =200/5 -> 40 | G16: =((J4-100)/100+10)^2 -> 81 | H16: =((L4-100)/100+10)^2 -> 97.852844 | I16: =H16-100 -> -2.1471565
B17: =IF(B6="", "", (IF(RIGHT(B6)="!",3,IF(RIGHT(B6)="#",5,IF(RIGHT(B6)="$",7,IF(MID(B6, 5, 1)="+", 1, 0)))))) | C17: =IF(C6="", "", (IF(RIGHT(C6)="!",3,IF(RIGHT(C6)="#",5,IF(RIGHT(C6)="$",7,IF(MID(C6, 5, 1)="+", 1, 0)))))) | D17: =IF(D6="", "", (IF(RIGHT(D6)="!",3,IF(RIGHT(D6)="#",5,IF(RIGHT(D6)="$",7,IF(MID(D6, 5, 1)="+", 1, 0)))))) | E17: =IF(E6="", "", (IF(RIGHT(E6)="!",3,IF(RIGHT(E6)="#",5,IF(RIGHT(E6)="$",7,IF(MID(E6, 5, 1)="+", 1, 0)))))) | F17: =300/5 -> 60 | G17: =IF(SQRT(J4/100)<1, AVERAGE(SQRT(J4/100), J4/100)*100, 100+((J4-100)/5)) -> 0 | H17: =IF(SQRT(L4/100)<1, AVERAGE(SQRT(L4/100), L4/100)*100, 100+((L4-100)/5)) -> 91.827435 | I17: =I16/20 -> -0.10735782 | J17: =IF(F5=0, -P5, F5) -> 872.04656 | K17: Favorite | L17: =IF(P5=0, -F5, P5) -> -872.04656 | M17: 260 | N17: W8 - Geosenge (DNF) | Q17: =IF(Q6="", "", (IF(RIGHT(Q6)="!",3,IF(RIGHT(Q6)="#",5,IF(RIGHT(Q6)="$",7,IF(MID(Q6, 5, 1)="+", 1, 0)))))) -> 0 | R17: =IF(R6="", "", (IF(RIGHT(R6)="!",3,IF(RIGHT(R6)="#",5,IF(RIGHT(R6)="$",7,IF(MID(R6, 5, 1)="+", 1, 0)))))) | S17: =IF(S6="", "", (IF(RIGHT(S6)="!",3,IF(RIGHT(S6)="#",5,IF(RIGHT(S6)="$",7,IF(MID(S6, 5, 1)="+", 1, 0)))))) | T17: =IF(T6="", "", (IF(RIGHT(T6)="!",3,IF(RIGHT(T6)="#",5,IF(RIGHT(T6)="$",7,IF(MID(T6, 5, 1)="+", 1, 0))))))
B18: =IF(B7="", "", (IF(RIGHT(B7)="!",3,IF(RIGHT(B7)="#",5,IF(RIGHT(B7)="$",7,IF(MID(B7, 5, 1)="+", 1, 0)))))) | C18: =IF(C7="", "", (IF(RIGHT(C7)="!",3,IF(RIGHT(C7)="#",5,IF(RIGHT(C7)="$",7,IF(MID(C7, 5, 1)="+", 1, 0)))))) | D18: =IF(D7="", "", (IF(RIGHT(D7)="!",3,IF(RIGHT(D7)="#",5,IF(RIGHT(D7)="$",7,IF(MID(D7, 5, 1)="+", 1, 0)))))) | E18: =IF(E7="", "", (IF(RIGHT(E7)="!",3,IF(RIGHT(E7)="#",5,IF(RIGHT(E7)="$",7,IF(MID(E7, 5, 1)="+", 1, 0)))))) | F18: =400/5 -> 80 | G18: =SQRT(G17) -> 0 | H18: =SQRT(H17) -> 9.5826633 | J18: =F6-N6 -> -4 | K18: Difference | L18: =N6-F6 -> 4 | M18: 248 | N18: W13 - Ambrette | Q18: =IF(Q7="", "", (IF(RIGHT(Q7)="!",3,IF(RIGHT(Q7)="#",5,IF(RIGHT(Q7)="$",7,IF(MID(Q7, 5, 1)="+", 1, 0)))))) -> 0 | R18: =IF(R7="", "", (IF(RIGHT(R7)="!",3,IF(RIGHT(R7)="#",5,IF(RIGHT(R7)="$",7,IF(MID(R7, 5, 1)="+", 1, 0)))))) | S18: =IF(S7="", "", (IF(RIGHT(S7)="!",3,IF(RIGHT(S7)="#",5,IF(RIGHT(S7)="$",7,IF(MID(S7, 5, 1)="+", 1, 0)))))) | T18: =IF(T7="", "", (IF(RIGHT(T7)="!",3,IF(RIGHT(T7)="#",5,IF(RIGHT(T7)="$",7,IF(MID(T7, 5, 1)="+", 1, 0))))))
B19: =IF(B8="", "", (IF(RIGHT(B8)="!",3,IF(RIGHT(B8)="#",5,IF(RIGHT(B8)="$",7,IF(MID(B8, 5, 1)="+", 1, 0)))))) | C19: =IF(C8="", "", (IF(RIGHT(C8)="!",3,IF(RIGHT(C8)="#",5,IF(RIGHT(C8)="$",7,IF(MID(C8, 5, 1)="+", 1, 0)))))) | D19: =IF(D8="", "", (IF(RIGHT(D8)="!",3,IF(RIGHT(D8)="#",5,IF(RIGHT(D8)="$",7,IF(MID(D8, 5, 1)="+", 1, 0)))))) | E19: =IF(E8="", "", (IF(RIGHT(E8)="!",3,IF(RIGHT(E8)="#",5,IF(RIGHT(E8)="$",7,IF(MID(E8, 5, 1)="+", 1, 0)))))) | F19: =500/5 -> 100 | G19: =SQRT(J4) -> 0 | H19: =SQRT(L4) -> 9.4448908 | J19: =IF(K8>2, -J17, 0) -> 0 | K19: Overtime? | L19: =IF(K8>2, -L17, 0) -> 0 | M19: 240 | N19: W2 - Crown Tundra | Q19: =IF(Q8="", "", (IF(RIGHT(Q8)="!",3,IF(RIGHT(Q8)="#",5,IF(RIGHT(Q8)="$",7,IF(MID(Q8, 5, 1)="+", 1, 0)))))) | R19: =IF(R8="", "", (IF(RIGHT(R8)="!",3,IF(RIGHT(R8)="#",5,IF(RIGHT(R8)="$",7,IF(MID(R8, 5, 1)="+", 1, 0)))))) | S19: =IF(S8="", "", (IF(RIGHT(S8)="!",3,IF(RIGHT(S8)="#",5,IF(RIGHT(S8)="$",7,IF(MID(S8, 5, 1)="+", 1, 0)))))) | T19: =IF(T8="", "", (IF(RIGHT(T8)="!",3,IF(RIGHT(T8)="#",5,IF(RIGHT(T8)="$",7,IF(MID(T8, 5, 1)="+", 1, 0))))))
B20: =IF(B9="", "", (IF(RIGHT(B9)="!",3,IF(RIGHT(B9)="#",5,IF(RIGHT(B9)="$",7,IF(MID(B9, 5, 1)="+", 1, 0)))))) | C20: =IF(C9="", "", (IF(RIGHT(C9)="!",3,IF(RIGHT(C9)="#",5,IF(RIGHT(C9)="$",7,IF(MID(C9, 5, 1)="+", 1, 0)))))) | D20: =IF(D9="", "", (IF(RIGHT(D9)="!",3,IF(RIGHT(D9)="#",5,IF(RIGHT(D9)="$",7,IF(MID(D9, 5, 1)="+", 1, 0)))))) | E20: =IF(E9="", "", (IF(RIGHT(E9)="!",3,IF(RIGHT(E9)="#",5,IF(RIGHT(E9)="$",7,IF(MID(E9, 5, 1)="+", 1, 0)))))) | F20: =1000/5 -> 200 | G20: =G18-G19 -> 0 | H20: =H18-H19 -> 0.13777246 | J20: =IF(AND(J17>0, J18>0, J17>J18), J18/J17, IF(AND(J17<0, J18<0, J18>J17), 3*(1-(J18/J17)), IF(AND(J17<0, J18<J17), -(J18/J17), IF(AND(J17>0, J18>0, J18>J17), 1+(J18/J17), IF(AND(J17<0, J18>0), -J17+(0.5*(J18+J17)), IF(AND(J17>0, J18<0), -J17+(0.25*J18), 0))))))/1.5 -> -582.03104 | K20: ATS | L20: =IF(AND(L17>0, L18>0, L17>L18), L18/L17, IF(AND(L17<0, L18<0, L18>L17), 3*(1-(L18/L17)), IF(AND(L17<0, L18<L17), -(L18/L17), IF(AND(L17>0, L18>0, L18>L17), 1+(L18/L17), IF(AND(L17<0, L18>0), -L17+(0.5*(L18+L17)), IF(AND(L17>0, L18<0), -L17+(0.25*L18), 0))))))/1.5 -> 292.01552 | M20: 239 | N20: W12 - Sandgem | Q20: =IF(Q9="", "", (IF(RIGHT(Q9)="!",3,IF(RIGHT(Q9)="#",5,IF(RIGHT(Q9)="$",7,IF(MID(Q9, 5, 1)="+", 1, 0)))))) | R20: =IF(R9="", "", (IF(RIGHT(R9)="!",3,IF(RIGHT(R9)="#",5,IF(RIGHT(R9)="$",7,IF(MID(R9, 5, 1)="+", 1, 0)))))) | S20: =IF(S9="", "", (IF(RIGHT(S9)="!",3,IF(RIGHT(S9)="#",5,IF(RIGHT(S9)="$",7,IF(MID(S9, 5, 1)="+", 1, 0)))))) | T20: =IF(T9="", "", (IF(RIGHT(T9)="!",3,IF(RIGHT(T9)="#",5,IF(RIGHT(T9)="$",7,IF(MID(T9, 5, 1)="+", 1, 0))))))
B21: =IF(B10="", "", (IF(RIGHT(B10)="!",3,IF(RIGHT(B10)="#",5,IF(RIGHT(B10)="$",7,IF(MID(B10, 5, 1)="+", 1, 0)))))) | C21: =IF(C10="", "", (IF(RIGHT(C10)="!",3,IF(RIGHT(C10)="#",5,IF(RIGHT(C10)="$",7,IF(MID(C10, 5, 1)="+", 1, 0)))))) | D21: =IF(D10="", "", (IF(RIGHT(D10)="!",3,IF(RIGHT(D10)="#",5,IF(RIGHT(D10)="$",7,IF(MID(D10, 5, 1)="+", 1, 0)))))) | E21: =IF(E10="", "", (IF(RIGHT(E10)="!",3,IF(RIGHT(E10)="#",5,IF(RIGHT(E10)="$",7,IF(MID(E10, 5, 1)="+", 1, 0)))))) | J21: =COUNTIF(B17:E22, 1) -> 0 | K21: Stoppage | L21: =COUNTIF(Q17:T22, 1) -> 0 | M21: 228 | N21: W5 - Circhester Bay | Q21: =IF(Q10="", "", (IF(RIGHT(Q10)="!",3,IF(RIGHT(Q10)="#",5,IF(RIGHT(Q10)="$",7,IF(MID(Q10, 5, 1)="+", 1, 0)))))) | R21: =IF(R10="", "", (IF(RIGHT(R10)="!",3,IF(RIGHT(R10)="#",5,IF(RIGHT(R10)="$",7,IF(MID(R10, 5, 1)="+", 1, 0)))))) | S21: =IF(S10="", "", (IF(RIGHT(S10)="!",3,IF(RIGHT(S10)="#",5,IF(RIGHT(S10)="$",7,IF(MID(S10, 5, 1)="+", 1, 0)))))) | T21: =IF(T10="", "", (IF(RIGHT(T10)="!",3,IF(RIGHT(T10)="#",5,IF(RIGHT(T10)="$",7,IF(MID(T10, 5, 1)="+", 1, 0))))))
B22: =IF(B11="", "", (IF(RIGHT(B11)="!",3,IF(RIGHT(B11)="#",5,IF(RIGHT(B11)="$",7,IF(MID(B11, 5, 1)="+", 1, 0)))))) | C22: =IF(C11="", "", (IF(RIGHT(C11)="!",3,IF(RIGHT(C11)="#",5,IF(RIGHT(C11)="$",7,IF(MID(C11, 5, 1)="+", 1, 0)))))) | D22: =IF(D11="", "", (IF(RIGHT(D11)="!",3,IF(RIGHT(D11)="#",5,IF(RIGHT(D11)="$",7,IF(MID(D11, 5, 1)="+", 1, 0)))))) | E22: =IF(E11="", "", (IF(RIGHT(E11)="!",3,IF(RIGHT(E11)="#",5,IF(RIGHT(E11)="$",7,IF(MID(E11, 5, 1)="+", 1, 0)))))) | J22: =(COUNTIF(B17:E22, 3)*3)+(COUNTIF(B17:E22, 5)*5)+(COUNTIF(B17:E22, 7)*7) -> 0 | K22: Aces/KRs | L22: =(COUNTIF(Q17:T22, 3)*3)+(COUNTIF(Q17:T22, 5)*5)+(COUNTIF(Q17:T22, 7)*7) -> 0 | M22: 226 | N22: W9 - Celadon | Q22: =IF(Q11="", "", (IF(RIGHT(Q11)="!",3,IF(RIGHT(Q11)="#",5,IF(RIGHT(Q11)="$",7,IF(MID(Q11, 5, 1)="+", 1, 0)))))) | R22: =IF(R11="", "", (IF(RIGHT(R11)="!",3,IF(RIGHT(R11)="#",5,IF(RIGHT(R11)="$",7,IF(MID(R11, 5, 1)="+", 1, 0)))))) | S22: =IF(S11="", "", (IF(RIGHT(S11)="!",3,IF(RIGHT(S11)="#",5,IF(RIGHT(S11)="$",7,IF(MID(S11, 5, 1)="+", 1, 0)))))) | T22: =IF(T11="", "", (IF(RIGHT(T11)="!",3,IF(RIGHT(T11)="#",5,IF(RIGHT(T11)="$",7,IF(MID(T11, 5, 1)="+", 1, 0))))))
J23: =O101*5 -> 0.3125 | K23: Time Led | L23: =R101*5 -> 4.6875 | M23: 210 | N23: W7 - Oldale (UTL)
B24: REGION-BY-REGION GAME CONDITIONS | J24: =IF(X102<0, -X102, 0) -> 0 | K24: Avg Led By | L24: =IF(X102>0, X102, 0) -> 3 | Q24: Goals are no longer allowed to be stamped at the same time
B25: Indigo | C25: Delta | D25: Lily Valley | E25: Vertress | F25: Kalosite | G25: Lanakila | H25: Dynamax | J25: =IF(AND(J18>0, (J18-J17)>0), IF((COUNT(B17:E22)-COUNT(Q17:T22))<0, (COUNT(B17:E22)-COUNT(Q17:T22))*-1, (COUNT(B17:E22)-COUNT(Q17:T22))*0.25), 0) -> 0 | K25: Goal Diff. | L25: =IF(AND(L18>0,(L18-L17)>0), IF((COUNT(Q17:T22)-COUNT(B17:E22))<0, (COUNT(Q17:T22)-COUNT(B17:E22))*-1, (COUNT(Q17:T22)-COUNT(B17:E22))*0.25), 0) -> 0.5 | N25: =CONCATENATE("GAME SPREAD - ", IF(K1>=0, N2, B2), " favored by ", IF(K1>=0, ROUND(L17, 3), ROUND(J17, 3))) -> GAME SPREAD - Cianwood City favored by -872.047
B26: =IF(B27=0, "Normal", IF(B27<1.25, "Severe", IF(B27<1.5, "Stormy", IF(B27<1.75, "Subpar", IF(B27<2.25, "Normal", IF(B27<2.5, "Good", IF(B27<2.75, "Beautiful", "Perfect"))))))) -> Normal | C26: =IF(C27=0, "Normal", IF(C27<1.25, "Severe", IF(C27<1.5, "Stormy", IF(C27<1.75, "Subpar", IF(C27<2.25, "Normal", IF(C27<2.5, "Good", IF(C27<2.75, "Beautiful", "Perfect"))))))) -> Normal | D26: =IF(D27=0, "Normal", IF(D27<1.25, "Severe", IF(D27<1.5, "Stormy", IF(D27<1.75, "Subpar", IF(D27<2.25, "Normal", IF(D27<2.5, "Good", IF(D27<2.75, "Beautiful", "Perfect"))))))) -> Good | E26: =IF(E27=0, "Normal", IF(E27<1.25, "Severe", IF(E27<1.5, "Stormy", IF(E27<1.75, "Subpar", IF(E27<2.25, "Normal", IF(E27<2.5, "Good", IF(E27<2.75, "Beautiful", "Perfect"))))))) -> Good | F26: =IF(F27=0, "Normal", IF(F27<1.25, "Severe", IF(F27<1.5, "Stormy", IF(F27<1.75, "Subpar", IF(F27<2.25, "Normal", IF(F27<2.5, "Good", IF(F27<2.75, "Beautiful", "Perfect"))))))) -> Normal | G26: =IF(G27=0, "Normal", IF(G27<1.25, "Severe", IF(G27<1.5, "Stormy", IF(G27<1.75, "Subpar", IF(G27<2.25, "Normal", IF(G27<2.5, "Good", IF(G27<2.75, "Beautiful", "Perfect"))))))) -> Good | H26: =IF(H27=0, "Normal", IF(H27<1.25, "Severe", IF(H27<1.5, "Stormy", IF(H27<1.75, "Subpar", IF(H27<2.25, "Normal", IF(H27<2.5, "Good", IF(H27<2.75, "Beautiful", "Perfect"))))))) -> Beautiful | J26: =IFERROR(F6/COUNT(B17:E22), 0) -> 0 | K26: Goal Avg. | L26: =IFERROR(N6/COUNT(Q17:T22), 0) -> 2 | N26: Rating | O26: Home Adv | P26: Climate | Q26: Eye Test | R26: WCS | S26: Fatigue | T26: Playoffs
A27: WK5 | B27: 1.8 | C27: 2.2 | D27: 2.26 | E27: 2.48 | F27: 2.11 | G27: 2.4 | H27: 2.72 | I27: =SUM(J19:J26)*J27 -> 0 | J27: =IFERROR((F6/N6)*(T1+1), F6*(T1+1)) -> 0 | K27: Multiplier | L27: =IFERROR((N6/F6)*(B1+1), N6*(B1+1)) -> 6.2876449 | M27: =SUM(L19:L26)*L27 -> 1900.1453 | N27: =(((T1-B1)/0.15)*3) -> 3.8553983 | O27: =(IF(A3="CCC", 1, IF(A3="", 0.5, 0.75))) -> 0.75 | P27: =((0.125*L1*ABS(C5-S5))+0.5) -> 0.66666667 | Q27: =((S1-C1)/2) -> 0.6449038 | R27: =IF(A3="WCS", (1/2)*(T5-B5), "-") -> - | S27: =IF(K1>0, ((1-(0.05*(R5-2))))*((1+(0.05*(D5-2)))), -((1+(0.05*(R5-2))))*((1-(0.05*(D5-2))))) -> -65.5025 | T27: =IF(A4>1, A4, IF(A3="CHMP", IF(A4="CONF",1.25,IF(LEFT(A4,1)="R",1.5,IF(A4="QTR", 1.75, IF(A4="SEMI", 2, IF(A4="FINAL", 2.25, "-"))))), IF(A3="CCC", IF(A4="SEMI", 1.25, IF(A4="FINAL", 1.5, "-")), IF(A3<>"", IF(LEFT(A4,1)="R", 1.25,IF(A4="QTR", 1.5, IF(A4="SEMI", 1.75, IF(A4="FINAL", 2, "-")))), "-")))) -> 2.25
B29: 53 | C29: 88 | D29: 63 | E29: 31 | F29: 83 | G29: 36 | H29: 95
B30: 23 | C30: 45 | D30: 15 | E30: 7 | F30: 11 | G30: 69 | H30: 81
B31: 21 | C31: 47 | D31: 67 | E31: 95 | F31: 5 | G31: 16 | H31: 45
B32: 91 | C32: 38 | D32: 86 | E32: 98 | F32: 61 | G32: 79 | H32: 96
B33: 62 | C33: 16 | D33: 8 | E33: 31 | F33: 80 | G33: 97 | H33: 98
B34: 62 | C34: 38 | D34: 63 | E34: 80 | F34: 86 | G34: 85 | H34: 30
B35: 46 | C35: 92 | D35: 52 | E35: 82 | F35: 36 | G35: 33 | H35: 16 | O35: =INDEX(Rankings!B2:'Rankings'!G113, (I4), 1) -> Indigo | Q35: =INDEX(Rankings!B2:'Rankings'!G113, (M4), 1) -> Indigo
B36: 2 | C36: 75 | D36: 97 | E36: 71 | F36: 60 | G36: 64 | H36: 21 | O36: =IF(O35="Indigo", 1, IF(O35="Delta", 2, IF(O35="Lily Valley", 3, IF(O35="Vertress", 4, IF(O35="Kalosite", 5, IF(O35="Lanakila", 6, IF(O35="Dynamax", 7, 0))))))) -> 1 | Q36: =IF(Q35="Indigo", 1, IF(Q35="Delta", 2, IF(Q35="Lily Valley", 3, IF(Q35="Vertress", 4, IF(Q35="Kalosite", 5, IF(Q35="Lanakila", 6, IF(Q35="Dynamax", 7, 0))))))) -> 1
B38: =SUM(B29:B36)/200 -> 1.8 | C38: =SUM(C29:C36)/200 -> 2.195 | D38: =SUM(D29:D36)/200 -> 2.255 | E38: =SUM(E29:E36)/200 -> 2.475 | F38: =SUM(F29:F36)/200 -> 2.11 | G38: =SUM(G29:G36)/200 -> 2.395 | H38: =SUM(H29:H36)/200 -> 2.41 | L38: =_xlfn.NUMBERVALUE(LEFT(B6, 1)) -> 0 | M38: =_xlfn.NUMBERVALUE(LEFT(C6, 1)) -> 0 | N38: =_xlfn.NUMBERVALUE(LEFT(D6, 1)) -> 0 | O38: =_xlfn.NUMBERVALUE(LEFT(E6, 1)) -> 0 | Q38: =_xlfn.NUMBERVALUE(LEFT(Q6, 1)) -> 2 | R38: =_xlfn.NUMBERVALUE(LEFT(R6, 1)) -> 0 | S38: =_xlfn.NUMBERVALUE(LEFT(S6, 1)) -> 0 | T38: =_xlfn.NUMBERVALUE(LEFT(T6, 1)) -> 0
B39: 1 | C39: 2 | D39: 3 | E39: 4 | F39: 5 | G39: 6 | H39: 7 | L39: =_xlfn.NUMBERVALUE(LEFT(B7, 1)) -> 0 | M39: =_xlfn.NUMBERVALUE(LEFT(C7, 1)) -> 0 | N39: =_xlfn.NUMBERVALUE(LEFT(D7, 1)) -> 0 | O39: =_xlfn.NUMBERVALUE(LEFT(E7, 1)) -> 0 | Q39: =_xlfn.NUMBERVALUE(LEFT(Q7, 1)) -> 2 | R39: =_xlfn.NUMBERVALUE(LEFT(R7, 1)) -> 0 | S39: =_xlfn.NUMBERVALUE(LEFT(S7, 1)) -> 0 | T39: =_xlfn.NUMBERVALUE(LEFT(T7, 1)) -> 0
L40: =_xlfn.NUMBERVALUE(LEFT(B8, 1)) -> 0 | M40: =_xlfn.NUMBERVALUE(LEFT(C8, 1)) -> 0 | N40: =_xlfn.NUMBERVALUE(LEFT(D8, 1)) -> 0 | O40: =_xlfn.NUMBERVALUE(LEFT(E8, 1)) -> 0 | Q40: =_xlfn.NUMBERVALUE(LEFT(Q8, 1)) -> 0 | R40: =_xlfn.NUMBERVALUE(LEFT(R8, 1)) -> 0 | S40: =_xlfn.NUMBERVALUE(LEFT(S8, 1)) -> 0 | T40: =_xlfn.NUMBERVALUE(LEFT(T8, 1)) -> 0
E41: Refreshes after each play block | L41: =_xlfn.NUMBERVALUE(LEFT(B9, 1)) -> 0 | M41: =_xlfn.NUMBERVALUE(LEFT(C9, 1)) -> 0 | N41: =_xlfn.NUMBERVALUE(LEFT(D9, 1)) -> 0 | O41: =_xlfn.NUMBERVALUE(LEFT(E9, 1)) -> 0 | Q41: =_xlfn.NUMBERVALUE(LEFT(Q9, 1)) -> 0 | R41: =_xlfn.NUMBERVALUE(LEFT(R9, 1)) -> 0 | S41: =_xlfn.NUMBERVALUE(LEFT(S9, 1)) -> 0 | T41: =_xlfn.NUMBERVALUE(LEFT(T9, 1)) -> 0
E42: (WCS, MRL, UTL, CCC, Regular) | L42: =_xlfn.NUMBERVALUE(LEFT(B10, 1)) -> 0 | M42: =_xlfn.NUMBERVALUE(LEFT(C10, 1)) -> 0 | N42: =_xlfn.NUMBERVALUE(LEFT(D10, 1)) -> 0 | O42: =_xlfn.NUMBERVALUE(LEFT(E10, 1)) -> 0 | Q42: =_xlfn.NUMBERVALUE(LEFT(Q10, 1)) -> 0 | R42: =_xlfn.NUMBERVALUE(LEFT(R10, 1)) -> 0 | S42: =_xlfn.NUMBERVALUE(LEFT(S10, 1)) -> 0 | T42: =_xlfn.NUMBERVALUE(LEFT(T10, 1)) -> 0
L43: =_xlfn.NUMBERVALUE(LEFT(B11, 1)) -> 0 | M43: =_xlfn.NUMBERVALUE(LEFT(C11, 1)) -> 0 | N43: =_xlfn.NUMBERVALUE(LEFT(D11, 1)) -> 0 | O43: =_xlfn.NUMBERVALUE(LEFT(E11, 1)) -> 0 | Q43: =_xlfn.NUMBERVALUE(LEFT(Q11, 1)) -> 0 | R43: =_xlfn.NUMBERVALUE(LEFT(R11, 1)) -> 0 | S43: =_xlfn.NUMBERVALUE(LEFT(S11, 1)) -> 0 | T43: =_xlfn.NUMBERVALUE(LEFT(T11, 1)) -> 0
L45: =IF(L38=0, 0, L38+B67) -> 0 | M45: =IF(M38=0, 0, M38+C67) -> 0 | N45: =IF(N38=0, 0, N38+D67) -> 0 | O45: =IF(O38=0, 0, O38+E67) -> 0 | Q45: =IF(Q38=0, 0, Q38+G67) -> 2 | R45: =IF(R38=0, 0, R38+H67) -> 0 | S45: =IF(S38=0, 0, S38+I67) -> 0 | T45: =IF(T38=0, 0, T38+J67) -> 0
...

Sheet Archive
C1: =IF(ScoreboardNCAA!J18>=0, ScoreboardNCAA!J17, ScoreboardNCAA!L17) -> -872.04656 | D1: =ScoreboardNCAA!J1 -> 647.04355 | E1: =IF(G1=ScoreboardNCAA!B2, "A", "H") -> H | F1: =IF(ScoreboardNCAA!J18>=0, ScoreboardNCAA!I4, ScoreboardNCAA!M4) -> 1 | G1: =IF(ScoreboardNCAA!J18>=0, ScoreboardNCAA!B2,ScoreboardNCAA!N2) -> Cianwood City | H1: =MAX(ScoreboardNCAA!F6, ScoreboardNCAA!N6) -> 4 | I1: =MIN(ScoreboardNCAA!F6, ScoreboardNCAA!N6) -> 0 | J1: =IF(ScoreboardNCAA!J18<0, ScoreboardNCAA!B2,ScoreboardNCAA!N2) -> Goldenrod City | K1: =IF(ScoreboardNCAA!J18<0, ScoreboardNCAA!I4, ScoreboardNCAA!M4) -> 3 | L1: =IF(ScoreboardNCAA!J18>=0,CONCATENATE("[",COUNTA(ScoreboardNCAA!B6:E11),"-",COUNTA(ScoreboardNCAA!Q6:T11),"]"),CONCATENATE("[",COUNTA(ScoreboardNCAA!Q6:T11),"-",COUNTA(ScoreboardNCAA!B6:E11),"]")) -> [2-0] | M1: =IF(ScoreboardNCAA!J18>=0,CONCATENATE("{", ROUND(ScoreboardNCAA!J4, 3), "-", ROUND(ScoreboardNCAA!L4, 3), "}"),CONCATENATE("{", ROUND(ScoreboardNCAA!L4, 3), "-", ROUND(ScoreboardNCAA!J4, 3), "}")) -> {89.206-0} | N1: =IF(OR(MID(M1, 5, 1)=".", MID(M1, 6, 1)="."), "MAX", "") | O1: CONCATENATE(G, " leads ", H, "-", I)
A2: D1 5/8 | B2: Matchday One | C2: 3.487 | D2: 12.241429 | F2: 79 | G2: Couriway Town | H2: 11 | I2: 9 | J2: Dendemille Town | K2: 112 | L2: [6-9] | M2: {13.2-9.2} | O2: Season Start - 5/8/2020
C3: 1.077 | D3: 8.6057143 | F3: 93 | G3: Petalburg City | H3: 14 | I3: 11 | J3: Littleroot Town | K3: 110 | L3: [8-6] | M3: {18.3-12.8}
C4: -2.006 | D4: 13.04 | F4: 109 | G4: Sootopolis City | H4: 15 | I4: 11 | J4: Pacifidlog Town | K4: 89 | L4: [10-7] | M4: {26.7-3.3}
C5: 4.059 | D5: 36.431071 | F5: 43 | G5: Floaroma City | H5: 20 | I5: 15 | J5: Snowpoint City | K5: 108 | L5: [10-7] | M5: {41.9-14.2}
C6: 2.158 | D6: 34.369286 | F6: 55 | G6: Nacrene City | H6: 22 | I6: 16 | J6: Accumula Town | K6: 107 | L6: [11-8] | M6: {22.5-19.5} | O6: OT - 16[8-8]
C7: -0.16 | D7: 6.8107143 | F7: 103 | G7: Ever Grande City | H7: 16 | I7: 15 | J7: Mossdeep City | K7: 106 | L7: [9-7] | M7: {23.8-11.2}
C8: 3.919 | D8: 40.147143 | F8: 37 | G8: Olivine City | H8: 19 | I8: 18 | J8: Ecruteak City | K8: 105 | L8: [7-9] | M8: {18.7-17.4}
C9: -2.918 | D9: 37.798571 | F9: 104 | G9: Ultra Megalopolis | H9: 15 | I9: 13 | J9: Hau'oli City | K9: 56 | L9: [8-7] | M9: {37.4-7.7}
C10: 4.825 | D10: 55.839286 | F10: 12 | G10: Seafolk Village | H10: 19 | I10: 14 | J10: Vast Poni Canyon | K10: 102 | L10: [5-9] | M10: {29.9-25.5}
C11: -2.123 | D11: 29.195 | F11: 99 | G11: Hammerlocke | H11: 16 | I11: 10 | J11: Circhester Bay | K11: 63 | L11: [9-4] | M11: {39.5-4.6} | O11: Dynamax Conference debut
C12: 4.53 | D12: 55.335714 | F12: 18 | G12: Postwick | H12: 12 | I12: 10 | J12: Crown Tundra | K12: 98 | L12: [6-5] | M12: {12.9-12.2}
A13: D2 5/9 | C13: -0.499 | D13: 23.124286 | F13: 97 | G13: Ambrette Town | H13: 16 | I13: 14 | J13: Shalour City | K13: 76 | L13: [9-10] | M13: {51.3-1.6} | O13: Ambrette: 3pt# @ 60:20
C14: 1.834 | D14: 41.636429 | F14: 46 | G14: Resort Area | H14: 24 | I14: 12 | J14: Sunyshore City | K14: 96 | L14: [9-8] | M14: {80.3-4.9} | O14: Resort: 22(20) pts In 1st
C15: 3.077 | D15: 42.7575 | F15: 42 | G15: Veilstone City | H15: 14 | I15: 10 | J15: Fight Area | K15: 95 | L15: [7-6] | M15: {15.5-12.7}
C16: 4.556 | D16: 58.531429 | F16: 15 | G16: Twinleaf Town | H16: 21 | I16: 15 | J16: Canalave City | K16: 92 | L16: [7-10] | M16: {41.8-17.0}
C17: 2.452 | D17: 50.436071 | F17: 28 | G17: Hulbury | H17: 20 | I17: 11 | J17: Motostoke | K17: 91 | L17: [11-5] | M17: {52.9-15.7}
C18: -4.019 | D18: 63.942143 | F18: 90 | G18: Opelucid City | H18: 16 | I18: 12 | J18: Humilau City | K18: 19 | L18: [11-6] | M18: {38.1-3.1}
C19: -1.281 | D19: 29.932857 | F19: 87 | G19: Fuchsia City | H19: 18 | I19: 16 | J19: Pewter City | K19: 72 | L19: [11-8] | M19: {36.0-17.1}
C20: -1.288 | D20: 47.080714 | F20: 86 | G20: Tapu Village | H20: 18 | I20: 15 | J20: Mount Hokulani | K20: 48 | L20: [10-9] | M20: {43.3-9.9} | O20: Tapu: 4pt @ 59:30
C21: -2.337 | D21: 49.838929 | F21: 85 | G21: Aquacorde Town | H21: 20 | I21: 12 | J21: Kiloude City | K21: 44 | L21: [12-5] | M21: {79.3-3.7}
C22: 3.323 | D22: 59.055 | F22: 24 | G22: Wyndon South | H22: 17 | I22: 14 | J22: Ballonlea | K22: 84 | L22: [8-8] | M22: {13.8-24.7} | N22: INVT
C23: -1.658 | D23: 54.577143 | F23: 83 | G23: Icirrus City | H23: 13 | I23: 9 | J23: Nimbasa City | K23: 33 | L23: [7-5] | M23: {43.4-7.6}
C24: 1.943 | D24: 46.781786 | F24: 47 | G24: Laverre City | H24: 16 | I24: 0 | J24: Camphrier Town | K24: 82 | L24: [11-0] | M24: {565.499-0} | N24: MAX | O24: FIRST EVER SHUTOUT, D-Score Record
C25: 1.39 | D25: 51.998214 | F25: 36 | G25: Anville Town | H25: 15 | I25: 13 | J25: Floccesy Town | K25: 81 | L25: [9-7] | M25: {26.2-15.8}
A26: D3 5/10 | C26: -1.551 | D26: 55.304286 | F26: 80 | G26: Mauville City | H26: 21 | I26: 15 | J26: Lilycove City | K26: 34 | L26: [12-8] | M26: {62.3-8.9}
C27: -0.059 | D27: 34.863571 | F27: 68 | G27: Anistar City | H27: 14 | I27: 13 | J27: Snowbelle City | K27: 78 | L27: [9-8] | M27: {24.0-11.5}
C28: -2.18 | D28: 55.351786 | F28: 77 | G28: Mistralton City | H28: 16 | I28: 14 | J28: Aspertia City | K28: 38 | L28: [9-7] | M28: {31.9-4.9}
A29: D4 5/11 | C29: 1.511 | D29: 56.331429 | F29: 31 | G29: Mahogany Town | H29: 19 | I29: 15 | J29: Violet City | K29: 75 | L29: [11-8] | M29: {29.7-27.0}
C30: -1.473 | D30: 59.266429 | F30: 74 | G30: Iki Town | H30: 18 | I30: 12 | J30: Kala'e Bay | K30: 30 | L30: [8-7] | M30: {71.4-1.6}
C31: 3.519 | D31: 65.700714 | F31: 16 | G31: Sandgem Town | H31: 18 | I31: 15 | J31: Jubilife City | K31: 73 | L31: [10-9] | M31: {32.2-21.3}
C32: -2.064 | D32: 58.885 | F32: 71 | G32: South Lakes | H32: 18 | I32: 13 | J32: Wedgehurst | K32: 35 | L32: [8-5] | M32: {55.6-1.7}
C33: 0.623 | D33: 39.287143 | F33: 65 | G33: Heahea City | H33: 24 | I33: 9 | J33: Aether Paradise | K33: 70 | L33: [9-6] | M33: {101.3-4.7} | N33: MAX
C34: 0.626 | D34: 40.177857 | F34: 64 | G34: Poni Meadow | H34: 16 | I34: 8 | J34: Exeggutor Island | K34: 69 | L34: [11-5] | M34: {63.2-4.1}
C35: -0.695 | D35: 57.505357 | F35: 67 | G35: Vermilion City | H35: 17 | I35: 9 | J35: Saffron City | K35: 40 | L35: [11-7] | M35: {82.3-2.5}
C36: 1.029 | D36: 51.854286 | F36: 52 | G36: Azalea Town | H36: 9 | I36: 8 | J36: Blackthorn City | K36: 66 | L36: [5-3] | M36: {17.6-12.7}
C37: 0.164 | D37: 55.284643 | F37: 49 | G37: Cerulean City | H37: 15 | I37: 10 | J37: Celadon City | K37: 62 | L37: [9-5] | M37: {34.1-3.0}
C38: 1.005 | D38: 61.916071 | F38: 32 | G38: Celestic Town | H38: 13 | I38: 10 | J38: Pastoria City | K38: 61 | L38: [8-6] | M38: {17.2-14.0}
C39: -2.092 | D39: 65.735357 | F39: 60 | G39: Malie City | H39: 24 | I39: 13 | J39: Po Town | K39: 29 | L39: [13-6] | M39: {108.5-0} | N39: MAX
C40: 4.383 | D40: 72.583571 | F40: 9 | G40: Undella Town | H40: 21 | I40: 20 | J40: Lacunosa Town | K40: 59 | L40: [8-9] | M40: {20.8-44.7} | N40: INVT
...

Sheet Rankings
C1: =CONCATENATE(" ", ROUND(Archive!C1, 3), " >", ROUND(Archive!D1, 0), "< ", Archive!M1) -> -872.047 >647< {89.206-0} | F1: SeW | G1: Se L | I1: CfW | J1: Cf L | L1: ExW | M1: Ex L | O1: P For | P1: P Agt | Q1: Gls | R1: SOS | S1: EXP | T1: DScore | V1: P For | W1: P Agt | X1: Gls | Y1: SOS | Z1: EXP | AA1: DScore | AC1: PF | AD1: PA | AE1: GOAL | AF1: SOS | AG1: EXP | AH1: DSCR | AI1: Gms | AJ1: PtsF/G | AK1: PtsA/G | AL1: PtDf | AM1: Gav | AN1: StrAvg | AO1: StrMod | AP1: VicAvg | AQ1: EXP | AR1: ExAv | AS1: D-Avg | AT1: D-Sqrt | AU1: WCS | AV1: CCC | AW1: M/U | AX1: Cups | AZ1: =112-COUNTIF(BB2:BB113, 0) -> 0 | BB1: RkCh | BC1: TOTAL | BD1: Wins (2.25) | BE1: Cf W (1.5) | BF1: P For (1) | BG1: P Agt (1) | BH1: G Av (.75) | BI1: SOS (1) | BJ1: SOV (1) | BK1: EYE (.75) | BL1: D Scr (1) | BM1: Cups (.75) | BN1: EX | BO1: TW | BP1: LW | BR1: Climate | BS1: =_xlfn.STDEV.P(BS2:BS113) -> 0.18229976 | BT1: WCSEntry | BU1: Dynamax | BV1: Pts For | BW1: Pts Ag | BX1: Conf Str | BZ1: =AVERAGE(BU2:BU113) -> 5.8231504 | CA1: =AVERAGE(BS2:BS113) -> 0.53604776 | CD1: =_xlfn.STDEV.P(BC2:BC113)-BS1 -> 0 | CE1: FINAL | CF1: LR2/WSF | CG1: LR1 | CH1: WQF | CI1: Opening | CJ1: Play-In | CK1: WMU FIN | CL1: ConfChmp | CM1: WMU SF | CN1: WMU QF | CO1: After W13 | CP1: MW13 | CQ1: After W12 | CR1: MW12 | CS1: After W11 | CT1: MW11 | CU1: After W10 | CV1: Revamp | CW1: After W9 | CX1: New Form | CY1: After W8 | CZ1: After W7 | DA1: After W6 | DB1: After W5 | DC1: After W4 | DD1: After W3 | DE1: After W2 | DF1: After W1 | DG1: Preseason
A2: 1 | B2: Indigo | C2: West Johto | D2: Cianwood City | F2: 10 | G2: 3 | H2: 14 | I2: 6 | J2: 3 | L2: 15 | M2: 5 | O2: 246 | P2: =162+17 -> 179 | Q2: 116 | R2: =25.242+10.264+0.174-0.856+1.147 -> 35.971 | S2: =632+54+89+92+95 -> 962 | T2: =500.1525+52.492+65.835+74.372+13.305 -> 706.1565 | V2: =343+19 -> 362 | W2: =292+21 -> 313 | X2: 160 | Y2: =62.155-0.31+3.508-2.826-6.707+1.102-2.023 -> 54.899 | Z2: =1025+91+89+94+101+92+91 -> 1583 | AA2: =676.5725+7.076+48.194+1.941+84.366+41.753+24.997 -> 884.8995 | AC2: =O2+((1/4)*V2) -> 336.5 | AD2: =P2+((1/4)*W2) -> 257.25 | AE2: =Q2+((1/4)*X2) -> 156 | AF2: =R2+((1/4)*Y2) -> 49.69575 | AG2: =S2+((1/4)*Z2) -> 1357.75 | AH2: =T2+((1/4)*AA2) -> 927.38137 | AI2: =F2+G2+((1/4)*(L2+M2)) -> 18 | AJ2: =IFERROR(AC2/AI2, 0) -> 18.694444 | AK2: =IFERROR(AD2/AI2, 0) -> 14.291667 | AL2: =AJ2-AK2 -> 4.4027778 | AM2: =IFERROR(AC2/AE2, 0) -> 2.1570513 | AN2: =IF((AF2)<0, (AF2/2), AF2)/AI2 -> 2.760875 | AO2: =(AN2-(SMALL(AN:AN,1)))*(2-(1-((1-BX2)/2)))+MIN(AN:AN) -> 2.484138 | AP2: =AL2-(IF(AVERAGE(AN2:AO2)<0, AVERAGE(AN2:AO2)*2, AVERAGE(AN2:AO2))) -> 1.7802713 | AQ2: =(AVERAGE((AL2-MIN(AL:AL))*AR2, SQRT((AL2-MIN(AL:AL))*AR2))/100)*BX2 -> 6.3983553 | AR2: =(AG2/AI2) -> 75.430556 | AS2: =IFERROR(AH2/AI2,0) -> 51.521187 | AT2: =IFERROR(IF(SQRT(AS2)>10, 10, SQRT(AS2)), 0) -> 7.1778261 | AU2: 28 | AV2: 24 | AW2: 26 | AX2: =SUM(AU2:AW2) -> 78 | AZ2: 14 | BA2: =_xlfn.RANK.EQ(BC2,BC:BC, 0) -> 14 | BB2: =AZ2-BA2 -> 0 | BC2: =((BD2*2.25)+(BE2*1.5)+(BF2*1)+(BG2*1)+(BH2*0.75)+(BI2*1)+(BJ2*1)+(BK2*0.75)+(BL2*1)+(BM2*0.75)+(BN2/LARGE(BN:BN,1))*(3/15))/(10+(9/30)) -> 0.76468114 | BD2: =IFERROR(IF((F2+G2)=1, IF(F2=0, 0.333, IF(F2=1, 0.666, 0)), IF((F2+G2)=2, IF(F2=0, 0.166, IF(F2=1, 0.5, IF(F2=2, 0.833, 0))), (F2+(L2/6))/(F2+G2))), 0) -> 0.96153846 | BE2: =IFERROR(IF((I2+J2)=1, IF(I2=0, 0.333, IF(I2=1, 0.666, 0)), IF((I2+J2)=2, IF(I2=0, 0.166, IF(I2=1, 0.5, IF(I2=2, 0.833, 0))), (I2/(I2+J2)))), 0) -> 0.66666667 | BF2: =(AJ2-(SMALL(AJ:AJ, 1)))/((LARGE(AJ:AJ, 1))-(SMALL(AJ:AJ, 1))) -> 0.52487325 | BG2: =1-(AK2-SMALL(AK:AK,1))/(LARGE(AK:AK,1)-SMALL(AK:AK,1)) -> 0.82945605 | BH2: =(AM2-SMALL(AM:AM,1))/(LARGE(AM:AM,1)-SMALL(AM:AM,1)) -> 0.53909853 | BI2: =1-(AO2-SMALL(AO:AO,1))/(LARGE(AO:AO,1)-SMALL(AO:AO,1)) -> 0.3825027 | BJ2: =(AP2+ABS(MIN(AP:AP)))/(MAX(AP:AP)+ABS(MIN(AP:AP))) -> 0.73260599 | BK2: =AVERAGE(AQ2/MAX(AQ:AQ), SQRT(AQ2/MAX(AQ:AQ))) -> 0.73129642 | BL2: =AVERAGE(AT2/MAX(AT:AT), (AT2-SMALL(AT:AT,1))/(LARGE(AT:AT,1)-SMALL(AT:AT,1))) -> 0.7542343 | BM2: =IFERROR(AX2/MAX(AX:AX), 0) -> 0.61904762 | BN2: =10+44 -> 54 | BO2: =BN2+AX2 -> 132 | BP2: 87 | BQ2: =BO2+BP2 -> 219 | BR2: 1.6666667 | BS2: 0.76468114 | BT2: 2 | BU2: 7.1778261 | BV2: 0.52487325 | BW2: 0.82945605 | BX2: =IF(A2<17, SoC!O$3, IF(A2<33, SoC!O$4, IF(A2<49, SoC!O$5, IF(A2<65, SoC!O$6, IF(A2<81, SoC!O$7, IF(A2<97, SoC!O$8, SoC!O$9)))))) -> 1.0968296 | BY2: =SQRT(BS2) -> 0.87446049 | BZ2: =IF(BY2<(15/30), "F", IF(BY2<(18/30), "F+", IF(BY2<(19/30), "D-", IF(BY2<(20/30), "D", IF(BY2<(21/30), "D+", IF(BY2<(22/30), "C-", IF(BY2<(23/30), "C", IF(BY2<(24/30), "C+", IF(BY2<(25/30), "B-", IF(BY2<(26/30), "B", IF(BY2<(27/30), "B+", IF(BY2<(28/30), "A-", IF(BY2<(29/30), "A", "A+"))))))))))))) -> B+ | CA2: =(((BS2-$CA$1)/0.15)*3)+((BU2-$BZ$1)/2) -> 5.2500054 | CB2: =CF2-CE2 -> 0 | CC2: 59 | CD2: Cianwood City | CE2: 14 | CF2: 14 | CG2: 14 | CH2: 14 | CI2: 14 | CJ2: 14 | CK2: 14 | CL2: 14 | CM2: 15 | CN2: 15 | CO2: 14 | CP2: 9 | CQ2: 9 | CR2: 12 | CS2: 11 | CT2: 13 | CU2: 11 | CV2: 14 | CW2: 17 | CX2: 20 | CY2: 18 | CZ2: 11 | DA2: 13 | DB2: 20 | DC2: 29 | DD2: 9 | DE2: 21 | DF2: 23 | DG2: 54
A3: 2 | B3: Indigo | C3: West Johto | D3: Ecruteak City | F3: 3 | G3: 10 | I3: 1 | J3: 8 | L3: 0 | M3: 2 | O3: 196 | P3: =269+25 -> 294 | Q3: 111 | R3: =-53.113-9.814-3.623-5.813-4.018 -> -76.381 | S3: =299+47+7+23+34 -> 410 | T3: =138.923+2.653+46.612+52.282+3.564 -> 244.034 | V3: 29 | W3: 47 | X3: 21 | Y3: =-13.625 -> -13.625 | Z3: =60 -> 60 | AA3: =27.339 -> 27.339 | AC3: =O3+((1/4)*V3) -> 203.25 | AD3: =P3+((1/4)*W3) -> 305.75 | AE3: =Q3+((1/4)*X3) -> 116.25 | AF3: =R3+((1/4)*Y3) -> -79.78725 | AG3: =S3+((1/4)*Z3) -> 425 | AH3: =T3+((1/4)*AA3) -> 250.86875 | AI3: =F3+G3+((1/4)*(L3+M3)) -> 13.5 | AJ3: =IFERROR(AC3/AI3, 0) -> 15.055556 | AK3: =IFERROR(AD3/AI3, 0) -> 22.648148 | AL3: =AJ3-AK3 -> -7.5925926 | AM3: =IFERROR(AC3/AE3, 0) -> 1.7483871 | AN3: =IF((AF3)<0, (AF3/2), AF3)/AI3 -> -2.9550833 | AO3: =(AN3-(SMALL(AN:AN,1)))*(2-(1-((1-BX3)/2)))+MIN(AN:AN) -> -2.9550833 | AP3: =AL3-(IF(AVERAGE(AN3:AO3)<0, AVERAGE(AN3:AO3)*2, AVERAGE(AN3:AO3))) -> -1.6824259 | AQ3: =(AVERAGE((AL3-MIN(AL:AL))*AR3, SQRT((AL3-MIN(AL:AL))*AR3))/100)*BX3 -> 0.57588842 | AR3: =(AG3/AI3) -> 31.481481 | AS3: =IFERROR(AH3/AI3,0) -> 18.58287 | AT3: =IFERROR(IF(SQRT(AS3)>10, 10, SQRT(AS3)), 0) -> 4.3107854 | AU3: 7 | AV3: 0 | AX3: =SUM(AU3:AW3) -> 7 | AZ3: 107 | BA3: =_xlfn.RANK.EQ(BC3,BC:BC, 0) -> 107 | BB3: =AZ3-BA3 -> 0 | BC3: =((BD3*2.25)+(BE3*1.5)+(BF3*1)+(BG3*1)+(BH3*0.75)+(BI3*1)+(BJ3*1)+(BK3*0.75)+(BL3*1)+(BM3*0.75)+(BN3/LARGE(BN:BN,1))*(3/15))/(10+(9/30)) -> 0.27824122 | BD3: =IFERROR(IF((F3+G3)=1, IF(F3=0, 0.333, IF(F3=1, 0.666, 0)), IF((F3+G3)=2, IF(F3=0, 0.166, IF(F3=1, 0.5, IF(F3=2, 0.833, 0))), (F3+(L3/6))/(F3+G3))), 0) -> 0.23076923 | BE3: =IFERROR(IF((I3+J3)=1, IF(I3=0, 0.333, IF(I3=1, 0.666, 0)), IF((I3+J3)=2, IF(I3=0, 0.166, IF(I3=1, 0.5, IF(I3=2, 0.833, 0))), (I3/(I3+J3)))), 0) -> 0.11111111 | BF3: =(AJ3-(SMALL(AJ:AJ, 1)))/((LARGE(AJ:AJ, 1))-(SMALL(AJ:AJ, 1))) -> 0.21333921 | BG3: =1-(AK3-SMALL(AK:AK,1))/(LARGE(AK:AK,1)-SMALL(AK:AK,1)) -> 0.049791709 | BH3: =(AM3-SMALL(AM:AM,1))/(LARGE(AM:AM,1)-SMALL(AM:AM,1)) -> 0.087435156 | BI3: =1-(AO3-SMALL(AO:AO,1))/(LARGE(AO:AO,1)-SMALL(AO:AO,1)) -> 1 | BJ3: =(AP3+ABS(MIN(AP:AP)))/(MAX(AP:AP)+ABS(MIN(AP:AP))) -> 0.37123897 | BK3: =AVERAGE(AQ3/MAX(AQ:AQ), SQRT(AQ3/MAX(AQ:AQ))) -> 0.15073175 | BL3: =AVERAGE(AT3/MAX(AT:AT), (AT3-SMALL(AT:AT,1))/(LARGE(AT:AT,1)-SMALL(AT:AT,1))) -> 0.31865875 | BM3: =IFERROR(AX3/MAX(AX:AX), 0) -> 0.055555556 | BN3: 5 | BO3: =BN3+AX3 -> 12 | BP3: 2 | BQ3: =BO3+BP3 -> 14 | BR3: -1 | BS3: 0.27824122 | BT3: 1 | BU3: 4.3107854 | BV3: 0.21333921 | BW3: 0.049791709 | BX3: =IF(A3<17, SoC!O$3, IF(A3<33, SoC!O$4, IF(A3<49, SoC!O$5, IF(A3<65, SoC!O$6, IF(A3<81, SoC!O$7, IF(A3<97, SoC!O$8, SoC!O$9)))))) -> 1.0968296 | BY3: =SQRT(BS3) -> 0.52748575 | BZ3: =IF(BY3<(15/30), "F", IF(BY3<(18/30), "F+", IF(BY3<(19/30), "D-", IF(BY3<(20/30), "D", IF(BY3<(21/30), "D+", IF(BY3<(22/30), "C-", IF(BY3<(23/30), "C", IF(BY3<(24/30), "C+", IF(BY3<(25/30), "B-", IF(BY3<(26/30), "B", IF(BY3<(27/30), "B+", IF(BY3<(28/30), "A-", IF(BY3<(29/30), "A", "A+"))))))))))))) -> F+ | CA3: =(((BS3-$CA$1)/0.15)*3)+((BU3-$BZ$1)/2) -> -5.9123134 | CB3: =CF3-CE3 -> 0 | CC3: 8 | CD3: Ecruteak City | CE3: 107 | CF3: 107 | CG3: 107 | CH3: 107 | CI3: 107 | CJ3: 107 | CK3: 107 | CL3: 107 | CM3: 107 | CN3: 107 | CO3: 107 | CP3: 104 | CQ3: 105 | CR3: 108 | CS3: 108 | CT3: 110 | CU3: 111 | CV3: 109 | CW3: 111 | CX3: 111 | CY3: 112 | CZ3: 112 | DA3: 112 | DB3: 112 | DC3: 110 | DD3: 109 | DE3: 108 | DF3: 92 | DG3: 105
A4: 3 | B4: Indigo | C4: West Johto | D4: Goldenrod City | F4: 7 | G4: 6 | I4: 5 | J4: 4 | L4: 4 | M4: 7 | O4: =188+25 -> 213 | P4: =188+11 -> 199 | Q4: 105 | R4: =8.326-0.625+6.433+1.197+4.018 -> 19.349 | S4: =579+84+46+55+34 -> 798 | T4: =325.391+22.022+1.245+10.229+(115.154-7.577) -> 466.464 | V4: =179+17 -> 196 | W4: =182+26 -> 208 | X4: 107 | Y4: =-5.713-4.817-7.792 -> -18.322 | Z4: =683+80+78 -> 841 | AA4: =300.679+11.27+6.327 -> 318.276 | AC4: =O4+((1/4)*V4) -> 262 | AD4: =P4+((1/4)*W4) -> 251 | AE4: =Q4+((1/4)*X4) -> 131.75 | AF4: =R4+((1/4)*Y4) -> 14.7685 | AG4: =S4+((1/4)*Z4) -> 1008.25 | AH4: =T4+((1/4)*AA4) -> 546.033 | AI4: =F4+G4+((1/4)*(L4+M4)) -> 15.75 | AJ4: =IFERROR(AC4/AI4, 0) -> 16.634921 | AK4: =IFERROR(AD4/AI4, 0) -> 15.936508 | AL4: =AJ4-AK4 -> 0.6984127 | AM4: =IFERROR(AC4/AE4, 0) -> 1.9886148 | AN4: =IF((AF4)<0, (AF4/2), AF4)/AI4 -> 0.93768254 | AO4: =(AN4-(SMALL(AN:AN,1)))*(2-(1-((1-BX4)/2)))+MIN(AN:AN) -> 0.74921507 | AP4: =AL4-(IF(AVERAGE(AN4:AO4)<0, AVERAGE(AN4:AO4)*2, AVERAGE(AN4:AO4))) -> -0.14503611 | AQ4: =(AVERAGE((AL4-MIN(AL:AL))*AR4, SQRT((AL4-MIN(AL:AL))*AR4))/100)*BX4 -> 4.1205537 | AR4: =(AG4/AI4) -> 64.015873 | AS4: =IFERROR(AH4/AI4,0) -> 34.668762 | AT4: =IFERROR(IF(SQRT(AS4)>10, 10, SQRT(AS4)), 0) -> 5.8880185 | AU4: 28 | AV4: 12 | AW4: 20 | AX4: =SUM(AU4:AW4) -> 60 | AZ4: 45 | BA4: =_xlfn.RANK.EQ(BC4,BC:BC, 0) -> 45 | BB4: =AZ4-BA4 -> 0 | BC4: =((BD4*2.25)+(BE4*1.5)+(BF4*1)+(BG4*1)+(BH4*0.75)+(BI4*1)+(BJ4*1)+(BK4*0.75)+(BL4*1)+(BM4*0.75)+(BN4/LARGE(BN:BN,1))*(3/15))/(10+(9/30)) -> 0.57191123 | BD4: =IFERROR(IF((F4+G4)=1, IF(F4=0, 0.333, IF(F4=1, 0.666, 0)), IF((F4+G4)=2, IF(F4=0, 0.166, IF(F4=1, 0.5, IF(F4=2, 0.833, 0))), (F4+(L4/6))/(F4+G4))), 0) -> 0.58974359 | BE4: =IFERROR(IF((I4+J4)=1, IF(I4=0, 0.333, IF(I4=1, 0.666, 0)), IF((I4+J4)=2, IF(I4=0, 0.166, IF(I4=1, 0.5, IF(I4=2, 0.833, 0))), (I4/(I4+J4)))), 0) -> 0.55555556 | BF4: =(AJ4-(SMALL(AJ:AJ, 1)))/((LARGE(AJ:AJ, 1))-(SMALL(AJ:AJ, 1))) -> 0.34855246 | BG4: =1-(AK4-SMALL(AK:AK,1))/(LARGE(AK:AK,1)-SMALL(AK:AK,1)) -> 0.67599145 | BH4: =(AM4-SMALL(AM:AM,1))/(LARGE(AM:AM,1)-SMALL(AM:AM,1)) -> 0.35293935 | BI4: =1-(AO4-SMALL(AO:AO,1))/(LARGE(AO:AO,1)-SMALL(AO:AO,1)) -> 0.57946292 | BJ4: =(AP4+ABS(MIN(AP:AP)))/(MAX(AP:AP)+ABS(MIN(AP:AP))) -> 0.53168095 | BK4: =AVERAGE(AQ4/MAX(AQ:AQ), SQRT(AQ4/MAX(AQ:AQ))) -> 0.53504084 | BL4: =AVERAGE(AT4/MAX(AT:AT), (AT4-SMALL(AT:AT,1))/(LARGE(AT:AT,1)-SMALL(AT:AT,1))) -> 0.55828011 | BM4: =IFERROR(AX4/MAX(AX:AX), 0) -> 0.47619048 | BN4: 10 | BO4: =BN4+AX4 -> 70 | BP4: 45 | BQ4: =BO4+BP4 -> 115 | BR4: 0.33333333 | BS4: 0.57191123 | BT4: 4 | BU4: 5.8880185 | BV4: 0.34855246 | BW4: 0.67599145 | BX4: =IF(A4<17, SoC!O$3, IF(A4<33, SoC!O$4, IF(A4<49, SoC!O$5, IF(A4<65, SoC!O$6, IF(A4<81, SoC!O$7, IF(A4<97, SoC!O$8, SoC!O$9)))))) -> 1.0968296 | BY4: =SQRT(BS4) -> 0.75624812 | BZ4: =IF(BY4<(15/30), "F", IF(BY4<(18/30), "F+", IF(BY4<(19/30), "D-", IF(BY4<(20/30), "D", IF(BY4<(21/30), "D+", IF(BY4<(22/30), "C-", IF(BY4<(23/30), "C", IF(BY4<(24/30), "C+", IF(BY4<(25/30), "B-", IF(BY4<(26/30), "B", IF(BY4<(27/30), "B+", IF(BY4<(28/30), "A-", IF(BY4<(29/30), "A", "A+"))))))))))))) -> C | CA4: =(((BS4-$CA$1)/0.15)*3)+((BU4-$BZ$1)/2) -> 0.74970327 | CB4: =CF4-CE4 -> 0 | CC4: 93 | CD4: Goldenrod City | CE4: 45 | CF4: 45 | CG4: 46 | CH4: 46 | CI4: 45 | CJ4: 46 | CK4: 46 | CL4: 46 | CM4: 46 | CN4: 46 | CO4: 45 | CP4: 53 | CQ4: 52 | CR4: 45 | CS4: 43 | CT4: 40 | CU4: 39 | CV4: 32 | CW4: 35 | CX4: 40 | CY4: 36 | CZ4: 32 | DA4: 31 | DB4: 40 | DC4: 42 | DD4: 32 | DE4: 48 | DF4: 61 | DG4: 24
A5: 4 | B5: Indigo | C5: West Johto | D5: Olivine City | F5: 11 | G5: 3 | H5: 12 | I5: 8 | J5: 1 | L5: 15 | M5: 15 | O5: 279 | P5: =194+27 -> 221 | Q5: 119 | R5: =26.278+8.638+1.012+7.073-1.147-6.875 -> 34.979 | S5: =579+58+88+64+95+93 -> 977 | T5: =420.565+36.764+51.595+62.232+56.4+4.601 -> 632.157 | V5: 544 | W5: =512+29 -> 541 | X5: 260 | Y5: =8.611+1.494+3.949+6.008+9.385+6.43+10.217-0.142-5.051-5.274-10.261+0.555-3.218-1.876+1.524-2.082-6.269-3.714-0.414+1.758-1.982 -> 9.648 | Z5: =842+82+80+84+73+86+74+95+99+93+89+94+92+94+94+94+91+92+95+93+92 -> 2628 | AA5: =435.336+40.646+(205.912-53.9143)+3.735+(114.62-7.31)+9.687+50.626+78.805+58.694+11.581+23.286+12.934+1.525+(218.552-62.368)+11.913+8.454+6.009+17.235+(250.516-83.6773)+60.543+8.125 -> 1421.4644 | AC5: =O5+((1/4)*V5) -> 415 | AD5: =P5+((1/4)*W5) -> 356.25 | AE5: =Q5+((1/4)*X5) -> 184 | AF5: =R5+((1/4)*Y5) -> 37.391 | AG5: =S5+((1/4)*Z5) -> 1634 | AH5: =T5+((1/4)*AA5) -> 987.5231 | AI5: =F5+G5+((1/4)*(L5+M5)) -> 21.5 | AJ5: =IFERROR(AC5/AI5, 0) -> 19.302326 | AK5: =IFERROR(AD5/AI5, 0) -> 16.569767 | AL5: =AJ5-AK5 -> 2.7325581 | AM5: =IFERROR(AC5/AE5, 0) -> 2.2554348 | AN5: =IF((AF5)<0, (AF5/2), AF5)/AI5 -> 1.7391163 | AO5: =(AN5-(SMALL(AN:AN,1)))*(2-(1-((1-BX5)/2)))+MIN(AN:AN) -> 1.5118476 | AP5: =AL5-(IF(AVERAGE(AN5:AO5)<0, AVERAGE(AN5:AO5)*2, AVERAGE(AN5:AO5))) -> 1.1070762 | AQ5: =(AVERAGE((AL5-MIN(AL:AL))*AR5, SQRT((AL5-MIN(AL:AL))*AR5))/100)*BX5 -> 5.7392152 | AR5: =(AG5/AI5) -> 76 | AS5: =IFERROR(AH5/AI5,0) -> 45.931307 | AT5: =IFERROR(IF(SQRT(AS5)>10, 10, SQRT(AS5)), 0) -> 6.777264 | AU5: 21 | AV5: 18 | AW5: 35 | AX5: =SUM(AU5:AW5) -> 74 | AZ5: 12 | BA5: =_xlfn.RANK.EQ(BC5,BC:BC, 0) -> 12 | BB5: =AZ5-BA5 -> 0 | BC5: =((BD5*2.25)+(BE5*1.5)+(BF5*1)+(BG5*1)+(BH5*0.75)+(BI5*1)+(BJ5*1)+(BK5*0.75)+(BL5*1)+(BM5*0.75)+(BN5/LARGE(BN:BN,1))*(3/15))/(10+(9/30)) -> 0.78630396 | BD5: =IFERROR(IF((F5+G5)=1, IF(F5=0, 0.333, IF(F5=1, 0.666, 0)), IF((F5+G5)=2, IF(F5=0, 0.166, IF(F5=1, 0.5, IF(F5=2, 0.833, 0))), (F5+(L5/6))/(F5+G5))), 0) -> 0.96428571 | BE5: =IFERROR(IF((I5+J5)=1, IF(I5=0, 0.333, IF(I5=1, 0.666, 0)), IF((I5+J5)=2, IF(I5=0, 0.166, IF(I5=1, 0.5, IF(I5=2, 0.833, 0))), (I5/(I5+J5)))), 0) -> 0.88888889 | BF5: =(AJ5-(SMALL(AJ:AJ, 1)))/((LARGE(AJ:AJ, 1))-(SMALL(AJ:AJ, 1))) -> 0.57691542 | BG5: =1-(AK5-SMALL(AK:AK,1))/(LARGE(AK:AK,1)-SMALL(AK:AK,1)) -> 0.61690799 | BH5: =(AM5-SMALL(AM:AM,1))/(LARGE(AM:AM,1)-SMALL(AM:AM,1)) -> 0.64783384 | BI5: =1-(AO5-SMALL(AO:AO,1))/(LARGE(AO:AO,1)-SMALL(AO:AO,1)) -> 0.49288371 | BJ5: =(AP5+ABS(MIN(AP:AP)))/(MAX(AP:AP)+ABS(MIN(AP:AP))) -> 0.66235137 | BK5: =AVERAGE(AQ5/MAX(AQ:AQ), SQRT(AQ5/MAX(AQ:AQ))) -> 0.67622093 | BL5: =AVERAGE(AT5/MAX(AT:AT), (AT5-SMALL(AT:AT,1))/(LARGE(AT:AT,1)-SMALL(AT:AT,1))) -> 0.69337884 | BM5: =IFERROR(AX5/MAX(AX:AX), 0) -> 0.58730159 | BN5: =30+60 -> 90 | BO5: =BN5+AX5 -> 164 | BP5: 91 | BQ5: =BO5+BP5 -> 255 | BR5: 0.66666667 | BS5: 0.78630396 | BT5: 3 | BU5: 6.777264 | BV5: 0.57691542 | BW5: 0.61690799 | BX5: =IF(A5<17, SoC!O$3, IF(A5<33, SoC!O$4, IF(A5<49, SoC!O$5, IF(A5<65, SoC!O$6, IF(A5<81, SoC!O$7, IF(A5<97, SoC!O$8, SoC!O$9)))))) -> 1.0968296 | BY5: =SQRT(BS5) -> 0.88673782 | BZ5: =IF(BY5<(15/30), "F", IF(BY5<(18/30), "F+", IF(BY5<(19/30), "D-", IF(BY5<(20/30), "D", IF(BY5<(21/30), "D+", IF(BY5<(22/30), "C-", IF(BY5<(23/30), "C", IF(BY5<(24/30), "C+", IF(BY5<(25/30), "B-", IF(BY5<(26/30), "B", IF(BY5<(27/30), "B+", IF(BY5<(28/30), "A-", IF(BY5<(29/30), "A", "A+"))))))))))))) -> B+ | CA5: =(((BS5-$CA$1)/0.15)*3)+((BU5-$BZ$1)/2) -> 5.4821807 | CB5: =CF5-CE5 -> 0 | CC5: 76 | CD5: Olivine City | CE5: 12 | CF5: 12 | CG5: 11 | CH5: 12 | CI5: 12 | CJ5: 12 | CK5: 12 | CL5: 11 | CM5: 9 | CN5: 10 | CO5: 9 | CP5: 10 | CQ5: 11 | CR5: 11 | CS5: 12 | CT5: 14 | CU5: 16 | CV5: 15 | CW5: 14 | CX5: 12 | CY5: 13 | CZ5: 17 | DA5: 17 | DB5: 18 | DC5: 22 | DD5: 30 | DE5: 23 | DF5: 48 | DG5: 37
A6: 5 | B6: Indigo | C6: East Johto | D6: Azalea Town | F6: 5 | G6: 8 | I6: 5 | J6: 4 | L6: 4 | M6: 5 | O6: 176 | P6: 270 | Q6: 103 | R6: =-14.995-5.3-10.645+1.094-5.704 -> -35.55 | S6: =542+64+64+16+62 -> 748 | T6: =203.597+0+0.536+(101.789-0.8945)+5.507 -> 310.5345 | V6: =118+25 -> 143 | W6: =143+15 -> 158 | X6: 77 | Y6: =-6.406+2.223+4.828 -> 0.645 | Z6: =474+23+21 -> 518 | AA6: =91.669+42.593+58.154 -> 192.416 | AC6: =O6+((1/4)*V6) -> 211.75 | AD6: =P6+((1/4)*W6) -> 309.5 | AE6: =Q6+((1/4)*X6) -> 122.25 | AF6: =R6+((1/4)*Y6) -> -35.38875 | AG6: =S6+((1/4)*Z6) -> 877.5 | AH6: =T6+((1/4)*AA6) -> 358.6385 | AI6: =F6+G6+((1/4)*(L6+M6)) -> 15.25 | AJ6: =IFERROR(AC6/AI6, 0) -> 13.885246 | AK6: =IFERROR(AD6/AI6, 0) -> 20.295082 | AL6: =AJ6-AK6 -> -6.4098361 | AM6: =IFERROR(AC6/AE6, 0) -> 1.7321063 | AN6: =IF((AF6)<0, (AF6/2), AF6)/AI6 -> -1.1602869 | AO6: =(AN6-(SMALL(AN:AN,1)))*(2-(1-((1-BX6)/2)))+MIN(AN:AN) -> -1.2471816 | AP6: =AL6-(IF(AVERAGE(AN6:AO6)<0, AVERAGE(AN6:AO6)*2, AVERAGE(AN6:AO6))) -> -4.0023676 | AQ6: =(AVERAGE((AL6-MIN(AL:AL))*AR6, SQRT((AL6-MIN(AL:AL))*AR6))/100)*BX6 -> 1.4133395 | AR6: =(AG6/AI6) -> 57.540984 | AS6: =IFERROR(AH6/AI6,0) -> 23.517279 | AT6: =IFERROR(IF(SQRT(AS6)>10, 10, SQRT(AS6)), 0) -> 4.8494617 | AU6: 21 | AV6: 6 | AW6: 14 | AX6: =SUM(AU6:AW6) -> 41 | AZ6: 82 | BA6: =_xlfn.RANK.EQ(BC6,BC:BC, 0) -> 82 | BB6: =AZ6-BA6 -> 0 | BC6: =((BD6*2.25)+(BE6*1.5)+(BF6*1)+(BG6*1)+(BH6*0.75)+(BI6*1)+(BJ6*1)+(BK6*0.75)+(BL6*1)+(BM6*0.75)+(BN6/LARGE(BN:BN,1))*(3/15))/(10+(9/30)) -> 0.39208454 | BD6: =IFERROR(IF((F6+G6)=1, IF(F6=0, 0.333, IF(F6=1, 0.666, 0)), IF((F6+G6)=2, IF(F6=0, 0.166, IF(F6=1, 0.5, IF(F6=2, 0.833, 0))), (F6+(L6/6))/(F6+G6))), 0) -> 0.43589744 | BE6: =IFERROR(IF((I6+J6)=1, IF(I6=0, 0.333, IF(I6=1, 0.666, 0)), IF((I6+J6)=2, IF(I6=0, 0.166, IF(I6=1, 0.5, IF(I6=2, 0.833, 0))), (I6/(I6+J6)))), 0) -> 0.55555556 | BF6: =(AJ6-(SMALL(AJ:AJ, 1)))/((LARGE(AJ:AJ, 1))-(SMALL(AJ:AJ, 1))) -> 0.11314618 | BG6: =1-(AK6-SMALL(AK:AK,1))/(LARGE(AK:AK,1)-SMALL(AK:AK,1)) -> 0.26933409 | BH6: =(AM6-SMALL(AM:AM,1))/(LARGE(AM:AM,1)-SMALL(AM:AM,1)) -> 0.069441356 | BI6: =1-(AO6-SMALL(AO:AO,1))/(LARGE(AO:AO,1)-SMALL(AO:AO,1)) -> 0.80610741 | BJ6: =(AP6+ABS(MIN(AP:AP)))/(MAX(AP:AP)+ABS(MIN(AP:AP))) -> 0.12912989 | BK6: =AVERAGE(AQ6/MAX(AQ:AQ), SQRT(AQ6/MAX(AQ:AQ))) -> 0.2622553 | BL6: =AVERAGE(AT6/MAX(AT:AT), (AT6-SMALL(AT:AT,1))/(LARGE(AT:AT,1)-SMALL(AT:AT,1))) -> 0.40049722 | BM6: =IFERROR(AX6/MAX(AX:AX), 0) -> 0.32539683 | BN6: 10 | BO6: =BN6+AX6 -> 51 | BP6: 14 | BQ6: =BO6+BP6 -> 65 | BR6: 0 | BS6: 0.39208454 | BT6: 3 | BU6: 4.8494617 | BV6: 0.11314618 | BW6: 0.26933409 | BX6: =IF(A6<17, SoC!O$3, IF(A6<33, SoC!O$4, IF(A6<49, SoC!O$5, IF(A6<65, SoC!O$6, IF(A6<81, SoC!O$7, IF(A6<97, SoC!O$8, SoC!O$9)))))) -> 1.0968296 | BY6: =SQRT(BS6) -> 0.62616655 | BZ6: =IF(BY6<(15/30), "F", IF(BY6<(18/30), "F+", IF(BY6<(19/30), "D-", IF(BY6<(20/30), "D", IF(BY6<(21/30), "D+", IF(BY6<(22/30), "C-", IF(BY6<(23/30), "C", IF(BY6<(24/30), "C+", IF(BY6<(25/30), "B-", IF(BY6<(26/30), "B", IF(BY6<(27/30), "B+", IF(BY6<(28/30), "A-", IF(BY6<(29/30), "A", "A+"))))))))))))) -> D- | CA6: =(((BS6-$CA$1)/0.15)*3)+((BU6-$BZ$1)/2) -> -3.3661088 | CB6: =CF6-CE6 -> 0 | CC6: 61 | CD6: Azalea Town | CE6: 82 | CF6: 82 | CG6: 81 | CH6: 81 | CI6: 81 | CJ6: 81 | CK6: 81 | CL6: 81 | CM6: 81 | CN6: 78 | CO6: 80 | CP6: 71 | CQ6: 71 | CR6: 84 | CS6: 84 | CT6: 75 | CU6: 79 | CV6: 72 | CW6: 70 | CX6: 64 | CY6: 63 | CZ6: 49 | DA6: 46 | DB6: 48 | DC6: 50 | DD6: 77 | DE6: 62 | DF6: 44 | DG6: 52
A7: 6 | B7: Indigo | C7: East Johto | D7: Blackthorn City | F7: 7 | G7: 6 | I7: 4 | J7: 5 | L7: 1 | M7: 3 | O7: 229 | P7: 213 | Q7: 112 | R7: =0.734+3.814+2.881-7.128-0.321 -> -0.02 | S7: =292+38+42+77+52 -> 501 | T7: =396.569+27.27+20.209+5.621+44.594 -> 494.263 | V7: 55 | W7: 66 | X7: 32 | Y7: =-14.568 -> -14.568 | Z7: =170 -> 170 | AA7: =135.123 -> 135.123 | AC7: =O7+((1/4)*V7) -> 242.75 | AD7: =P7+((1/4)*W7) -> 229.5 | AE7: =Q7+((1/4)*X7) -> 120 | AF7: =R7+((1/4)*Y7) -> -3.662 | AG7: =S7+((1/4)*Z7) -> 543.5 | AH7: =T7+((1/4)*AA7) -> 528.04375 | AI7: =F7+G7+((1/4)*(L7+M7)) -> 14 | AJ7: =IFERROR(AC7/AI7, 0) -> 17.339286 | AK7: =IFERROR(AD7/AI7, 0) -> 16.392857 | AL7: =AJ7-AK7 -> 0.94642857 | AM7: =IFERROR(AC7/AE7, 0) -> 2.0229167 | AN7: =IF((AF7)<0, (AF7/2), AF7)/AI7 -> -0.13078571 | AO7: =(AN7-(SMALL(AN:AN,1)))*(2-(1-((1-BX7)/2)))+MIN(AN:AN) -> -0.26752351 | AP7: =AL7-(IF(AVERAGE(AN7:AO7)<0, AVERAGE(AN7:AO7)*2, AVERAGE(AN7:AO7))) -> 1.3447378 | AQ7: =(AVERAGE((AL7-MIN(AL:AL))*AR7, SQRT((AL7-MIN(AL:AL))*AR7))/100)*BX7 -> 2.5783351 | AR7: =(AG7/AI7) -> 38.821429 | AS7: =IFERROR(AH7/AI7,0) -> 37.717411 | AT7: =IFERROR(IF(SQRT(AS7)>10, 10, SQRT(AS7)), 0) -> 6.1414502 | AU7: 21 | AV7: 0 | AX7: =SUM(AU7:AW7) -> 21 | AZ7: 51 | BA7: =_xlfn.RANK.EQ(BC7,BC:BC, 0) -> 51 | BB7: =AZ7-BA7 -> 0 | BC7: =((BD7*2.25)+(BE7*1.5)+(BF7*1)+(BG7*1)+(BH7*0.75)+(BI7*1)+(BJ7*1)+(BK7*0.75)+(BL7*1)+(BM7*0.75)+(BN7/LARGE(BN:BN,1))*(3/15))/(10+(9/30)) -> 0.54798735 | BD7: =IFERROR(IF((F7+G7)=1, IF(F7=0, 0.333, IF(F7=1, 0.666, 0)), IF((F7+G7)=2, IF(F7=0, 0.166, IF(F7=1, 0.5, IF(F7=2, 0.833, 0))), (F7+(L7/6))/(F7+G7))), 0) -> 0.55128205 | BE7: =IFERROR(IF((I7+J7)=1, IF(I7=0, 0.333, IF(I7=1, 0.666, 0)), IF((I7+J7)=2, IF(I7=0, 0.166, IF(I7=1, 0.5, IF(I7=2, 0.833, 0))), (I7/(I7+J7)))), 0) -> 0.44444444 | BF7: =(AJ7-(SMALL(AJ:AJ, 1)))/((LARGE(AJ:AJ, 1))-(SMALL(AJ:AJ, 1))) -> 0.40885485 | BG7: =1-(AK7-SMALL(AK:AK,1))/(LARGE(AK:AK,1)-SMALL(AK:AK,1)) -> 0.63341382 | BH7: =(AM7-SMALL(AM:AM,1))/(LARGE(AM:AM,1)-SMALL(AM:AM,1)) -> 0.39085042 | BI7: =1-(AO7-SMALL(AO:AO,1))/(LARGE(AO:AO,1)-SMALL(AO:AO,1)) -> 0.69488998 | BJ7: =(AP7+ABS(MIN(AP:AP)))/(MAX(AP:AP)+ABS(MIN(AP:AP))) -> 0.68715373 | BK7: =AVERAGE(AQ7/MAX(AQ:AQ), SQRT(AQ7/MAX(AQ:AQ))) -> 0.38842507 | BL7: =AVERAGE(AT7/MAX(AT:AT), (AT7-SMALL(AT:AT,1))/(LARGE(AT:AT,1)-SMALL(AT:AT,1))) -> 0.59678275 | BM7: =IFERROR(AX7/MAX(AX:AX), 0) -> 0.16666667 | BN7: 5 | BO7: =BN7+AX7 -> 26 | BP7: 39 | BQ7: =BO7+BP7 -> 65 | BR7: -1.6666667 | BS7: 0.54798735 | BT7: 2 | BU7: 6.1414502 | BV7: 0.40885485 | BW7: 0.63341382 | BX7: =IF(A7<17, SoC!O$3, IF(A7<33, SoC!O$4, IF(A7<49, SoC!O$5, IF(A7<65, SoC!O$6, IF(A7<81, SoC!O$7, IF(A7<97, SoC!O$8, SoC!O$9)))))) -> 1.0968296 | BY7: =SQRT(BS7) -> 0.74026168 | BZ7: =IF(BY7<(15/30), "F", IF(BY7<(18/30), "F+", IF(BY7<(19/30), "D-", IF(BY7<(20/30), "D", IF(BY7<(21/30), "D+", IF(BY7<(22/30), "C-", IF(BY7<(23/30), "C", IF(BY7<(24/30), "C+", IF(BY7<(25/30), "B-", IF(BY7<(26/30), "B", IF(BY7<(27/30), "B+", IF(BY7<(28/30), "A-", IF(BY7<(29/30), "A", "A+"))))))))))))) -> C | CA7: =(((BS7-$CA$1)/0.15)*3)+((BU7-$BZ$1)/2) -> 0.39794159 | CB7: =CF7-CE7 -> 0 | CC7: 47 | CD7: Blackthorn City | CE7: 51 | CF7: 51 | CG7: 51 | CH7: 51 | CI7: 51 | CJ7: 51 | CK7: 51 | CL7: 51 | CM7: 51 | CN7: 52 | CO7: 52 | CP7: 56 | CQ7: 56 | CR7: 46 | CS7: 47 | CT7: 52 | CU7: 53 | CV7: 59 | CW7: 60 | CX7: 66 | CY7: 65 | CZ7: 79 | DA7: 86 | DB7: 98 | DC7: 105 | DD7: 97 | DE7: 86 | DF7: 68 | DG7: 66
A8: 7 | B8: Indigo | C8: East Johto | D8: Mahogany Town | F8: 5 | G8: 8 | I8: 4 | J8: 5 | L8: 3 | M8: 8 | O8: =184+14 -> 198 | P8: =192+17 -> 209 | Q8: 107 | R8: =14.676+1.597-5.724-5.955+0.321 -> 4.915 | S8: =563+44+74+68+52 -> 801 | T8: =255.194+78.577+12.595+13.063+14.991 -> 374.42 | V8: =147+14 -> 161 | W8: =171+21 -> 192 | X8: 94 | Y8: =-30.481-6.35-3.233 -> -40.064 | Z8: =632+76+78 -> 786 | AA8: =328.603+16.451+12.599 -> 357.653 | AC8: =O8+((1/4)*V8) -> 238.25 | AD8: =P8+((1/4)*W8) -> 257 | AE8: =Q8+((1/4)*X8) -> 130.5 | AF8: =R8+((1/4)*Y8) -> -5.101 | AG8: =S8+((1/4)*Z8) -> 997.5 | AH8: =T8+((1/4)*AA8) -> 463.83325 | AI8: =F8+G8+((1/4)*(L8+M8)) -> 15.75 | AJ8: =IFERROR(AC8/AI8, 0) -> 15.126984 | AK8: =IFERROR(AD8/AI8, 0) -> 16.31746 | AL8: =AJ8-AK8 -> -1.1904762 | AM8: =IFERROR(AC8/AE8, 0) -> 1.8256705 | AN8: =IF((AF8)<0, (AF8/2), AF8)/AI8 -> -0.16193651 | AO8: =(AN8-(SMALL(AN:AN,1)))*(2-(1-((1-BX8)/2)))+MIN(AN:AN) -> -0.29716614 | AP8: =AL8-(IF(AVERAGE(AN8:AO8)<0, AVERAGE(AN8:AO8)*2, AVERAGE(AN8:AO8))) -> -0.73137354 | AQ8: =(AVERAGE((AL8-MIN(AL:AL))*AR8, SQRT((AL8-MIN(AL:AL))*AR8))/100)*BX8 -> 3.4085263 | AR8: =(AG8/AI8) -> 63.333333 | AS8: =IFERROR(AH8/AI8,0) -> 29.44973 | AT8: =IFERROR(IF(SQRT(AS8)>10, 10, SQRT(AS8)), 0) -> 5.4267606 | AU8: 35 | AV8: 6 | AW8: 14 | AX8: =SUM(AU8:AW8) -> 55 | AZ8: 64 | BA8: =_xlfn.RANK.EQ(BC8,BC:BC, 0) -> 64 | BB8: =AZ8-BA8 -> 0 | BC8: =((BD8*2.25)+(BE8*1.5)+(BF8*1)+(BG8*1)+(BH8*0.75)+(BI8*1)+(BJ8*1)+(BK8*0.75)+(BL8*1)+(BM8*0.75)+(BN8/LARGE(BN:BN,1))*(3/15))/(10+(9/30)) -> 0.48068896 | BD8: =IFERROR(IF((F8+G8)=1, IF(F8=0, 0.333, IF(F8=1, 0.666, 0)), IF((F8+G8)=2, IF(F8=0, 0.166, IF(F8=1, 0.5, IF(F8=2, 0.833, 0))), (F8+(L8/6))/(F8+G8))), 0) -> 0.42307692 | BE8: =IFERROR(IF((I8+J8)=1, IF(I8=0, 0.333, IF(I8=1, 0.666, 0)), IF((I8+J8)=2, IF(I8=0, 0.166, IF(I8=1, 0.5, IF(I8=2, 0.833, 0))), (I8/(I8+J8)))), 0) -> 0.44444444 | BF8: =(AJ8-(SMALL(AJ:AJ, 1)))/((LARGE(AJ:AJ, 1))-(SMALL(AJ:AJ, 1))) -> 0.21945438 | BG8: =1-(AK8-SMALL(AK:AK,1))/(LARGE(AK:AK,1)-SMALL(AK:AK,1)) -> 0.64044839 | BH8: =(AM8-SMALL(AM:AM,1))/(LARGE(AM:AM,1)-SMALL(AM:AM,1)) -> 0.17285023 | BI8: =1-(AO8-SMALL(AO:AO,1))/(LARGE(AO:AO,1)-SMALL(AO:AO,1)) -> 0.69825521 | BJ8: =(AP8+ABS(MIN(AP:AP)))/(MAX(AP:AP)+ABS(MIN(AP:AP))) -> 0.47049078 | BK8: =AVERAGE(AQ8/MAX(AQ:AQ), SQRT(AQ8/MAX(AQ:AQ))) -> 0.46929215 | BL8: =AVERAGE(AT8/MAX(AT:AT), (AT8-SMALL(AT:AT,1))/(LARGE(AT:AT,1)-SMALL(AT:AT,1))) -> 0.48820343 | BM8: =IFERROR(AX8/MAX(AX:AX), 0) -> 0.43650794 | BN8: 5 | BO8: =BN8+AX8 -> 60 | BP8: 27 | BQ8: =BO8+BP8 -> 87 | BR8: -1.6666667 | BS8: 0.48068896 | BT8: 4 | BU8: 5.4267606 | BV8: 0.21945438 | BW8: 0.64044839 | BX8: =IF(A8<17, SoC!O$3, IF(A8<33, SoC!O$4, IF(A8<49, SoC!O$5, IF(A8<65, SoC!O$6, IF(A8<81, SoC!O$7, IF(A8<97, SoC!O$8, SoC!O$9)))))) -> 1.0968296 | BY8: =SQRT(BS8) -> 0.69331736 | BZ8: =IF(BY8<(15/30), "F", IF(BY8<(18/30), "F+", IF(BY8<(19/30), "D-", IF(BY8<(20/30), "D", IF(BY8<(21/30), "D+", IF(BY8<(22/30), "C-", IF(BY8<(23/30), "C", IF(BY8<(24/30), "C+", IF(BY8<(25/30), "B-", IF(BY8<(26/30), "B", IF(BY8<(27/30), "B+", IF(BY8<(28/30), "A-", IF(BY8<(29/30), "A", "A+"))))))))))))) -> D+ | CA8: =(((BS8-$CA$1)/0.15)*3)+((BU8-$BZ$1)/2) -> -1.3053709 | CB8: =CF8-CE8 -> 0 | CC8: 83 | CD8: Mahogany Town | CE8: 64 | CF8: 64 | CG8: 64 | CH8: 64 | CI8: 64 | CJ8: 64 | CK8: 65 | CL8: 65 | CM8: 65 | CN8: 65 | CO8: 64 | CP8: 63 | CQ8: 62 | CR8: 56 | CS8: 56 | CT8: 50 | CU8: 49 | CV8: 58 | CW8: 62 | CX8: 54 | CY8: 58 | CZ8: 50 | DA8: 56 | DB8: 38 | DC8: 21 | DD8: 35 | DE8: 15 | DF8: 27 | DG8: 30
A9: 8 | B9: Indigo | C9: East Johto | D9: Violet City | F9: 10 | G9: 3 | I9: 7 | J9: 2 | L9: 2 | M9: 2 | O9: 251 | P9: 178 | Q9: 128 | R9: =-11.161+5.334+5.529+7.475+5.704 -> 12.881 | S9: =479+53+49+52+62 -> 695 | T9: =401.67+(100.529-0.2645)+78.856+45.512+(168.851-34.4255) -> 760.728 | V9: 65 | W9: 57 | X9: 27 | Y9: =10.811 -> 10.811 | Z9: =167 -> 167 | AA9: =106.569 -> 106.569 | AC9: =O9+((1/4)*V9) -> 267.25 | AD9: =P9+((1/4)*W9) -> 192.25 | AE9: =Q9+((1/4)*X9) -> 134.75 | AF9: =R9+((1/4)*Y9) -> 15.58375 | AG9: =S9+((1/4)*Z9) -> 736.75 | AH9: =T9+((1/4)*AA9) -> 787.37025 | AI9: =F9+G9+((1/4)*(L9+M9)) -> 14 | AJ9: =IFERROR(AC9/AI9, 0) -> 19.089286 | AK9: =IFERROR(AD9/AI9, 0) -> 13.732143 | AL9: =AJ9-AK9 -> 5.3571429 | AM9: =IFERROR(AC9/AE9, 0) -> 1.9833024 | AN9: =IF((AF9)<0, (AF9/2), AF9)/AI9 -> 1.113125 | AO9: =(AN9-(SMALL(AN:AN,1)))*(2-(1-((1-BX9)/2)))+MIN(AN:AN) -> 0.91616352 | AP9: =AL9-(IF(AVERAGE(AN9:AO9)<0, AVERAGE(AN9:AO9)*2, AVERAGE(AN9:AO9))) -> 4.3424986 | AQ9: =(AVERAGE((AL9-MIN(AL:AL))*AR9, SQRT((AL9-MIN(AL:AL))*AR9))/100)*BX9 -> 4.7695433 | AR9: =(AG9/AI9) -> 52.625 | AS9: =IFERROR(AH9/AI9,0) -> 56.240732 | AT9: =IFERROR(IF(SQRT(AS9)>10, 10, SQRT(AS9)), 0) -> 7.4993821 | AU9: 7 | AV9: 12 | AX9: =SUM(AU9:AW9) -> 19 | AZ9: 15 | BA9: =_xlfn.RANK.EQ(BC9,BC:BC, 0) -> 15 | BB9: =AZ9-BA9 -> 0 | BC9: =((BD9*2.25)+(BE9*1.5)+(BF9*1)+(BG9*1)+(BH9*0.75)+(BI9*1)+(BJ9*1)+(BK9*0.75)+(BL9*1)+(BM9*0.75)+(BN9/LARGE(BN:BN,1))*(3/15))/(10+(9/30)) -> 0.73693288 | BD9: =IFERROR(IF((F9+G9)=1, IF(F9=0, 0.333, IF(F9=1, 0.666, 0)), IF((F9+G9)=2, IF(F9=0, 0.166, IF(F9=1, 0.5, IF(F9=2, 0.833, 0))), (F9+(L9/6))/(F9+G9))), 0) -> 0.79487179 | BE9: =IFERROR(IF((I9+J9)=1, IF(I9=0, 0.333, IF(I9=1, 0.666, 0)), IF((I9+J9)=2, IF(I9=0, 0.166, IF(I9=1, 0.5, IF(I9=2, 0.833, 0))), (I9/(I9+J9)))), 0) -> 0.77777778 | BF9: =(AJ9-(SMALL(AJ:AJ, 1)))/((LARGE(AJ:AJ, 1))-(SMALL(AJ:AJ, 1))) -> 0.55867656 | BG9: =1-(AK9-SMALL(AK:AK,1))/(LARGE(AK:AK,1)-SMALL(AK:AK,1)) -> 0.88165994 | BH9: =(AM9-SMALL(AM:AM,1))/(LARGE(AM:AM,1)-SMALL(AM:AM,1)) -> 0.347068 | BI9: =1-(AO9-SMALL(AO:AO,1))/(LARGE(AO:AO,1)-SMALL(AO:AO,1)) -> 0.5605098 | BJ9: =(AP9+ABS(MIN(AP:AP)))/(MAX(AP:AP)+ABS(MIN(AP:AP))) -> 1 | BK9: =AVERAGE(AQ9/MAX(AQ:AQ), SQRT(AQ9/MAX(AQ:AQ))) -> 0.59282373 | BL9: =AVERAGE(AT9/MAX(AT:AT), (AT9-SMALL(AT:AT,1))/(LARGE(AT:AT,1)-SMALL(AT:AT,1))) -> 0.80308674 | BM9: =IFERROR(AX9/MAX(AX:AX), 0) -> 0.15079365 | BN9: 10 | BO9: =BN9+AX9 -> 29 | BP9: 83 | BQ9: =BO9+BP9 -> 112 | BR9: 0 | BS9: 0.73693288 | BT9: 1 | BU9: 7.4993821 | BV9: 0.55867656 | BW9: 0.88165994 | BX9: =IF(A9<17, SoC!O$3, IF(A9<33, SoC!O$4, IF(A9<49, SoC!O$5, IF(A9<65, SoC!O$6, IF(A9<81, SoC!O$7, IF(A9<97, SoC!O$8, SoC!O$9)))))) -> 1.0968296 | BY9: =SQRT(BS9) -> 0.85844795 | BZ9: =IF(BY9<(15/30), "F", IF(BY9<(18/30), "F+", IF(BY9<(19/30), "D-", IF(BY9<(20/30), "D", IF(BY9<(21/30), "D+", IF(BY9<(22/30), "C-", IF(BY9<(23/30), "C", IF(BY9<(24/30), "C+", IF(BY9<(25/30), "B-", IF(BY9<(26/30), "B", IF(BY9<(27/30), "B+", IF(BY9<(28/30), "A-", IF(BY9<(29/30), "A", "A+"))))))))))))) -> B | CA9: =(((BS9-$CA$1)/0.15)*3)+((BU9-$BZ$1)/2) -> 4.8558181 | CB9: =CF9-CE9 -> 0 | CC9: 38 | CD9: Violet City | CE9: 15 | CF9: 15 | CG9: 15 | CH9: 15 | CI9: 15 | CJ9: 15 | CK9: 15 | CL9: 15 | CM9: 17 | CN9: 18 | CO9: 19 | CP9: 23 | CQ9: 25 | CR9: 24 | CS9: 24 | CT9: 29 | CU9: 29 | CV9: 37 | CW9: 36 | CX9: 43 | CY9: 46 | CZ9: 53 | DA9: 44 | DB9: 46 | DC9: 70 | DD9: 79 | DE9: 94 | DF9: 78 | DG9: 75
