Workbook

Sheet AutoScoreboard
C1: Score | D1: DSCR | E1: Off/Def | F1: Fatigue | G1: Climate | H1: DEX | N1: DEX | O1: Climate | P1: Fatigue | Q1: Off/Def | R1: DSCR | S1: Score
A2: AGG | I2: SEASON FOUR WORLD CHAMPIONSHIP | U2: Legs
A3: PLAYOFFS | C3: =INDEX(Rankings!BK2:'Rankings'!BK129, (J4), 1) -> 0.84947088 | D3: =INDEX(Rankings!BJ2:'Rankings'!BJ129, (J4), 1) -> 6.5982005 | E3: =INDEX(Rankings!BH2:BH129,J4,1)-INDEX(Rankings!BI2:BI129,L4,1) -> -0.41986277 | F3: =INDEX(Rankings!BE2:'Rankings'!BE129, (J4), 1) -> 161.84375 | G3: =INDEX(Rankings!BF2:'Rankings'!BF129, (J4), 1) -> 1 | H3: =INDEX(Rankings!A2:'Rankings'!A129, (J4), 1) -> 109 | I3: WORLD CHAMPIONSHIP - Lumiose City wins 2-0 | N3: =INDEX(Rankings!A2:'Rankings'!A129, (L4), 1) -> 72 | O3: =INDEX(Rankings!BF2:'Rankings'!BF129, (L4), 1) -> 0.33333333 | P3: =INDEX(Rankings!BE2:'Rankings'!BE129, (L4), 1) -> 115 | Q3: =INDEX(Rankings!BH2:BH129,L4,1)-INDEX(Rankings!BI2:BI129,J4,1) -> -0.14116615 | R3: =INDEX(Rankings!BJ2:'Rankings'!BJ129, (L4), 1) -> 7.5280955 | S3: =INDEX(Rankings!BK2:'Rankings'!BK129, (L4), 1) -> 0.99722768 | U3: Cup
C4: =INDEX(Rankings!C2:'Rankings'!C129, (J4), 1) -> Hulbury | J4: 10 | K4: =Q22*IF(Q22>0, 1+(F3-P3)*0.005, 1-(F3-P3)*0.005)*IF(Q22>0, S22, 1/S22) -> 17.028751 | L4: 1 | M4: =INDEX(Rankings!C2:'Rankings'!C129, (L4), 1) -> Lumiose City | U4: Stage
K5: =(((1-(((AVERAGE(J4,L4)*(IF(AND(J4<32, L4<32), 0.875, IF(OR(J4<32, L4<32), 1, IF(AND(J4>64, L4>64), 1.25, 1.125)))))+(IF(H26>0, G26, G27)))*(1-IF(A2="AGG", 0.06, 0)-IF(A3="WCS", 0.08, 0)-IF(A3="MRL", 0.06, 0)-IF(A3="UTL", 0.04, 0)-IF(A3="CONF", 0.1, 0)-IF(A3="PLAYOFFS", 0.12, 0))/150))*100)+(IF(G178>2, G178-2, 0)))*(1+(0.01*(A14-4)))*(1-(0.0025*T24))*IF(A13<3, 0.98, IF(A13=4, 1.02, IF(A13=5, 0.99, 1))) -> 89.526493 | U5: Neutral
J6: =IF(ISBLANK(K6), "", K6+G9) -> 39 | K6: 20 | L6: =IF(ISBLANK(K7), "", K7+M9) -> 57
D7: =CONCATENATE("(#", INDEX(Rankings!BY2:'Rankings'!BY129, (J4), 1), ", ", INDEX(Rankings!I2:'Rankings'!I129, (J4), 1), "-", INDEX(Rankings!J2:'Rankings'!J129, (J4), 1), ") ", INDEX(Rankings!F2:'Rankings'!F129, (J4), 1), "-", INDEX(Rankings!G2:'Rankings'!G129, (J4), 1)) -> (#1, 9-0) 11-1 | E7: =INDEX(Rankings!B2:'Rankings'!B129, (J4), 1) -> Dynamax | F7: =IF(K4<=-0.5, CONCATENATE("[+", ROUND(-K4, 0), "]"), "[--]") -> [--] | G7: =IF(A3="WCS",CONCATENATE(INDEX(Rankings!BR2:'Rankings'!BR129,(J4),1)," (",INDEX(Rankings!BS2:'Rankings'!BS129,(J4),1)," Region)"), IF(OR(A3="MRL", A3="UTL"), CONCATENATE(INDEX(Rankings!BT2:'Rankings'!BT129,(J4),1), " Group ", INDEX(Rankings!BU2:'Rankings'!BU129,(J4),1), " - #", INDEX(Rankings!BV2:'Rankings'!BV129,(J4),1)), INDEX(Rankings!BW2:'Rankings'!BW129,(J4),1))) -> - | I7: =IFERROR(IF(SQRT(R26/100)<1, AVERAGE(SQRT(R26/100), R26/100)*100, ((R26-100)/100+10)^2),0) -> 19.3107 | K7: 21 | M7: =IFERROR(IF(SQRT(R27/100)<1, AVERAGE(SQRT(R27/100), R27/100)*100, ((R27-100)/100+10)^2),0) -> 99.465774 | N7: =IF(A3="WCS",CONCATENATE(INDEX(Rankings!BR2:'Rankings'!BR129,(L4),1)," (",INDEX(Rankings!BS2:'Rankings'!BS129,(L4),1)," Region)"), IF(OR(A3="MRL", A3="UTL"), CONCATENATE(INDEX(Rankings!BT2:'Rankings'!BT129,(L4),1), " Group ", INDEX(Rankings!BU2:'Rankings'!BU129,(L4),1), " - #", INDEX(Rankings!BV2:'Rankings'!BV129,(L4),1)), INDEX(Rankings!BW2:'Rankings'!BW129,(L4),1))) -> S4 Kalosite Champion | P7: =IF(K4>=0.5, CONCATENATE("[+", ROUND(K4, 0), "]"), "[--]") -> [+17] | Q7: =INDEX(Rankings!B2:'Rankings'!B129, (L4), 1) -> Kalosite | R7: =CONCATENATE(INDEX(Rankings!F2:'Rankings'!F129, (L4), 1), "-", INDEX(Rankings!G2:'Rankings'!G129, (L4), 1), " (", INDEX(Rankings!I2:'Rankings'!I129, (L4), 1), "-", INDEX(Rankings!J2:'Rankings'!J129, (L4), 1), ", #", INDEX(Rankings!BY2:'Rankings'!BY129, (L4), 1), ")") -> 11-1 (8-1, #2)
C8: =INDEX(Rankings!BL2:BL129, (J4)) -> 2082 | D8: =CONCATENATE(INDEX(Rankings!F2:'Rankings'!F129, (J4), 1)+INDEX(Rankings!L2:'Rankings'!L129, (J4), 1), "-", INDEX(Rankings!G2:'Rankings'!G129, (J4), 1)+INDEX(Rankings!M2:'Rankings'!M129, (J4), 1)) -> 27-16 | E8: Overall | G8: =IF(A3="WCS", "", INDEX(Rankings!BX2:'Rankings'!BX129, (J4), 1)) -> - | J8: =IF(K13=0, "", IF(K13=1, "1st",IF(K13=2, "2nd",IF(K13=3, "1st", IF(K13=4, "2nd", IF(K13=5, "3rd", IF(K13>5, CONCATENATE(K13-2,"th")))))))) | K8: =IF(K13=0,IF(G178=2,"Final",IF(G178>2,CONCATENATE("Final/",IF(G178=3,"",G178-2),"OT"))),IF(T180="GOOD",IF(K13<3,"HALF","Overtime"),"Duplicate")) -> Final | N8: =IF(A3="WCS", "", INDEX(Rankings!BX2:'Rankings'!BX129, (L4), 1)) -> S4 WCS Champion | Q8: Overall | R8: =CONCATENATE(INDEX(Rankings!F2:'Rankings'!F129, (L4), 1)+INDEX(Rankings!L2:'Rankings'!L129, (L4), 1), "-", INDEX(Rankings!G2:'Rankings'!G129, (L4), 1)+INDEX(Rankings!M2:'Rankings'!M129, (L4), 1)) -> 43-6 | S8: =INDEX(Rankings!BL2:BL129, (L4)) -> 2303
C9: =IF(C171<>0, C171, "") | D9: =IF(D171<>0, D171, "") | E9: =IF(E171<>0, E171, "") -> 3*37 | F9: =IF(F171<>0, F171, "") -> 2*6 | G9: =SUM(G198:J203) -> 19 | M9: =SUM(L198:O203) -> 36 | P9: =IF(P171<>0, P171, "") -> 3*8! | Q9: =IF(Q171<>0, Q171, "") -> 1*44 | R9: =IF(R171<>0, R171, "") | S9: =IF(S171<>0, S171, "")
C10: =IF(C172<>0, C172, "") | D10: =IF(D172<>0, D172, "") | E10: =IF(E172<>0, E172, "") -> 3*48 | F10: =IF(F172<>0, F172, "") -> 1*10 | J10: =J178 -> 624 | L10: 0 | P10: =IF(P172<>0, P172, "") -> 2*21 | Q10: =IF(Q172<>0, Q172, "") -> 1*50+2 | R10: =IF(R172<>0, R172, "") | S10: =IF(S172<>0, S172, "")
A11: =IF(A13=1, "Tuesday", IF(A13=2, "Thursday", IF(A13=3, "Saturday", IF(A13=4, "Sunday", "Friday")))) -> Thursday | C11: =IF(C173<>0, C173, "") | D11: =IF(D173<>0, D173, "") | E11: =IF(E173<>0, E173, "") -> 1*50+7 | F11: =IF(F173<>0, F173, "") -> 1*13 | P11: =IF(P173<>0, P173, "") -> 1*25+6! | Q11: =IF(Q173<>0, Q173, "") -> 2*50+4 | R11: =IF(R173<>0, R173, "") | S11: =IF(S173<>0, S173, "") | U11: Day
A12: =IF(A14=1, "12:00p", IF(A14=2, "1:15p", IF(A14=3, "2:30p", IF(A14=4, "3:45p", IF(A14=5, "5:00p", IF(A14=6, "6:15p", IF(A14=7, "7:30p", "8:45p"))))))) -> 8:45p | C12: =IF(C174<>0, C174, "") | D12: =IF(D174<>0, D174, "") | E12: =IF(E174<>0, E174, "") -> 2*50+10 | F12: =IF(F174<>0, F174, "") -> 1*19! | P12: =IF(P174<>0, P174, "") -> 2*25+11 | Q12: =IF(Q174<>0, Q174, "") -> 4*50+12$ | R12: =IF(R174<>0, R174, "") | S12: =IF(S174<>0, S174, "") | U12: Time
A13: 2 | C13: =IF(C175<>0, C175, "") | D13: =IF(D175<>0, D175, "") | E13: =IF(E175<>0, E175, "") | F13: =IF(F175<>0, F175, "") -> 2*22 | J13: 247 | K13: =IF(L13="FINAL", 0, ROUNDDOWN(J13/100, 0)) -> 0 | L13: =K178 -> FINAL | P13: =IF(P175<>0, P175, "") -> 1*29 | Q13: =IF(Q175<>0, Q175, "") | R13: =IF(R175<>0, R175, "") | S13: =IF(S175<>0, S175, "") | U13: TRSSF
A14: 8 | C14: =IF(C176<>0, C176, "") | D14: =IF(D176<>0, D176, "") | E14: =IF(E176<>0, E176, "") | F14: =IF(F176<>0, F176, "") -> 1*24 | K14: =IF(K13=0, "", (CONCATENATE(IF(K13=1,IF(J10<251,ROUNDUP(J10/10,0),CONCATENATE("25+",ROUNDUP((J10-250)/10,0))),IF(K13=2,IF(J10<501,ROUNDUP(J10/10,0),CONCATENATE("50+",ROUNDUP((J10-500)/10,0))),IF(K13>2,IF(J10<(301+(100*K13)),ROUNDUP(J10/10,0),CONCATENATE((K13+3),"0+",ROUNDUP((J10-(300+(K13*100)))/10, 0)))))), "'"))) | L14: =IF(L178/10<0, 0, L178/10) -> 57.5 | P14: =IF(P176<>0, P176, "") -> 1*39 | Q14: =IF(Q176<>0, Q176, "") | R14: =IF(R176<>0, R176, "") | S14: =IF(S176<>0, S176, "") | U14: 1-8
A15: =IF(A179=0, "CHANGE", "") -> CHANGE | C15: =IF($I$178=C180, IF($H$178=2, ">>>>", "<<<<"), "") | D15: =IF($I$178=D180, IF($H$178=2, ">>>>", "<<<<"), "") | E15: =IF($I$178=E180, IF($H$178=2, ">>>>", "<<<<"), "") | F15: =IF($I$178=F180, IF($H$178=2, ">>>>", "<<<<"), "") | G15: =IF($I$178=G180, IF($H$178=2, ">>>>", "<<<<"), "") | H15: =IF($I$178=H180, IF($H$178=2, ">>>>", "<<<<"), "") -> <<<< | I15: =IF($I$178=I180, IF($H$178=2, ">>>>", "<<<<"), "") | J15: =IF($I$178=J180, IF($H$178=2, ">>>>", "<<<<"), "") | ... S15: =IF($I$178=S180, IF($H$178=2, ">>>>", "<<<<"), "")
B16: GOAL | C16: X | D16: X | E16: =CONCATENATE(Cards!E1, "|", Cards!F1) -> 3|4 | F16: =CONCATENATE(Cards!E2, "|", Cards!F2) -> 2|3 | G16: =CONCATENATE(Cards!E3, "|", Cards!F3) -> 2|2 | H16: =CONCATENATE(Cards!E4, "|", Cards!F4) -> 2|2 | I16: =CONCATENATE(Cards!E5, "|", Cards!F5) -> 1|1 | J16: =CONCATENATE(Cards!E6, "|", Cards!F6) -> 1|1 | K16: =CONCATENATE(Cards!E7, "|", Cards!F7) -> 1|1 | L16: =CONCATENATE(Cards!E8, "|", Cards!F8) -> 1|1 | M16: =CONCATENATE(Cards!E9, "|", Cards!F9) -> 1|1 | N16: =CONCATENATE(Cards!E10, "|", Cards!F10) -> 2|2 | O16: =CONCATENATE(Cards!E11, "|", Cards!F11) -> 2|2 | P16: =CONCATENATE(Cards!E12, "|", Cards!F12) -> 2|3 | Q16: =CONCATENATE(Cards!E13, "|", Cards!F13) -> 3|4 | R16: X | S16: X | T16: GOAL
F17: * | G17: K | H17: Q | I17: J | K17: =IF(J13=100, "RESET", "9*9") -> 9*9 | M17: J | N17: Q | O17: K | P17: *
B19: REGIONAL WEATHER | E19: Elo Win% | F19: K-Value | G19: Elo Change | J19: =IFERROR(VLOOKUP(VLOOKUP(J13-1, Cards!AK:AP, 5, FALSE), A190:B202, 2, FALSE), "") -> J | K19: =IFERROR(VLOOKUP(VLOOKUP(J13-1, Cards!AK:AP, 6, FALSE), A190:B202, 2, FALSE), "") -> 7 | N19: Rating | O19: Home Adv | P19: Climate | Q19: Eye Test | R19: ELO | S19: Game
B20: Indigo | C20: =CONCATENATE(IF(M184<(15/30), "F", IF(M184<(18/30), "F+", IF(M184<(19/30), "D-", IF(M184<(20/30), "D", IF(M184<(21/30), "D+", IF(M184<(22/30), "C-", IF(M184<(23/30), "C", IF(M184<(24/30), "C+", IF(M184<(25/30), "B-", IF(M184<(26/30), "B", IF(M184<(27/30), "B+", IF(M184<(28/30), "A-", IF(M184<(29/30), "A", "A+"))))))))))))), " ", ROUND(M184*100,0)) -> C+ 77 | E20: =1/(10^(-(C8-S8-(O20*100))/400)+1)*100 -> 13.612852 | F20: =(24+IF(OR(A3="WCS",A3="MRL",A3="UTL",A3="CONF"),8,IF(A3="PLAYOFFS",16,0))+IF(S22>1,8,0))+(ABS(H26)-4) -> 61 | G20: =ROUNDUP(IF(G9>M9, (1-(E20/100))*F20, (1-(E21/100))*F20),0) -> 9 | L20: =IFERROR(J10-VLOOKUP(K21, A205:B217, 2, FALSE), "") -> 620 | N20: =(((S3-C3)/0.15)*3) -> 2.9551361 | O20: =IF(OR(A3="WCS", A3="CONF", A3="PLAYOFFS"), 1, IF(OR(A3="MRL", A3="UTL"), 0.75, 0.5)) -> 1 | P20: =INDEX(M184:M191,L194)*((ABS(O3-G3)/3)+(1/3)) -> 0.39588071 | Q20: =((R3-D3)/2) -> 0.46494751 | R20: =(E21-E20)/50 -> 1.4554859 | S20: Spread | W20: Favorite
B21: Delta | C21: =CONCATENATE(IF(M185<(15/30), "F", IF(M185<(18/30), "F+", IF(M185<(19/30), "D-", IF(M185<(20/30), "D", IF(M185<(21/30), "D+", IF(M185<(22/30), "C-", IF(M185<(23/30), "C", IF(M185<(24/30), "C+", IF(M185<(25/30), "B-", IF(M185<(26/30), "B", IF(M185<(27/30), "B+", IF(M185<(28/30), "A-", IF(M185<(29/30), "A", "A+"))))))))))))), " ", ROUND(M185*100,0)) -> D- 62 | E21: =1/(10^(-(S8-C8+(O20*100))/400)+1)*100 -> 86.387148 | J21: =IFERROR(VLOOKUP(VLOOKUP(J13, Cards!AK:AP, 5, FALSE), A190:B202, 2, FALSE), "") -> 2 | K21: =IFERROR(VLOOKUP(VLOOKUP(J13, Cards!AK:AP, 6, FALSE), A190:B202, 2, FALSE), "") -> 4 | N21: =IF(K4>=0, M4, C4) -> Lumiose City | P21: WCS Seed | Q21: Raw Sprd | R21: Fatigue | S21: Playoffs | W21: Difference
B22: Lily Valley | C22: =CONCATENATE(IF(M186<(15/30), "F", IF(M186<(18/30), "F+", IF(M186<(19/30), "D-", IF(M186<(20/30), "D", IF(M186<(21/30), "D+", IF(M186<(22/30), "C-", IF(M186<(23/30), "C", IF(M186<(24/30), "C+", IF(M186<(25/30), "B-", IF(M186<(26/30), "B", IF(M186<(27/30), "B+", IF(M186<(28/30), "A-", IF(M186<(29/30), "A", "A+"))))))))))))), " ", ROUND(M186*100,0)) -> C 76 | L22: =J10 -> 624 | N22: =CONCATENATE("favored by ", IF(K4>0, ROUND(K4, 2), ROUND(-K4, 2))) -> favored by 17.03 | P22: =IF(A3="WCS", (MID(INDEX(Rankings!BR2:'Rankings'!BR129, (L4), 1), 2, 2)-MID(INDEX(Rankings!BR2:'Rankings'!BR129, (J4), 1), 2, 2))/-4, "-") -> - | Q22: =(SUM(N20:R20)+IF(P22="-", 0, P22)) -> 6.2714502 | R22: =1+(F3-P3)*0.005 -> 1.2342187 | S22: 2.2 | W22: Overtime
B23: Vertress | C23: =CONCATENATE(IF(M187<(15/30), "F", IF(M187<(18/30), "F+", IF(M187<(19/30), "D-", IF(M187<(20/30), "D", IF(M187<(21/30), "D+", IF(M187<(22/30), "C-", IF(M187<(23/30), "C", IF(M187<(24/30), "C+", IF(M187<(25/30), "B-", IF(M187<(26/30), "B", IF(M187<(27/30), "B+", IF(M187<(28/30), "A-", IF(M187<(29/30), "A", "A+"))))))))))))), " ", ROUND(M187*100,0)) -> C 74 | T23: Mins Late | W23: ATS
B24: Kalosite | C24: =CONCATENATE(IF(M188<(15/30), "F", IF(M188<(18/30), "F+", IF(M188<(19/30), "D-", IF(M188<(20/30), "D", IF(M188<(21/30), "D+", IF(M188<(22/30), "C-", IF(M188<(23/30), "C", IF(M188<(24/30), "C+", IF(M188<(25/30), "B-", IF(M188<(26/30), "B", IF(M188<(27/30), "B+", IF(M188<(28/30), "A-", IF(M188<(29/30), "A", "A+"))))))))))))), " ", ROUND(M188*100,0)) -> C- 71 | E24: DYNAMAX SCORE CALCULATION | S24: Game Time | T24: 1 | W24: Stoppage
B25: Lanakila | C25: =CONCATENATE(IF(M189<(15/30), "F", IF(M189<(18/30), "F+", IF(M189<(19/30), "D-", IF(M189<(20/30), "D", IF(M189<(21/30), "D+", IF(M189<(22/30), "C-", IF(M189<(23/30), "C", IF(M189<(24/30), "C+", IF(M189<(25/30), "B-", IF(M189<(26/30), "B", IF(M189<(27/30), "B+", IF(M189<(28/30), "A-", IF(M189<(29/30), "A", "A+"))))))))))))), " ", ROUND(M189*100,0)) -> C 75 | E25: Away | F25: Home | G25: Favorite | H25: Difference | I25: Overtime? | J25: ATS | K25: !#$+ | L25: MOV/SEC | M25: LEAD | N25: LEAD SIZE | O25: Goal Diff. | P25: Goal Avg. | Q25: Multiplier | R25: Raw DSCR | S25: =Cards!BL1 -> 75 | W25: Aces/KRs
B26: Dynamax | C26: =CONCATENATE(IF(M190<(15/30), "F", IF(M190<(18/30), "F+", IF(M190<(19/30), "D-", IF(M190<(20/30), "D", IF(M190<(21/30), "D+", IF(M190<(22/30), "C-", IF(M190<(23/30), "C", IF(M190<(24/30), "C+", IF(M190<(25/30), "B-", IF(M190<(26/30), "B", IF(M190<(27/30), "B+", IF(M190<(28/30), "A-", IF(M190<(29/30), "A", "A+"))))))))))))), " ", ROUND(M190*100,0)) -> D 66 | E26: =C4 -> Hulbury | G26: =-G27 -> -17.028751 | H26: =G9-M9 -> -17 | I26: =IF(ROUNDDOWN(J13/100, 0)>2, -G26, 0) -> 0 | J26: =IF(AND(G26>0, H26>0, G26>H26), H26/G26, IF(AND(G26<0, H26<0, H26>G26), 3*(1-(H26/G26)), IF(AND(G26<0, H26<G26), -(H26/G26), IF(AND(G26>0, H26>0, H26>G26), 1+(H26/G26), IF(AND(G26<0, H26>0), -G26+(0.5*(H26+G26)), IF(AND(G26>0, H26<0), -G26+(0.25*H26), 0))))))/1.5 -> 0.003376784 | K26: =SUM(C182:F187) -> 5 | L26: =IFERROR(Cards!CC1*3,0) -> 1.4583127 | M26: =IFERROR(Cards!BP2*2,0) -> 0.24210526 | N26: =IFERROR(IF(Cards!BO1>0, Cards!BO1, 0),0) -> 0 | O26: =IF(AND(H26>0, (H26-G26)>0), IF((COUNT(C182:F187)-COUNT(P182:S187))<0, (COUNT(C182:F187)-COUNT(P182:S187))*-1, (COUNT(C182:F187)-COUNT(P182:S187))*0.25), 0) -> 0 | P26: =IFERROR(SUM(C190:F195)/COUNT(C182:F187),0) -> 1.7 | Q26: =IFERROR((G9/M9)*(S3+1), G9*(S3+1)) -> 1.0540924 | R26: =IFERROR(IF(((SUM(I26:P26)-IF(J26>G9,J26-G9,0)+IF(J26<-M9,-M9-J26, 0))*Q26)<0, 0, ((SUM(I26:P26)-IF(J26>G9,J26-G9,0)+IF(J26<-M9,-M9-J26, 0))*Q26)),0) -> 8.8583761 | T26: Next Block | W26: Time Led
B27: Phoenix | C27: =CONCATENATE(IF(M191<(15/30), "F", IF(M191<(18/30), "F+", IF(M191<(19/30), "D-", IF(M191<(20/30), "D", IF(M191<(21/30), "D+", IF(M191<(22/30), "C-", IF(M191<(23/30), "C", IF(M191<(24/30), "C+", IF(M191<(25/30), "B-", IF(M191<(26/30), "B", IF(M191<(27/30), "B+", IF(M191<(28/30), "A-", IF(M191<(29/30), "A", "A+"))))))))))))), " ", ROUND(M191*100,0)) -> F+ 58 | E27: =M4 -> Lumiose City | G27: =K4 -> 17.028751 | H27: =M9-G9 -> 17 | I27: =IF(ROUNDDOWN(J13/100, 0)>2, -G27, 0) -> 0 | J27: =IF(AND(G27>0, H27>0, G27>H27), H27/G27, IF(AND(G27<0, H27<0, H27>G27), 3*(1-(H27/G27)), IF(AND(G27<0, H27<G27), -(H27/G27), IF(AND(G27>0, H27>0, H27>G27), 1+(H27/G27), IF(AND(G27<0, H27>0), -G27+(0.5*(H27+G27)), IF(AND(G27>0, H27<0), -G27+(0.25*H27), 0))))))/1.5 -> 0.66554107 | K27: =SUM(P182:S187) -> 16 | L27: =IFERROR(Cards!CC2*3,0) -> 1.5416873 | M27: =IFERROR(Cards!BQ2*2,0) -> 1.7578947 | N27: =IFERROR(IF(Cards!BO1<0, -Cards!BO1, 0),0) -> 6.5684211 | O27: =IF(AND(H27>0,(H27-G27)>0), IF((COUNT(P182:S187)-COUNT(C182:F187))<0, (COUNT(P182:S187)-COUNT(C182:F187))*-1, (COUNT(P182:S187)-COUNT(C182:F187))*0.25), 0) -> 0 | P27: =IFERROR(SUM(P190:S195)/COUNT(P182:S187),0) -> 1.8 | Q27: =IFERROR((M9/G9)*(C3+1), M9*(C3+1)) -> 3.5042606 | R27: =IFERROR(IF(((SUM(I27:P27)-IF(J27>M9,J27-M9,0)+IF(J27<-G9,-G9-J27, 0))*Q27)<0, 0, ((SUM(I27:P27)-IF(J27>M9,J27-M9,0)+IF(J27<-G9,-G9-J27, 0))*Q27)),0) -> 99.288123 | T27: 0 | W27: Avg Led By
W28: ToP
G29: FIRST HALF | I29: SECOND HALF | K29: FIRST OVERTIME | M29: SECOND OVERTIME | O29: THIRD OVERTIME | Q29: FOURTH OVERTIME | S29: FIFTH OVERTIME
A30: Regulation | B30: 1 | C30: =IF($J$13=100, RAND(), "") | D30: =IF($J$13=100, RAND(), "") | E30: =IFERROR(RANK(C30, $C$30:$D$55),"") | F30: =IFERROR(RANK(D30, $C$30:$D$55),"") | G30: 52 | H30: 38 | I30: 51 | J30: 16 | W30: 1
B31: 2 | C31: =IF($J$13=100, RAND(), "") | D31: =IF($J$13=100, RAND(), "") | E31: =IFERROR(RANK(C31, $C$30:$D$55),"") | F31: =IFERROR(RANK(D31, $C$30:$D$55),"") | G31: 17 | H31: 23 | I31: 37 | J31: 47 | W31: 1
B32: 3 | C32: =IF($J$13=100, RAND(), "") | D32: =IF($J$13=100, RAND(), "") | E32: =IFERROR(RANK(C32, $C$30:$D$55),"") | F32: =IFERROR(RANK(D32, $C$30:$D$55),"") | G32: 9 | H32: 16 | I32: 19 | J32: 1 | W32: 1
B33: 4 | C33: =IF($J$13=100, RAND(), "") | D33: =IF($J$13=100, RAND(), "") | E33: =IFERROR(RANK(C33, $C$30:$D$55),"") | F33: =IFERROR(RANK(D33, $C$30:$D$55),"") | G33: 28 | H33: 40 | I33: 36 | J33: 43 | W33: 1
B34: 5 | C34: =IF($J$13=100, RAND(), "") | D34: =IF($J$13=100, RAND(), "") | E34: =IFERROR(RANK(C34, $C$30:$D$55),"") | F34: =IFERROR(RANK(D34, $C$30:$D$55),"") | G34: 26 | H34: 25 | I34: 45 | J34: 13 | W34: 1
B35: 6 | C35: =IF($J$13=100, RAND(), "") | D35: =IF($J$13=100, RAND(), "") | E35: =IFERROR(RANK(C35, $C$30:$D$55),"") | F35: =IFERROR(RANK(D35, $C$30:$D$55),"") | G35: 45 | H35: 39 | I35: 33 | J35: 21 | W35: 1
B36: 7 | C36: =IF($J$13=100, RAND(), "") | D36: =IF($J$13=100, RAND(), "") | E36: =IFERROR(RANK(C36, $C$30:$D$55),"") | F36: =IFERROR(RANK(D36, $C$30:$D$55),"") | G36: 8 | H36: 31 | I36: 46 | J36: 11 | W36: 1
B37: 8 | C37: =IF($J$13=100, RAND(), "") | D37: =IF($J$13=100, RAND(), "") | E37: =IFERROR(RANK(C37, $C$30:$D$55),"") | F37: =IFERROR(RANK(D37, $C$30:$D$55),"") | G37: 27 | H37: 13 | I37: 44 | J37: 7 | W37: 1
B38: 9 | C38: =IF($J$13=100, RAND(), "") | D38: =IF($J$13=100, RAND(), "") | E38: =IFERROR(RANK(C38, $C$30:$D$55),"") | F38: =IFERROR(RANK(D38, $C$30:$D$55),"") | G38: 33 | H38: 6 | I38: 6 | J38: 18 | W38: 1
B39: 10 | C39: =IF($J$13=100, RAND(), "") | D39: =IF($J$13=100, RAND(), "") | E39: =IFERROR(RANK(C39, $C$30:$D$55),"") | F39: =IFERROR(RANK(D39, $C$30:$D$55),"") | G39: 49 | H39: 4 | I39: 14 | J39: 41 | W39: 1
B40: 11 | C40: =IF($J$13=100, RAND(), "") | D40: =IF($J$13=100, RAND(), "") | E40: =IFERROR(RANK(C40, $C$30:$D$55),"") | F40: =IFERROR(RANK(D40, $C$30:$D$55),"") | G40: 7 | H40: 37 | I40: 40 | J40: 27 | W40: 1
B41: 12 | C41: =IF($J$13=100, RAND(), "") | D41: =IF($J$13=100, RAND(), "") | E41: =IFERROR(RANK(C41, $C$30:$D$55),"") | F41: =IFERROR(RANK(D41, $C$30:$D$55),"") | G41: 30 | H41: 3 | I41: 31 | J41: 22 | W41: 1
...

Sheet Archive
B1: =IF(AutoScoreboard!I195="W", AutoScoreboard!J195, AutoScoreboard!J196) -> HW!109+36-19^10(17.03)[90]{99.5}2312 | C1: =IF(AutoScoreboard!H26>0, AutoScoreboard!G26, AutoScoreboard!G27) -> 17.028751 | D1: =AutoScoreboard!G20 -> 9 | E1: =AutoScoreboard!K5 -> 89.526493 | F1: =IF(AutoScoreboard!H26>0, "A", "H") -> H | G1: =IF(AutoScoreboard!H26>0, AutoScoreboard!J4, AutoScoreboard!L4) -> 1 | H1: =IF(AutoScoreboard!H26>0, AutoScoreboard!C4, AutoScoreboard!M4) -> Lumiose City | I1: =IF(AutoScoreboard!H26>0, AutoScoreboard!G9, AutoScoreboard!M9) -> 36 | J1: =IF(AutoScoreboard!H26>0, AutoScoreboard!M9, AutoScoreboard!G9) -> 19 | K1: =IF(AutoScoreboard!H26>0, AutoScoreboard!M4, AutoScoreboard!C4) -> Hulbury | L1: =IF(AutoScoreboard!H26>0, AutoScoreboard!L4, AutoScoreboard!J4) -> 10 | M1: =IF(AutoScoreboard!H26>0, CONCATENATE("[", AutoScoreboard!M178, "-", AutoScoreboard!N178, "]"), CONCATENATE("[", AutoScoreboard!N178, "-", AutoScoreboard!M178, "]")) -> [10-10] | N1: =IF(AutoScoreboard!H26>0,CONCATENATE("{",ROUND(AutoScoreboard!I7,1),"-",ROUND(AutoScoreboard!M7,1),"}"),CONCATENATE("{",ROUND(AutoScoreboard!M7,1),"-",ROUND(AutoScoreboard!I7,1),"}")) -> {99.5-19.3} | O1: =IF(MAX(AutoScoreboard!I7,AutoScoreboard!M7)>100, "MAX", IF(AutoScoreboard!H26>0, IF(AutoScoreboard!M7>AutoScoreboard!I7, "INVT", ""), IF(AutoScoreboard!I7>AutoScoreboard!M7, "INVT", ""))) | P1: CONCATENATE(H, " leads ", I, "-", J) | Q1: =IF(AutoScoreboard!I195="L", AutoScoreboard!J195, AutoScoreboard!J196) -> AL!72+19-36^10(-17.03)[90]{19.3}2073
A2: D1 8/14 | B2: Matchday One (Sat) | C2: 7.4959961 | D2: 11 | E2: 22.571369 | F2: A | G2: 64 | H2: Oreburgh City | I2: 26 | J2: 13 | K2: Canalave City | L2: 128 | M2: [11-5] | N2: {72.8-16.9}
C3: 11.414909 | D3: 19 | E3: 40.94108 | F3: H | G3: 38 | H3: Gateon Port | I3: 36 | J3: 12 | K3: Ringtown | L3: 126 | M3: [8-7] | N3: {105.8-12.9} | O3: MAX | P3: Phoenix Conference debut
C4: 1.0434648 | D4: 13 | E4: -3.9534332 | F4: H | G4: 125 | H4: Dendemille Town | I4: 26 | J4: 18 | K4: Santalune City | L4: 123 | M4: [12-9] | N4: {59.9-16.7} | P4: First ever negative game rating
A5: D2 8/15 | C5: 5.3122666 | D5: 8 | E5: 6.3373923 | F5: H | G5: 92 | H5: Crown Tundra | I5: 21 | J5: 13 | K5: Isle of Armor | L5: 124 | M5: [9-8] | N5: {51.4-21.5}
C6: 10.022209 | D6: 21 | E6: 46.397879 | F6: A | G6: 17 | H6: Aqua Resort | I6: 32 | J6: 15 | K6: Pueltown | L6: 122 | M6: [8-7] | N6: {88-15.2}
C7: 1.9901923 | D7: 15 | E7: 8.9762484 | F7: A | G7: 94 | H7: Azalea Town | I7: 35 | J7: 20 | K7: Ecruteak City | L7: 121 | M7: [13-9] | N7: {99-19.5}
C8: 4.0880599 | D8: 12 | E8: 10.475361 | F8: H | G8: 88 | H8: Seafolk Village | I8: 32 | J8: 13 | K8: Hau'oli City | L8: 120 | M8: [12-9] | N8: {108.5-8.3} | O8: MAX
C9: -2.2892498 | D9: 12 | E9: 16.731048 | F9: H | G9: 119 | H9: Viridian City | I9: 21 | J9: 17 | K9: Cerulean City | L9: 84 | M9: [13-4] | N9: {41.6-30.7} | P9: Viridian: GW 4pt! @ 55:00
C10: 8.6171013 | D10: 8 | E10: 37.02242 | F10: A | G10: 34 | H10: Ultra Megalopolis | I10: 19 | J10: 14 | K10: Vast Poni Canyon | L10: 118 | M10: [4-7] | N10: {51.6-33.1}
C11: -1.703801 | D11: 14 | E11: 4.8796073 | F11: A | G11: 115 | H11: Verdanturf Town | I11: 19 | J11: 18 | K11: Petalburg City | L11: 116 | M11: [12-9] | N11: {30.6-34.1} | O11: INVT | P11: Verdanturf: GW 1pt+1 @ 61:10
C12: 3.4913331 | D12: 7 | E12: 18.390117 | F12: A | G12: 76 | H12: Saffron City | I12: 23 | J12: 19 | K12: Pewter City | L12: 114 | M12: [9-11] | N12: {48.2-27.9}
C13: 1.9376096 | D13: 12 | E13: 6.9975837 | F13: H | G13: 107 | H13: Fight Area | I13: 25 | J13: 20 | K13: Hearthome City | L13: 113 | M13: [11-9] | N13: {57.3-20}
C14: 4.8901478 | D14: 9 | E14: 17.573235 | F14: H | G14: 78 | H14: Oldale Town | I14: 13 | J14: 8 | K14: Lavaridge Town | L14: 112 | M14: [5-6] | N14: {52.4-16.4}
C15: 4.6999066 | D15: 14 | E15: 33.899312 | F15: A | G15: 56 | H15: Lilycove City | I15: 29 | J15: 16 | K15: Mossdeep City | L15: 111 | M15: [12-8] | N15: {82.6-14.5}
C16: 4.547775 | D16: 11 | E16: 20.402991 | F16: H | G16: 74 | H16: Tapu Village | I16: 26 | J16: 16 | K16: Konikoni City | L16: 110 | M16: [12-11] | N16: {86.7-25.4}
C17: -0.88287991 | D17: 13 | E17: 19.656477 | F17: H | G17: 109 | H17: Stow-on-Side | I17: 16 | J17: 10 | K17: Circhester Bay | L17: 85 | M17: [8-4] | N17: {62.1-15.6}
C18: 2.1524544 | D18: 10 | E18: 37.081011 | F18: H | G18: 68 | H18: Vientown | I18: 12 | J18: 10 | K18: Tilt Village | L18: 80 | M18: [6-7] | N18: {35.2-21.9} | P18: jump to 80
C19: 4.9102456 | D19: 9 | E19: 50.728768 | F19: H | G19: 45 | H19: Anville Town | I19: 20 | J19: 13 | K19: Icirrus City | L19: 79 | M19: [9-7] | N19: {57.2-20.1}
C20: 3.3985468 | D20: 11 | E20: 46.211924 | F20: H | G20: 61 | H20: Accumula Town | I20: 19 | J20: 11 | K20: Opelucid City | L20: 77 | M20: [12-9] | N20: {68.1-17.9}
C21: -6.7401436 | D21: 14 | E21: 72.15288 | F21: A | G21: 75 | H21: Cocona Village | I21: 25 | J21: 22 | K21: Haruba Village | L21: 22 | M21: [12-6] | N21: {81.9-21.3} | P21: Cocona: GW 2pt+1 @ 55:20
A22: D3 8/16 | C22: 2.443103 | D22: 13 | E22: 58.438403 | F22: A | G22: 36 | H22: Floaroma City | I22: 19 | J22: 15 | K22: Jubilife City | L22: 72 | M22: [7-9] | N22: {55.9-36.6}
C23: -2.0456759 | D23: 17 | E23: 38.597104 | F23: A | G23: 81 | H23: Aquacorde Town | I23: 19 | J23: 9 | K23: Snowbelle City | L23: 71 | M23: [9-4] | N23: {100.3-5.6} | O23: MAX
C24: 3.1249536 | D24: 10 | E24: 66.560556 | F24: A | G24: 27 | H24: Snowpoint City | I24: 23 | J24: 22 | K24: Sandgem Town | L24: 70 | M24: [9-12] | N24: {38.3-40.1} | O24: INVT | P24: Snowpoint: GW 1pt @ 58:50
C25: 3.5589893 | D25: 9 | E25: 55.592387 | F25: H | G25: 46 | H25: Floccesy Town | I25: 20 | J25: 12 | K25: Nimbasa City | L25: 69 | M25: [11-6] | N25: {61.2-30.8}
C26: 4.8464537 | D26: 7 | E26: 32.722102 | F26: H | G26: 67 | H26: Mistralton City | I26: 17 | J26: 16 | K26: Driftveil City | L26: 89 | M26: [8-7] | N26: {35.8-31.1}
C27: 0.28952858 | D27: 10 | E27: 59.616452 | F27: H | G27: 66 | H27: Mount Hokulani | I27: 21 | J27: 14 | K27: Paniola Town | L27: 50 | M27: [13-6] | N27: {96.6-0} | P27: OT - 14[9-6]
C28: 0.62259632 | D28: 13 | E28: 56.608734 | F28: A | G28: 54 | H28: Coumarine City | I28: 16 | J28: 12 | K28: Ambrette Town | L28: 65 | M28: [9-7] | N28: {43.5-11.5} | P28: Coumarine: GW 4pt! @ 56:40
C29: -6.3081687 | D29: 20 | E29: 78.491609 | F29: A | G29: 63 | H29: Heahea City | I29: 21 | J29: 14 | K29: Malie City | L29: 21 | M29: [12-5] | N29: {66.5-7.1}
C30: -3.7116903 | D30: 16 | E30: 77.99897 | F30: H | G30: 59 | H30: Nacrene City | I30: 21 | J30: 18 | K30: Humilau City | L30: 20 | M30: [12-7] | N30: {49.2-17.6}
C31: 4.8617422 | D31: 10 | E31: 44.7967 | F31: H | G31: 55 | H31: Striaton City | I31: 25 | J31: 14 | K31: Lacunosa Town | L31: 87 | M31: [14-7] | N31: {101.1-11.9} | O31: MAX
C32: -5.6952756 | D32: 17 | E32: 46.786244 | F32: A | G32: 102 | H32: Kiloude City | I32: 21 | J32: 17 | K32: Anistar City | L32: 53 | M32: [11-5] | N32: {62.6-17.3}
C33: 3.4804404 | D33: 10 | E33: 76.547026 | F33: A | G33: 18 | H33: Violet City | I33: 15 | J33: 14 | K33: Goldenrod City | L33: 52 | M33: [8-8] | N33: {32.3-36.2} | O33: INVT
A34: D4 8/17 | B34: Matchday One (Sun) | C34: 2.6262248 | D34: 13 | E34: 12.385304 | F34: H | G34: 97 | H34: Ballonlea | I34: 23 | J34: 10 | K34: City of Circhester | L34: 108 | M34: [13-5] | N34: {100.1-13.3} | O34: MAX | P34: jump back
C35: 6.7137419 | D35: 10 | E35: 36.457742 | F35: H | G35: 49 | H35: Cyllage City | I35: 30 | J35: 15 | K35: Camphrier Town | L35: 105 | M35: [11-8] | N35: {90.7-27.6}
C36: -6.0097243 | D36: 17 | E36: 47.778788 | F36: H | G36: 104 | H36: Exeggutor Island | I36: 24 | J36: 17 | K36: Iki Town | L36: 42 | M36: [11-6] | N36: {78.8-12.3}
C37: -10.080826 | D37: 23 | E37: 62.465039 | F37: A | G37: 103 | H37: Turffield | I37: 24 | J37: 17 | K37: Postwick | L37: 23 | M37: [15-5] | N37: {66.7-10.2}
A38: D5 8/22 | C38: -1.384003 | D38: 15 | E38: 16.829215 | F38: A | G38: 100 | H38: Aether Paradise | I38: 15 | J38: 7 | K38: Po Town | L38: 101 | M38: [8-3] | N38: {85.4-11.2}
C39: 8.0684749 | D39: 17 | E39: 51.895263 | F39: H | G39: 26 | H39: Pyrite Town | I39: 32 | J39: 13 | K39: Wintown | L39: 99 | M39: [8-9] | N39: {103.6-15} | O39: MAX
C40: -5.9655316 | D40: 20 | E40: 62.697481 | F40: H | G40: 91 | H40: Sunyshore City | I40: 22 | J40: 15 | K40: Celestic Town | L40: 29 | M40: [13-5] | N40: {88.9-12.6}
...

Sheet Rankings
A1: DEX | B1: =Archive!B1 -> HW!109+36-19^10(17.03)[90]{99.5}2312 | C1: =Archive!Q1 -> AL!72+19-36^10(-17.03)[90]{19.3}2073 | D1: GmCde | E1: =ROUNDDOWN((128-COUNTIF(D:D, "-"))/2, 0) -> 0 | F1: SeW | G1: SeL | I1: CfW | J1: CfL | L1: ExW | M1: ExL | O1: PF | P1: PA | Q1: PD | R1: GLS | S1: SOS | T1: SPRD | U1: EXP | V1: DSCR | X1: Gms | Y1: STR | Z1: StrMod | AA1: VicAvg | AB1: ExAv | AC1: D-Avg | AD1: EXP | AE1: D-Sqrt | AG1: M/U | AH1: WCS | AI1: CC | AJ1: PO | AK1: Bonus | AL1: TOT | AN1: Rank | AO1: PR | AP1: RkCh | AQ1: TOTAL | AR1: Wins | AS1: CfW | AT1: PF | AU1: PA | AV1: GlAv | AW1: SOS | AX1: SOV | AY1: EYE | AZ1: DSCR | BA1: ELO | BB1: Cups | BC1: EX | BE1: Fatig | BF1: Climate | BG1: CfStr | BH1: PF | BI1: PA | BJ1: =AVERAGE(BJ2:BJ129) -> 6.5011206 | BK1: =AVERAGE(BK2:BK129) -> 0.51705232 | BL1: ELO | BN1: Sqrt | BO1: Grade | BP1: <avg< | BR1: WCS Seed | BS1: WCS Reg | BT1: MRL/UTL | BU1: M/U Grp | BV1: M/U Rnk | BW1: Accolade | BX1: Accolade | CA1: Team Name | CB1: W25 F | CC1: W24 | CD1: W23 | CE1: W22 | CF1: W21 | CG1: MW21 | CH1: W20 | CI1: W19 | CJ1: W18 | CK1: W17 | CL1: W16 | CM1: MW16 | CN1: W15 | CO1: MW15 | CP1: W14 | CQ1: MW14 | CR1: W13 | CS1: MW13 | CT1: W12 | CU1: MW12 | CV1: W11 | CW1: MW11 | CX1: W10 | CY1: MW10 | CZ1: W9 | DA1: MW9 | DB1: W8 | DC1: W7 | DD1: MW7 | DE1: W6 | DF1: MW5 | DG1: W5 | DH1: MW5 | DI1: W4 | DJ1: MW4 | DK1: W3 | DL1: W2 | DM1: W1 | DN1: Start
A2: 72 | B2: Kalosite | C2: Lumiose City | D2: - | E2: 1 | F2: =VLOOKUP($A2, Calcs!$A$3:'Calcs'!$ALW$130, 95, FALSE)+VLOOKUP($A2, Calcs!$A$3:'Calcs'!$ALW$130, 97, FALSE) -> 11 | G2: =VLOOKUP($A2, Calcs!$A$3:'Calcs'!$ALW$130, 96, FALSE)+VLOOKUP($A2, Calcs!$A$3:'Calcs'!$ALW$130, 98, FALSE) -> 1 | H2: * | I2: =VLOOKUP($A2, Calcs!$A$3:'Calcs'!$ALW$130, 99, FALSE)+VLOOKUP($A2, Calcs!$A$3:'Calcs'!$ALW$130, 101, FALSE) -> 8 | J2: =VLOOKUP($A2, Calcs!$A$3:'Calcs'!$ALW$130, 100, FALSE)+VLOOKUP($A2, Calcs!$A$3:'Calcs'!$ALW$130, 102, FALSE) -> 1 | L2: =VLOOKUP($A2, Calcs!$A$3:'Calcs'!$ALW$130, 119, FALSE) -> 32 | M2: =VLOOKUP($A2, Calcs!$A$3:'Calcs'!$ALW$130, 120, FALSE) -> 5 | N2: M | O2: =VLOOKUP($A2, Calcs!$A$3:'Calcs'!$ALW$130, 302, FALSE)/X2 -> 20.677778 | P2: =VLOOKUP($A2, Calcs!$A$3:'Calcs'!$ALW$130, 394, FALSE)/X2 -> 11.844444 | Q2: =O2-P2 -> 8.8333333 | R2: =O2/(VLOOKUP($A2,Calcs!$A$3:'Calcs'!$ALW$130,485,FALSE)/X2) -> 2.9010133 | S2: =VLOOKUP($A2, Calcs!$A$3:'Calcs'!$ALW$130, 210, FALSE)/X2 -> 0.66473541 | T2: =VLOOKUP($A2, Calcs!$A$3:'Calcs'!$ALW$130, 576, FALSE)/X2 -> 6.8290556 | U2: =VLOOKUP($A2, Calcs!$A$3:'Calcs'!$ALW$130, 667, FALSE)/X2 -> 65.25 | V2: =VLOOKUP($A2, Calcs!$A$3:'Calcs'!$ALW$130, 758, FALSE)/X2 -> 56.672222 | X2: =VLOOKUP($A2, Calcs!$A$3:'Calcs'!$ALW$130, 9, FALSE) -> 30 | Y2: =-(T2-MAX(T:T))*S2 -> 0.67319135 | Z2: =(S2)*(BG2) -> 0.67910287 | AA2: =Q2-T2 -> 2.0042778 | AB2: =U2 -> 65.25 | AC2: =V2 -> 56.672222 | AD2: =IFERROR((AVERAGE((Q2-MIN(Q:Q))*AB2, SQRT((Q2-MIN(Q:Q))*AB2))/100)*BG2, 0) -> 8.9414523 | AE2: =IFERROR(IF(SQRT(AC2)>10, 10, SQRT(AC2)), 0) -> 7.5280955 | AG2: 48 | AH2: 80 | AI2: 55 | AJ2: 150 | AL2: =SUM(AG2:AJ2) -> 333 | AN2: 1 | AO2: =_xlfn.RANK.EQ(AQ2,AQ:AQ, 0) -> 1 | AP2: =AN2-AO2 -> 0 | AQ2: =((AR2*2.4)+(AS2*1.6)+(AT2*1)+(AU2*1)+(AV2*0.75)+(AW2*1)+(AX2*1)+(AY2*0.75)+(AZ2*1)+(BA2*0.75)+(BB2*0.75)+(BC2/LARGE(BC:BC,1))*(0/12))/(11+(20/24)) -> 0.99743601 | AR2: =IFERROR(IF((F2+G2)=1, IF(F2=0, 0.333, IF(F2=1, 0.666, 0)), IF((F2+G2)=2, IF(F2=0, 0.166, IF(F2=1, 0.5, IF(F2=2, 0.833, 0))), (F2+(L2/6))/(F2+G2))), 0) -> 1.3611111 | AS2: =IFERROR(IF((I2+J2)=1, IF(I2=0, 0.333, IF(I2=1, 0.666, 0)), IF((I2+J2)=2, IF(I2=0, 0.166, IF(I2=1, 0.5, IF(I2=2, 0.833, 0))), (I2/(I2+J2)))), 0) -> 0.88888889 | AT2: =(O2-(SMALL(O:O, 1)))/((LARGE(O:O, 1))-(SMALL(O:O, 1))) -> 0.85883385 | AU2: =1-(P2-(SMALL(P:P, 1)))/((LARGE(P:P, 1))-(SMALL(P:P, 1))) -> 0.95279593 | AV2: =(R2-(SMALL(R:R, 1)))/((LARGE(R:R, 1))-(SMALL(R:R, 1))) -> 0.90873632 | AW2: =(Z2-(SMALL(Z:Z, 1)))/((LARGE(Z:Z, 1))-(SMALL(Z:Z, 1))) -> 0.91495722 | AX2: =(AA2+ABS(MIN(AA:AA)))/(MAX(AA:AA)+ABS(MIN(AA:AA))) -> 0.77322969 | AY2: =AVERAGE(AD2/MAX(AD:AD), SQRT(AD2/MAX(AD:AD))) -> 0.90335216 | AZ2: =AVERAGE(AE2/MAX(AE:AE), (AE2-SMALL(AE:AE,1))/(LARGE(AE:AE,1)-SMALL(AE:AE,1))) -> 0.75522085 | BA2: =(BL2-MIN($BL$2:$BL$129))/(MAX($BL$2:$BL$129)-MIN($BL$2:$BL$129)) -> 1 | BB2: =IFERROR(AL2/MAX(AL:AL), 0) -> 1 | BC2: 370 | BE2: =VLOOKUP($A2, Calcs!$A$3:'Calcs'!$ALW$130, 845, FALSE) -> 115 | BF2: 0.33333333 | BG2: =IF(A2<17, SoC!P$3, IF(A2<33, SoC!P$4, IF(A2<49, SoC!P$5, IF(A2<65, SoC!P$6, IF(A2<81, SoC!P$7, IF(A2<97, SoC!P$8, SoC!P$9)))))) -> 1.0216138 | BH2: 0.85883385 | BI2: 0.95279593 | BJ2: 7.5280955 | BK2: 0.99722768 | BL2: =VLOOKUP($A2, Calcs!$A$3:'Calcs'!$BAA$130, 1025, FALSE) -> 2303 | BM2: 11.5 | BN2: =SQRT(BK2) -> 0.99861288 | BO2: =IF(BN2<(15/30), "F", IF(BN2<(18/30), "F+", IF(BN2<(19/30), "D-", IF(BN2<(20/30), "D", IF(BN2<(21/30), "D+", IF(BN2<(22/30), "C-", IF(BN2<(23/30), "C", IF(BN2<(24/30), "C+", IF(BN2<(25/30), "B-", IF(BN2<(26/30), "B", IF(BN2<(27/30), "B+", IF(BN2<(28/30), "A-", IF(BN2<(29/30), "A", "A+"))))))))))))) -> A+ | BP2: =(((BK2-$BK$1)/0.15)*3)+((BJ2-$BJ$1)/2) -> 10.116995 | BQ2: B | BR2: #1 | BS2: =IF(BQ2="A","Platinum",IF(BQ2="B","Prism",IF(BQ2="C","Hakuna",IF(BQ2="D","Wild",IF(BQ2="E","Crystal",IF(BQ2="F","Gray",IF(BQ2="G","Emerald",IF(BQ2="H","Mystery")))))))) -> Prism | BT2: MRL | BU2: A | BV2: =IF(BT2="MRL", VLOOKUP(C2, Master!BL:BP, 5, FALSE), IF(BT2="UTL", VLOOKUP(C2, Ultra!BL:BP, 5, FALSE), "")) -> 1 | BW2: S4 Kalosite Champion | BX2: S4 WCS Champion | BY2: =MATCH(A2, Standings!$X$3:$X$18, 0) -> 2 | BZ2: 0.95589642 | CA2: Lumiose City | CB2: 1 | CC2: 1 | CD2: 1 | CE2: 1 | CF2: 1 | CG2: 1 | CH2: 1 | CI2: 1 | CJ2: 1 | CK2: 1 | CL2: 1 | CM2: 1 | CN2: 1 | CO2: 1 | CP2: 1 | CQ2: 1 | CR2: 1 | CS2: 1 | CT2: 1 | CU2: 1 | CV2: 1 | CW2: 1 | CX2: 2 | CY2: 2 | CZ2: 2 | DA2: 3 | DB2: 3 | DC2: 3 | DD2: 3 | DE2: 3 | DF2: 4 | DG2: 4 | DH2: 6 | DI2: 6 | DJ2: 10 | DK2: 10 | DL2: 12 | DM2: 2 | DN2: 2
A3: 42 | B3: Lily Valley | C3: Resort Area | D3: - | E3: 2 | F3: =VLOOKUP($A3, Calcs!$A$3:'Calcs'!$ALW$130, 95, FALSE)+VLOOKUP($A3, Calcs!$A$3:'Calcs'!$ALW$130, 97, FALSE) -> 12 | G3: =VLOOKUP($A3, Calcs!$A$3:'Calcs'!$ALW$130, 96, FALSE)+VLOOKUP($A3, Calcs!$A$3:'Calcs'!$ALW$130, 98, FALSE) -> 0 | H3: * | I3: =VLOOKUP($A3, Calcs!$A$3:'Calcs'!$ALW$130, 99, FALSE)+VLOOKUP($A3, Calcs!$A$3:'Calcs'!$ALW$130, 101, FALSE) -> 9 | J3: =VLOOKUP($A3, Calcs!$A$3:'Calcs'!$ALW$130, 100, FALSE)+VLOOKUP($A3, Calcs!$A$3:'Calcs'!$ALW$130, 102, FALSE) -> 0 | L3: =VLOOKUP($A3, Calcs!$A$3:'Calcs'!$ALW$130, 119, FALSE) -> 20 | M3: =VLOOKUP($A3, Calcs!$A$3:'Calcs'!$ALW$130, 120, FALSE) -> 8 | N3: M | O3: =VLOOKUP($A3, Calcs!$A$3:'Calcs'!$ALW$130, 302, FALSE)/X3 -> 21.513158 | P3: =VLOOKUP($A3, Calcs!$A$3:'Calcs'!$ALW$130, 394, FALSE)/X3 -> 12.710526 | Q3: =O3-P3 -> 8.8026316 | R3: =O3/(VLOOKUP($A3,Calcs!$A$3:'Calcs'!$ALW$130,485,FALSE)/X3) -> 2.9118433 | S3: =VLOOKUP($A3, Calcs!$A$3:'Calcs'!$ALW$130, 210, FALSE)/X3 -> 0.65438847 | T3: =VLOOKUP($A3, Calcs!$A$3:'Calcs'!$ALW$130, 576, FALSE)/X3 -> 7.8417763 | U3: =VLOOKUP($A3, Calcs!$A$3:'Calcs'!$ALW$130, 667, FALSE)/X3 -> 68.184211 | V3: =VLOOKUP($A3, Calcs!$A$3:'Calcs'!$ALW$130, 758, FALSE)/X3 -> 59.393421 | X3: =VLOOKUP($A3, Calcs!$A$3:'Calcs'!$ALW$130, 9, FALSE) -> 25.333333 | Y3: =-(T3-MAX(T:T))*S3 -> 0 | Z3: =(S3)*(BG3) -> 0.63706474 | AA3: =Q3-T3 -> 0.96085526 | AB3: =U3 -> 68.184211 | AC3: =V3 -> 59.393421 | AD3: =IFERROR((AVERAGE((Q3-MIN(Q:Q))*AB3, SQRT((Q3-MIN(Q:Q))*AB3))/100)*BG3, 0) -> 8.8888567 | AE3: =IFERROR(IF(SQRT(AC3)>10, 10, SQRT(AC3)), 0) -> 7.7067127 | AG3: 36 | AH3: 60 | AI3: 60 | AJ3: 80 | AL3: =SUM(AG3:AJ3) -> 236 | AN3: 2 | AO3: =_xlfn.RANK.EQ(AQ3,AQ:AQ, 0) -> 2 | AP3: =AN3-AO3 -> 0 | AQ3: =((AR3*2.4)+(AS3*1.6)+(AT3*1)+(AU3*1)+(AV3*0.75)+(AW3*1)+(AX3*1)+(AY3*0.75)+(AZ3*1)+(BA3*0.75)+(BB3*0.75)+(BC3/LARGE(BC:BC,1))*(0/12))/(11+(20/24)) -> 0.95125388 | AR3: =IFERROR(IF((F3+G3)=1, IF(F3=0, 0.333, IF(F3=1, 0.666, 0)), IF((F3+G3)=2, IF(F3=0, 0.166, IF(F3=1, 0.5, IF(F3=2, 0.833, 0))), (F3+(L3/6))/(F3+G3))), 0) -> 1.2777778 | AS3: =IFERROR(IF((I3+J3)=1, IF(I3=0, 0.333, IF(I3=1, 0.666, 0)), IF((I3+J3)=2, IF(I3=0, 0.166, IF(I3=1, 0.5, IF(I3=2, 0.833, 0))), (I3/(I3+J3)))), 0) -> 1 | AT3: =(O3-(SMALL(O:O, 1)))/((LARGE(O:O, 1))-(SMALL(O:O, 1))) -> 0.92478967 | AU3: =1-(P3-(SMALL(P:P, 1)))/((LARGE(P:P, 1))-(SMALL(P:P, 1))) -> 0.90133533 | AV3: =(R3-(SMALL(R:R, 1)))/((LARGE(R:R, 1))-(SMALL(R:R, 1))) -> 0.91659299 | AW3: =(Z3-(SMALL(Z:Z, 1)))/((LARGE(Z:Z, 1))-(SMALL(Z:Z, 1))) -> 0.77787687 | AX3: =(AA3+ABS(MIN(AA:AA)))/(MAX(AA:AA)+ABS(MIN(AA:AA))) -> 0.69571098 | AY3: =AVERAGE(AD3/MAX(AD:AD), SQRT(AD3/MAX(AD:AD))) -> 0.89941009 | AZ3: =AVERAGE(AE3/MAX(AE:AE), (AE3-SMALL(AE:AE,1))/(LARGE(AE:AE,1)-SMALL(AE:AE,1))) -> 0.78034254 | BA3: =(BL3-MIN($BL$2:$BL$129))/(MAX($BL$2:$BL$129)-MIN($BL$2:$BL$129)) -> 0.82166446 | BB3: =IFERROR(AL3/MAX(AL:AL), 0) -> 0.70870871 | BC3: 356 | BE3: =VLOOKUP($A3, Calcs!$A$3:'Calcs'!$ALW$130, 845, FALSE) -> 100.375 | BF3: 0.66666667 | BG3: =IF(A3<17, SoC!P$3, IF(A3<33, SoC!P$4, IF(A3<49, SoC!P$5, IF(A3<65, SoC!P$6, IF(A3<81, SoC!P$7, IF(A3<97, SoC!P$8, SoC!P$9)))))) -> 0.97352684 | BH3: 0.92478967 | BI3: 0.90133533 | BJ3: 7.7067127 | BK3: 0.95123167 | BL3: =VLOOKUP($A3, Calcs!$A$3:'Calcs'!$BAA$130, 1025, FALSE) -> 2168 | BM3: 10 | BN3: =SQRT(BK3) -> 0.97531106 | BO3: =IF(BN3<(15/30), "F", IF(BN3<(18/30), "F+", IF(BN3<(19/30), "D-", IF(BN3<(20/30), "D", IF(BN3<(21/30), "D+", IF(BN3<(22/30), "C-", IF(BN3<(23/30), "C", IF(BN3<(24/30), "C+", IF(BN3<(25/30), "B-", IF(BN3<(26/30), "B", IF(BN3<(27/30), "B+", IF(BN3<(28/30), "A-", IF(BN3<(29/30), "A", "A+"))))))))))))) -> A+ | BP3: =(((BK3-$BK$1)/0.15)*3)+((BJ3-$BJ$1)/2) -> 9.2863829 | BQ3: A | BR3: #1 | BS3: =IF(BQ3="A","Platinum",IF(BQ3="B","Prism",IF(BQ3="C","Hakuna",IF(BQ3="D","Wild",IF(BQ3="E","Crystal",IF(BQ3="F","Gray",IF(BQ3="G","Emerald",IF(BQ3="H","Mystery")))))))) -> Platinum | BT3: MRL | BU3: C | BV3: =IF(BT3="MRL", VLOOKUP(C3, Master!BL:BP, 5, FALSE), IF(BT3="UTL", VLOOKUP(C3, Ultra!BL:BP, 5, FALSE), "")) -> 1 | BW3: S4 Lily Valley Champ | BX3: S3 World Champion | BY3: =MATCH(A3, Standings!$N$3:$N$18, 0) -> 1 | BZ3: 0.94989296 | CA3: Resort Area | CB3: 2 | CC3: 2 | CD3: 2 | CE3: 2 | CF3: 2 | CG3: 2 | CH3: 2 | CI3: 2 | CJ3: 2 | CK3: 2 | CL3: 2 | CM3: 2 | CN3: 2 | CO3: 2 | CP3: 2 | CQ3: 2 | CR3: 2 | CS3: 2 | CT3: 2 | CU3: 2 | CV3: 2 | CW3: 2 | CX3: 1 | CY3: 1 | CZ3: 1 | DA3: 1 | DB3: 2 | DC3: 1 | DD3: 1 | DE3: 1 | DF3: 2 | DG3: 2 | DH3: 4 | DI3: 5 | DJ3: 4 | DK3: 5 | DL3: 1 | DM3: 3 | DN3: 3
A4: 48 | B4: Lily Valley | C4: Solaceon Town | D4: - | E4: 5 | F4: =VLOOKUP($A4, Calcs!$A$3:'Calcs'!$ALW$130, 95, FALSE)+VLOOKUP($A4, Calcs!$A$3:'Calcs'!$ALW$130, 97, FALSE) -> 11 | G4: =VLOOKUP($A4, Calcs!$A$3:'Calcs'!$ALW$130, 96, FALSE)+VLOOKUP($A4, Calcs!$A$3:'Calcs'!$ALW$130, 98, FALSE) -> 1 | I4: =VLOOKUP($A4, Calcs!$A$3:'Calcs'!$ALW$130, 99, FALSE)+VLOOKUP($A4, Calcs!$A$3:'Calcs'!$ALW$130, 101, FALSE) -> 8 | J4: =VLOOKUP($A4, Calcs!$A$3:'Calcs'!$ALW$130, 100, FALSE)+VLOOKUP($A4, Calcs!$A$3:'Calcs'!$ALW$130, 102, FALSE) -> 1 | L4: =VLOOKUP($A4, Calcs!$A$3:'Calcs'!$ALW$130, 119, FALSE) -> 26 | M4: =VLOOKUP($A4, Calcs!$A$3:'Calcs'!$ALW$130, 120, FALSE) -> 8 | N4: M | O4: =VLOOKUP($A4, Calcs!$A$3:'Calcs'!$ALW$130, 302, FALSE)/X4 -> 20.591463 | P4: =VLOOKUP($A4, Calcs!$A$3:'Calcs'!$ALW$130, 394, FALSE)/X4 -> 12.810976 | Q4: =O4-P4 -> 7.7804878 | R4: =O4/(VLOOKUP($A4,Calcs!$A$3:'Calcs'!$ALW$130,485,FALSE)/X4) -> 2.6507064 | S4: =VLOOKUP($A4, Calcs!$A$3:'Calcs'!$ALW$130, 210, FALSE)/X4 -> 0.6185194 | T4: =VLOOKUP($A4, Calcs!$A$3:'Calcs'!$ALW$130, 576, FALSE)/X4 -> 5.1310366 | U4: =VLOOKUP($A4, Calcs!$A$3:'Calcs'!$ALW$130, 667, FALSE)/X4 -> 63.262195 | V4: =VLOOKUP($A4, Calcs!$A$3:'Calcs'!$ALW$130, 758, FALSE)/X4 -> 58.256707 | X4: =VLOOKUP($A4, Calcs!$A$3:'Calcs'!$ALW$130, 9, FALSE) -> 27.333333 | Y4: =-(T4-MAX(T:T))*S4 -> 1.6766451 | Z4: =(S4)*(BG4) -> 0.60214524 | AA4: =Q4-T4 -> 2.6494512 | AB4: =U4 -> 63.262195 | AC4: =V4 -> 58.256707 | AD4: =IFERROR((AVERAGE((Q4-MIN(Q:Q))*AB4, SQRT((Q4-MIN(Q:Q))*AB4))/100)*BG4, 0) -> 7.935815 | AE4: =IFERROR(IF(SQRT(AC4)>10, 10, SQRT(AC4)), 0) -> 7.6326082 | AG4: 50 | AH4: 50 | AI4: 45 | AJ4: 105 | AL4: =SUM(AG4:AJ4) -> 250 | AN4: 3 | AO4: =_xlfn.RANK.EQ(AQ4,AQ:AQ, 0) -> 3 | AP4: =AN4-AO4 -> 0 | AQ4: =((AR4*2.4)+(AS4*1.6)+(AT4*1)+(AU4*1)+(AV4*0.75)+(AW4*1)+(AX4*1)+(AY4*0.75)+(AZ4*1)+(BA4*0.75)+(BB4*0.75)+(BC4/LARGE(BC:BC,1))*(0/12))/(11+(20/24)) -> 0.91257611 | AR4: =IFERROR(IF((F4+G4)=1, IF(F4=0, 0.333, IF(F4=1, 0.666, 0)), IF((F4+G4)=2, IF(F4=0, 0.166, IF(F4=1, 0.5, IF(F4=2, 0.833, 0))), (F4+(L4/6))/(F4+G4))), 0) -> 1.2777778 | AS4: =IFERROR(IF((I4+J4)=1, IF(I4=0, 0.333, IF(I4=1, 0.666, 0)), IF((I4+J4)=2, IF(I4=0, 0.166, IF(I4=1, 0.5, IF(I4=2, 0.833, 0))), (I4/(I4+J4)))), 0) -> 0.88888889 | AT4: =(O4-(SMALL(O:O, 1)))/((LARGE(O:O, 1))-(SMALL(O:O, 1))) -> 0.85201907 | AU4: =1-(P4-(SMALL(P:P, 1)))/((LARGE(P:P, 1))-(SMALL(P:P, 1))) -> 0.89536687 | AV4: =(R4-(SMALL(R:R, 1)))/((LARGE(R:R, 1))-(SMALL(R:R, 1))) -> 0.72715056 | AW4: =(Z4-(SMALL(Z:Z, 1)))/((LARGE(Z:Z, 1))-(SMALL(Z:Z, 1))) -> 0.66400934 | AX4: =(AA4+ABS(MIN(AA:AA)))/(MAX(AA:AA)+ABS(MIN(AA:AA))) -> 0.82116139 | AY4: =AVERAGE(AD4/MAX(AD:AD), SQRT(AD4/MAX(AD:AD))) -> 0.82723469 | AZ4: =AVERAGE(AE4/MAX(AE:AE), (AE4-SMALL(AE:AE,1))/(LARGE(AE:AE,1)-SMALL(AE:AE,1))) -> 0.76992007 | BA4: =(BL4-MIN($BL$2:$BL$129))/(MAX($BL$2:$BL$129)-MIN($BL$2:$BL$129)) -> 0.77146631 | BB4: =IFERROR(AL4/MAX(AL:AL), 0) -> 0.75075075 | BC4: 167 | BE4: =VLOOKUP($A4, Calcs!$A$3:'Calcs'!$ALW$130, 845, FALSE) -> 112 | BF4: -1 | BG4: =IF(A4<17, SoC!P$3, IF(A4<33, SoC!P$4, IF(A4<49, SoC!P$5, IF(A4<65, SoC!P$6, IF(A4<81, SoC!P$7, IF(A4<97, SoC!P$8, SoC!P$9)))))) -> 0.97352684 | BH4: 0.85201907 | BI4: 0.89536687 | BJ4: 7.6326082 | BK4: 0.91255549 | BL4: =VLOOKUP($A4, Calcs!$A$3:'Calcs'!$BAA$130, 1025, FALSE) -> 2130 | BM4: 11.2 | BN4: =SQRT(BK4) -> 0.9552777 | BO4: =IF(BN4<(15/30), "F", IF(BN4<(18/30), "F+", IF(BN4<(19/30), "D-", IF(BN4<(20/30), "D", IF(BN4<(21/30), "D+", IF(BN4<(22/30), "C-", IF(BN4<(23/30), "C", IF(BN4<(24/30), "C+", IF(BN4<(25/30), "B-", IF(BN4<(26/30), "B", IF(BN4<(27/30), "B+", IF(BN4<(28/30), "A-", IF(BN4<(29/30), "A", "A+"))))))))))))) -> A | BP4: =(((BK4-$BK$1)/0.15)*3)+((BJ4-$BJ$1)/2) -> 8.475807 | BQ4: C | BR4: #2 | BS4: =IF(BQ4="A","Platinum",IF(BQ4="B","Prism",IF(BQ4="C","Hakuna",IF(BQ4="D","Wild",IF(BQ4="E","Crystal",IF(BQ4="F","Gray",IF(BQ4="G","Emerald",IF(BQ4="H","Mystery")))))))) -> Hakuna | BT4: UTL | BU4: C | BV4: =IF(BT4="MRL", VLOOKUP(C4, Master!BL:BP, 5, FALSE), IF(BT4="UTL", VLOOKUP(C4, Ultra!BL:BP, 5, FALSE), "")) -> 1 | BW4: - | BX4: S4 UTL Champion | BY4: =MATCH(A4, Standings!$N$3:$N$18, 0) -> 2 | BZ4: 0.6777043 | CA4: Solaceon Town | CB4: 3 | CC4: 3 | CD4: 3 | CE4: 3 | CF4: 4 | CG4: 4 | CH4: 4 | CI4: 4 | CJ4: 5 | CK4: 4 | CL4: 4 | CM4: 4 | CN4: 4 | CO4: 4 | CP4: 4 | CQ4: 3 | CR4: 4 | CS4: 5 | CT4: 5 | CU4: 6 | CV4: 6 | CW4: 7 | CX4: 8 | CY4: 11 | CZ4: 10 | DA4: 10 | DB4: 11 | DC4: 12 | DD4: 23 | DE4: 20 | DF4: 20 | DG4: 19 | DH4: 20 | DI4: 21 | DJ4: 21 | DK4: 25 | DL4: 24 | DM4: 37 | DN4: 33
A5: 13 | B5: Indigo | C5: Cinnabar Island | D5: - | E5: 3 | F5: =VLOOKUP($A5, Calcs!$A$3:'Calcs'!$ALW$130, 95, FALSE)+VLOOKUP($A5, Calcs!$A$3:'Calcs'!$ALW$130, 97, FALSE) -> 10 | G5: =VLOOKUP($A5, Calcs!$A$3:'Calcs'!$ALW$130, 96, FALSE)+VLOOKUP($A5, Calcs!$A$3:'Calcs'!$ALW$130, 98, FALSE) -> 2 | H5: * | I5: =VLOOKUP($A5, Calcs!$A$3:'Calcs'!$ALW$130, 99, FALSE)+VLOOKUP($A5, Calcs!$A$3:'Calcs'!$ALW$130, 101, FALSE) -> 8 | J5: =VLOOKUP($A5, Calcs!$A$3:'Calcs'!$ALW$130, 100, FALSE)+VLOOKUP($A5, Calcs!$A$3:'Calcs'!$ALW$130, 102, FALSE) -> 1 | L5: =VLOOKUP($A5, Calcs!$A$3:'Calcs'!$ALW$130, 119, FALSE) -> 15 | M5: =VLOOKUP($A5, Calcs!$A$3:'Calcs'!$ALW$130, 120, FALSE) -> 11 | N5: M | O5: =VLOOKUP($A5, Calcs!$A$3:'Calcs'!$ALW$130, 302, FALSE)/X5 -> 22.089041 | P5: =VLOOKUP($A5, Calcs!$A$3:'Calcs'!$ALW$130, 394, FALSE)/X5 -> 13.917808 | Q5: =O5-P5 -> 8.1712329 | R5: =O5/(VLOOKUP($A5,Calcs!$A$3:'Calcs'!$ALW$130,485,FALSE)/X5) -> 2.9833488 | S5: =VLOOKUP($A5, Calcs!$A$3:'Calcs'!$ALW$130, 210, FALSE)/X5 -> 0.65494912 | T5: =VLOOKUP($A5, Calcs!$A$3:'Calcs'!$ALW$130, 576, FALSE)/X5 -> 5.9035616 | U5: =VLOOKUP($A5, Calcs!$A$3:'Calcs'!$ALW$130, 667, FALSE)/X5 -> 77.609589 | V5: =VLOOKUP($A5, Calcs!$A$3:'Calcs'!$ALW$130, 758, FALSE)/X5 -> 64.516438 | X5: =VLOOKUP($A5, Calcs!$A$3:'Calcs'!$ALW$130, 9, FALSE) -> 24.333333 | Y5: =-(T5-MAX(T:T))*S5 -> 1.269432 | Z5: =(S5)*(BG5) -> 0.6625266 | AA5: =Q5-T5 -> 2.2676712 | AB5: =U5 -> 77.609589 | AC5: =V5 -> 64.516438 | AD5: =IFERROR((AVERAGE((Q5-MIN(Q:Q))*AB5, SQRT((Q5-MIN(Q:Q))*AB5))/100)*BG5, 0) -> 10.24711 | AE5: =IFERROR(IF(SQRT(AC5)>10, 10, SQRT(AC5)), 0) -> 8.0322125 | AG5: 36 | AH5: 70 | AI5: 60 | AJ5: 50 | AL5: =SUM(AG5:AJ5) -> 216 | AN5: 4 | AO5: =_xlfn.RANK.EQ(AQ5,AQ:AQ, 0) -> 4 | AP5: =AN5-AO5 -> 0 | AQ5: =((AR5*2.4)+(AS5*1.6)+(AT5*1)+(AU5*1)+(AV5*0.75)+(AW5*1)+(AX5*1)+(AY5*0.75)+(AZ5*1)+(BA5*0.75)+(BB5*0.75)+(BC5/LARGE(BC:BC,1))*(0/12))/(11+(20/24)) -> 0.89976669 | AR5: =IFERROR(IF((F5+G5)=1, IF(F5=0, 0.333, IF(F5=1, 0.666, 0)), IF((F5+G5)=2, IF(F5=0, 0.166, IF(F5=1, 0.5, IF(F5=2, 0.833, 0))), (F5+(L5/6))/(F5+G5))), 0) -> 1.0416667 | AS5: =IFERROR(IF((I5+J5)=1, IF(I5=0, 0.333, IF(I5=1, 0.666, 0)), IF((I5+J5)=2, IF(I5=0, 0.166, IF(I5=1, 0.5, IF(I5=2, 0.833, 0))), (I5/(I5+J5)))), 0) -> 0.88888889 | AT5: =(O5-(SMALL(O:O, 1)))/((LARGE(O:O, 1))-(SMALL(O:O, 1))) -> 0.97025741 | AU5: =1-(P5-(SMALL(P:P, 1)))/((LARGE(P:P, 1))-(SMALL(P:P, 1))) -> 0.82960141 | AV5: =(R5-(SMALL(R:R, 1)))/((LARGE(R:R, 1))-(SMALL(R:R, 1))) -> 0.96846683 | AW5: =(Z5-(SMALL(Z:Z, 1)))/((LARGE(Z:Z, 1))-(SMALL(Z:Z, 1))) -> 0.86090435 | AX5: =(AA5+ABS(MIN(AA:AA)))/(MAX(AA:AA)+ABS(MIN(AA:AA))) -> 0.79279791 | AY5: =AVERAGE(AD5/MAX(AD:AD), SQRT(AD5/MAX(AD:AD))) -> 1 | AZ5: =AVERAGE(AE5/MAX(AE:AE), (AE5-SMALL(AE:AE,1))/(LARGE(AE:AE,1)-SMALL(AE:AE,1))) -> 0.82612258 | BA5: =(BL5-MIN($BL$2:$BL$129))/(MAX($BL$2:$BL$129)-MIN($BL$2:$BL$129)) -> 0.64332893 | BB5: =IFERROR(AL5/MAX(AL:AL), 0) -> 0.64864865 | BC5: 380 | BE5: =VLOOKUP($A5, Calcs!$A$3:'Calcs'!$ALW$130, 845, FALSE) -> 85.375 | BF5: 1.6666667 | BG5: =IF(A5<17, SoC!P$3, IF(A5<33, SoC!P$4, IF(A5<49, SoC!P$5, IF(A5<65, SoC!P$6, IF(A5<81, SoC!P$7, IF(A5<97, SoC!P$8, SoC!P$9)))))) -> 1.0115696 | BH5: 0.97025741 | BI5: 0.82960141 | BJ5: 8.0322125 | BK5: 0.89976634 | BL5: =VLOOKUP($A5, Calcs!$A$3:'Calcs'!$BAA$130, 1025, FALSE) -> 2033 | BM5: 8.5 | BN5: =SQRT(BK5) -> 0.94856014 | BO5: =IF(BN5<(15/30), "F", IF(BN5<(18/30), "F+", IF(BN5<(19/30), "D-", IF(BN5<(20/30), "D", IF(BN5<(21/30), "D+", IF(BN5<(22/30), "C-", IF(BN5<(23/30), "C", IF(BN5<(24/30), "C+", IF(BN5<(25/30), "B-", IF(BN5<(26/30), "B", IF(BN5<(27/30), "B+", IF(BN5<(28/30), "A-", IF(BN5<(29/30), "A", "A+"))))))))))))) -> A | BP5: =(((BK5-$BK$1)/0.15)*3)+((BJ5-$BJ$1)/2) -> 8.4198263 | BQ5: E | BR5: #1 | BS5: =IF(BQ5="A","Platinum",IF(BQ5="B","Prism",IF(BQ5="C","Hakuna",IF(BQ5="D","Wild",IF(BQ5="E","Crystal",IF(BQ5="F","Gray",IF(BQ5="G","Emerald",IF(BQ5="H","Mystery")))))))) -> Crystal | BT5: MRL | BU5: C | BV5: =IF(BT5="MRL", VLOOKUP(C5, Master!BL:BP, 5, FALSE), IF(BT5="UTL", VLOOKUP(C5, Ultra!BL:BP, 5, FALSE), "")) -> 2 | BW5: S4 Indigo Champion | BX5: - | BY5: =MATCH(A5, Standings!$D$3:$D$18, 0) -> 1 | BZ5: 0.99815419 | CA5: Cinnabar Island | CB5: 4 | CC5: 4 | CD5: 4 | CE5: 4 | CF5: 5 | CG5: 3 | CH5: 3 | CI5: 3 | CJ5: 3 | CK5: 3 | CL5: 3 | CM5: 3 | CN5: 3 | CO5: 3 | CP5: 3 | CQ5: 4 | CR5: 3 | CS5: 4 | CT5: 3 | CU5: 3 | CV5: 4 | CW5: 6 | CX5: 6 | CY5: 4 | CZ5: 7 | DA5: 4 | DB5: 4 | DC5: 7 | DD5: 10 | DE5: 9 | DF5: 12 | DG5: 8 | DH5: 11 | DI5: 9 | DJ5: 16 | DK5: 13 | DL5: 7 | DM5: 1 | DN5: 1
A6: 56 | B6: Vertress | C6: Virbank City | D6: - | E6: 6 | F6: =VLOOKUP($A6, Calcs!$A$3:'Calcs'!$ALW$130, 95, FALSE)+VLOOKUP($A6, Calcs!$A$3:'Calcs'!$ALW$130, 97, FALSE) -> 10 | G6: =VLOOKUP($A6, Calcs!$A$3:'Calcs'!$ALW$130, 96, FALSE)+VLOOKUP($A6, Calcs!$A$3:'Calcs'!$ALW$130, 98, FALSE) -> 2 | I6: =VLOOKUP($A6, Calcs!$A$3:'Calcs'!$ALW$130, 99, FALSE)+VLOOKUP($A6, Calcs!$A$3:'Calcs'!$ALW$130, 101, FALSE) -> 7 | J6: =VLOOKUP($A6, Calcs!$A$3:'Calcs'!$ALW$130, 100, FALSE)+VLOOKUP($A6, Calcs!$A$3:'Calcs'!$ALW$130, 102, FALSE) -> 2 | L6: =VLOOKUP($A6, Calcs!$A$3:'Calcs'!$ALW$130, 119, FALSE) -> 24 | M6: =VLOOKUP($A6, Calcs!$A$3:'Calcs'!$ALW$130, 120, FALSE) -> 11 | N6: M | O6: =VLOOKUP($A6, Calcs!$A$3:'Calcs'!$ALW$130, 302, FALSE)/X6 -> 19.935294 | P6: =VLOOKUP($A6, Calcs!$A$3:'Calcs'!$ALW$130, 394, FALSE)/X6 -> 12.376471 | Q6: =O6-P6 -> 7.5588235 | R6: =O6/(VLOOKUP($A6,Calcs!$A$3:'Calcs'!$ALW$130,485,FALSE)/X6) -> 2.6643082 | S6: =VLOOKUP($A6, Calcs!$A$3:'Calcs'!$ALW$130, 210, FALSE)/X6 -> 0.62287076 | T6: =VLOOKUP($A6, Calcs!$A$3:'Calcs'!$ALW$130, 576, FALSE)/X6 -> 5.0307059 | U6: =VLOOKUP($A6, Calcs!$A$3:'Calcs'!$ALW$130, 667, FALSE)/X6 -> 68.705882 | V6: =VLOOKUP($A6, Calcs!$A$3:'Calcs'!$ALW$130, 758, FALSE)/X6 -> 61.031176 | X6: =VLOOKUP($A6, Calcs!$A$3:'Calcs'!$ALW$130, 9, FALSE) -> 28.333333 | Y6: =-(T6-MAX(T:T))*S6 -> 1.7509336 | Z6: =(S6)*(BG6) -> 0.6684169 | AA6: =Q6-T6 -> 2.5281176 | AB6: =U6 -> 68.705882 | AC6: =V6 -> 61.031176 | AD6: =IFERROR((AVERAGE((Q6-MIN(Q:Q))*AB6, SQRT((Q6-MIN(Q:Q))*AB6))/100)*BG6, 0) -> 9.4083205 | AE6: =IFERROR(IF(SQRT(AC6)>10, 10, SQRT(AC6)), 0) -> 7.8122453 | AG6: 60 | AH6: 60 | AI6: 35 | AJ6: 70 | AL6: =SUM(AG6:AJ6) -> 225 | AN6: 5 | AO6: =_xlfn.RANK.EQ(AQ6,AQ:AQ, 0) -> 5 | AP6: =AN6-AO6 -> 0 | AQ6: =((AR6*2.4)+(AS6*1.6)+(AT6*1)+(AU6*1)+(AV6*0.75)+(AW6*1)+(AX6*1)+(AY6*0.75)+(AZ6*1)+(BA6*0.75)+(BB6*0.75)+(BC6/LARGE(BC:BC,1))*(0/12))/(11+(20/24)) -> 0.8961922 | AR6: =IFERROR(IF((F6+G6)=1, IF(F6=0, 0.333, IF(F6=1, 0.666, 0)), IF((F6+G6)=2, IF(F6=0, 0.166, IF(F6=1, 0.5, IF(F6=2, 0.833, 0))), (F6+(L6/6))/(F6+G6))), 0) -> 1.1666667 | AS6: =IFERROR(IF((I6+J6)=1, IF(I6=0, 0.333, IF(I6=1, 0.666, 0)), IF((I6+J6)=2, IF(I6=0, 0.166, IF(I6=1, 0.5, IF(I6=2, 0.833, 0))), (I6/(I6+J6)))), 0) -> 0.77777778 | AT6: =(O6-(SMALL(O:O, 1)))/((LARGE(O:O, 1))-(SMALL(O:O, 1))) -> 0.80021249 | AU6: =1-(P6-(SMALL(P:P, 1)))/((LARGE(P:P, 1))-(SMALL(P:P, 1))) -> 0.92118416 | AV6: =(R6-(SMALL(R:R, 1)))/((LARGE(R:R, 1))-(SMALL(R:R, 1))) -> 0.73701798 | AW6: =(Z6-(SMALL(Z:Z, 1)))/((LARGE(Z:Z, 1))-(SMALL(Z:Z, 1))) -> 0.88011179 | AX6: =(AA6+ABS(MIN(AA:AA)))/(MAX(AA:AA)+ABS(MIN(AA:AA))) -> 0.81214718 | AY6: =AVERAGE(AD6/MAX(AD:AD), SQRT(AD6/MAX(AD:AD))) -> 0.93817103 | AZ6: =AVERAGE(AE6/MAX(AE:AE), (AE6-SMALL(AE:AE,1))/(LARGE(AE:AE,1)-SMALL(AE:AE,1))) -> 0.79518521 | BA6: =(BL6-MIN($BL$2:$BL$129))/(MAX($BL$2:$BL$129)-MIN($BL$2:$BL$129)) -> 0.78467635 | BB6: =IFERROR(AL6/MAX(AL:AL), 0) -> 0.67567568 | BC6: 318 | BE6: =VLOOKUP($A6, Calcs!$A$3:'Calcs'!$ALW$130, 845, FALSE) -> 184.5 | BF6: 1.3333333 | BG6: =IF(A6<17, SoC!P$3, IF(A6<33, SoC!P$4, IF(A6<49, SoC!P$5, IF(A6<65, SoC!P$6, IF(A6<81, SoC!P$7, IF(A6<97, SoC!P$8, SoC!P$9)))))) -> 1.0731229 | BH6: 0.80021249 | BI6: 0.92118416 | BJ6: 7.8122453 | BK6: 0.89620059 | BL6: =VLOOKUP($A6, Calcs!$A$3:'Calcs'!$BAA$130, 1025, FALSE) -> 2140 | BM6: 18.5 | BN6: =SQRT(BK6) -> 0.94667872 | BO6: =IF(BN6<(15/30), "F", IF(BN6<(18/30), "F+", IF(BN6<(19/30), "D-", IF(BN6<(20/30), "D", IF(BN6<(21/30), "D+", IF(BN6<(22/30), "C-", IF(BN6<(23/30), "C", IF(BN6<(24/30), "C+", IF(BN6<(25/30), "B-", IF(BN6<(26/30), "B", IF(BN6<(27/30), "B+", IF(BN6<(28/30), "A-", IF(BN6<(29/30), "A", "A+"))))))))))))) -> A | BP6: =(((BK6-$BK$1)/0.15)*3)+((BJ6-$BJ$1)/2) -> 8.2385277 | BQ6: F | BR6: #1 | BS6: =IF(BQ6="A","Platinum",IF(BQ6="B","Prism",IF(BQ6="C","Hakuna",IF(BQ6="D","Wild",IF(BQ6="E","Crystal",IF(BQ6="F","Gray",IF(BQ6="G","Emerald",IF(BQ6="H","Mystery")))))))) -> Gray | BT6: MRL | BU6: F | BV6: =IF(BT6="MRL", VLOOKUP(C6, Master!BL:BP, 5, FALSE), IF(BT6="UTL", VLOOKUP(C6, Ultra!BL:BP, 5, FALSE), "")) -> 2 | BW6: - | BX6: S4 MRL Champion | BY6: =MATCH(A6, Standings!$N$21:$N$36, 0) -> 5 | BZ6: 0.84842567 | CA6: Virbank City | CB6: 5 | CC6: 5 | CD6: 5 | CE6: 5 | CF6: 3 | CG6: 5 | CH6: 5 | CI6: 5 | CJ6: 6 | CK6: 5 | CL6: 5 | CM6: 5 | CN6: 5 | CO6: 5 | CP6: 6 | CQ6: 8 | CR6: 8 | CS6: 10 | CT6: 12 | CU6: 13 | CV6: 16 | CW6: 16 | CX6: 16 | CY6: 16 | CZ6: 17 | DA6: 21 | DB6: 22 | DC6: 22 | DD6: 12 | DE6: 12 | DF6: 10 | DG6: 9 | DH6: 13 | DI6: 14 | DJ6: 20 | DK6: 17 | DL6: 3 | DM6: 6 | DN6: 6
A7: 125 | B7: Phoenix | C7: Aqua Resort | D7: - | E7: 7 | F7: =VLOOKUP($A7, Calcs!$A$3:'Calcs'!$ALW$130, 95, FALSE)+VLOOKUP($A7, Calcs!$A$3:'Calcs'!$ALW$130, 97, FALSE) -> 11 | G7: =VLOOKUP($A7, Calcs!$A$3:'Calcs'!$ALW$130, 96, FALSE)+VLOOKUP($A7, Calcs!$A$3:'Calcs'!$ALW$130, 98, FALSE) -> 1 | I7: =VLOOKUP($A7, Calcs!$A$3:'Calcs'!$ALW$130, 99, FALSE)+VLOOKUP($A7, Calcs!$A$3:'Calcs'!$ALW$130, 101, FALSE) -> 8 | J7: =VLOOKUP($A7, Calcs!$A$3:'Calcs'!$ALW$130, 100, FALSE)+VLOOKUP($A7, Calcs!$A$3:'Calcs'!$ALW$130, 102, FALSE) -> 1 | L7: =VLOOKUP($A7, Calcs!$A$3:'Calcs'!$ALW$130, 119, FALSE) -> 20 | M7: =VLOOKUP($A7, Calcs!$A$3:'Calcs'!$ALW$130, 120, FALSE) -> 16 | N7: M | O7: =VLOOKUP($A7, Calcs!$A$3:'Calcs'!$ALW$130, 302, FALSE)/X7 -> 18.531792 | P7: =VLOOKUP($A7, Calcs!$A$3:'Calcs'!$ALW$130, 394, FALSE)/X7 -> 11.809249 | Q7: =O7-P7 -> 6.7225434 | R7: =O7/(VLOOKUP($A7,Calcs!$A$3:'Calcs'!$ALW$130,485,FALSE)/X7) -> 2.6343468 | S7: =VLOOKUP($A7, Calcs!$A$3:'Calcs'!$ALW$130, 210, FALSE)/X7 -> 0.66211149 | T7: =VLOOKUP($A7, Calcs!$A$3:'Calcs'!$ALW$130, 576, FALSE)/X7 -> 3.5275145 | U7: =VLOOKUP($A7, Calcs!$A$3:'Calcs'!$ALW$130, 667, FALSE)/X7 -> 62.445087 | V7: =VLOOKUP($A7, Calcs!$A$3:'Calcs'!$ALW$130, 758, FALSE)/X7 -> 58.939884 | X7: =VLOOKUP($A7, Calcs!$A$3:'Calcs'!$ALW$130, 9, FALSE) -> 28.833333 | Y7: =-(T7-MAX(T:T))*S7 -> 2.8565223 | Z7: =(S7)*(BG7) -> 0.63855167 | AA7: =Q7-T7 -> 3.1950289 | AB7: =U7 -> 62.445087 | AC7: =V7 -> 58.939884 | AD7: =IFERROR((AVERAGE((Q7-MIN(Q:Q))*AB7, SQRT((Q7-MIN(Q:Q))*AB7))/100)*BG7, 0) -> 7.4386259 | AE7: =IFERROR(IF(SQRT(AC7)>10, 10, SQRT(AC7)), 0) -> 7.6772316 | AG7: 45 | AH7: 40 | AI7: 50 | AJ7: 105 | AL7: =SUM(AG7:AJ7) -> 240 | AN7: 6 | AO7: =_xlfn.RANK.EQ(AQ7,AQ:AQ, 0) -> 6 | AP7: =AN7-AO7 -> 0 | AQ7: =((AR7*2.4)+(AS7*1.6)+(AT7*1)+(AU7*1)+(AV7*0.75)+(AW7*1)+(AX7*1)+(AY7*0.75)+(AZ7*1)+(BA7*0.75)+(BB7*0.75)+(BC7/LARGE(BC:BC,1))*(0/12))/(11+(20/24)) -> 0.89034353 | AR7: =IFERROR(IF((F7+G7)=1, IF(F7=0, 0.333, IF(F7=1, 0.666, 0)), IF((F7+G7)=2, IF(F7=0, 0.166, IF(F7=1, 0.5, IF(F7=2, 0.833, 0))), (F7+(L7/6))/(F7+G7))), 0) -> 1.1944444 | AS7: =IFERROR(IF((I7+J7)=1, IF(I7=0, 0.333, IF(I7=1, 0.666, 0)), IF((I7+J7)=2, IF(I7=0, 0.166, IF(I7=1, 0.5, IF(I7=2, 0.833, 0))), (I7/(I7+J7)))), 0) -> 0.88888889 | AT7: =(O7-(SMALL(O:O, 1)))/((LARGE(O:O, 1))-(SMALL(O:O, 1))) -> 0.6894017 | AU7: =1-(P7-(SMALL(P:P, 1)))/((LARGE(P:P, 1))-(SMALL(P:P, 1))) -> 0.95488719 | AV7: =(R7-(SMALL(R:R, 1)))/((LARGE(R:R, 1))-(SMALL(R:R, 1))) -> 0.71528239 | AW7: =(Z7-(SMALL(Z:Z, 1)))/((LARGE(Z:Z, 1))-(SMALL(Z:Z, 1))) -> 0.78272554 | AX7: =(AA7+ABS(MIN(AA:AA)))/(MAX(AA:AA)+ABS(MIN(AA:AA))) -> 0.86169384 | AY7: =AVERAGE(AD7/MAX(AD:AD), SQRT(AD7/MAX(AD:AD))) -> 0.78896811 | AZ7: =AVERAGE(AE7/MAX(AE:AE), (AE7-SMALL(AE:AE,1))/(LARGE(AE:AE,1)-SMALL(AE:AE,1))) -> 0.77619615 | BA7: =(BL7-MIN($BL$2:$BL$129))/(MAX($BL$2:$BL$129)-MIN($BL$2:$BL$129)) -> 0.68428005 | BB7: =IFERROR(AL7/MAX(AL:AL), 0) -> 0.72072072 | BC7: 105 | BE7: =VLOOKUP($A7, Calcs!$A$3:'Calcs'!$ALW$130, 845, FALSE) -> 106 | BF7: 1.3333333 | BG7: =IF(A7<17, SoC!P$3, IF(A7<33, SoC!P$4, IF(A7<49, SoC!P$5, IF(A7<65, SoC!P$6, IF(A7<81, SoC!P$7, IF(A7<97, SoC!P$8, SoC!P$9)))))) -> 0.96441715 | BH7: 0.6894017 | BI7: 0.95488719 | BJ7: 7.6772316 | BK7: 0.8902247 | BL7: =VLOOKUP($A7, Calcs!$A$3:'Calcs'!$BAA$130, 1025, FALSE) -> 2064 | BM7: 10.6 | BN7: =SQRT(BK7) -> 0.94351719 | BO7: =IF(BN7<(15/30), "F", IF(BN7<(18/30), "F+", IF(BN7<(19/30), "D-", IF(BN7<(20/30), "D", IF(BN7<(21/30), "D+", IF(BN7<(22/30), "C-", IF(BN7<(23/30), "C", IF(BN7<(24/30), "C+", IF(BN7<(25/30), "B-", IF(BN7<(26/30), "B", IF(BN7<(27/30), "B+", IF(BN7<(28/30), "A-", IF(BN7<(29/30), "A", "A+"))))))))))))) -> A | BP7: =(((BK7-$BK$1)/0.15)*3)+((BJ7-$BJ$1)/2) -> 8.0515029 | BQ7: B | BR7: #7 | BS7: =IF(BQ7="A","Platinum",IF(BQ7="B","Prism",IF(BQ7="C","Hakuna",IF(BQ7="D","Wild",IF(BQ7="E","Crystal",IF(BQ7="F","Gray",IF(BQ7="G","Emerald",IF(BQ7="H","Mystery")))))))) -> Prism | BT7: UTL | BU7: E | BV7: =IF(BT7="MRL", VLOOKUP(C7, Master!BL:BP, 5, FALSE), IF(BT7="UTL", VLOOKUP(C7, Ultra!BL:BP, 5, FALSE), "")) -> 2 | BW7: - | BX7: - | BY7: =MATCH(A7, Standings!$AH$21:$AH$36, 0) -> 2 | BZ7: 0.76078885 | CA7: Aqua Resort | CB7: 6 | CC7: 6 | CD7: 6 | CE7: 6 | CF7: 6 | CG7: 7 | CH7: 6 | CI7: 6 | CJ7: 4 | CK7: 6 | CL7: 6 | CM7: 6 | CN7: 6 | CO7: 6 | CP7: 5 | CQ7: 7 | CR7: 7 | CS7: 7 | CT7: 6 | CU7: 7 | CV7: 7 | CW7: 8 | CX7: 7 | CY7: 10 | CZ7: 11 | DA7: 14 | DB7: 16 | DC7: 17 | DD7: 19 | DE7: 17 | DF7: 24 | DG7: 27 | DH7: 26 | DI7: 24 | DJ7: 23 | DK7: 26 | DL7: 23 | DM7: 16 | DN7: 17
